Workbook

Sheet Cover
B2: UNIT TEST CASE
A4: Project Name | B4: InterDev Platform | E4: Creator | F4: Nguyen Phuc An
A5: Project Code | B5: INTERDEV | E5: Reviewer/Approver | F5: Pending review
A6: Document Code | B6: =B5&"_UTC_"&"v0.8" | E6: Issue Date | F6: 46111
E7: Version | F7: 0.8
A10: Record of change
A11: Effective Date | B11: Version | C11: Change Item | D11: *A,D,M | E11: Change description | F11: Reference
A12: 46111 | B12: 0.8 | C12: API batch 20 preview | D12: A | E12: First 20 requested API endpoints reworked with label/detail row separation, hidden filler rows, and denser UTC coverage where the code paths justify it. | F12: Current codebase + contracts.controller.spec.ts + contracts.service.spec.ts

Sheet Function List
E2: UNIT TEST CASE LIST
A4: Project Name | E4: InterDev Platform
A5: Project Code | E5: INTERDEV
A6: Normal number of Test cases/KLOC | E6: 300
A7: Test Environment Setup Description | E7: Source of truth: current codebase and executed Jest tests. Heavy flows expand from service/business rules, lighter routes stay controller-oriented. Note: code also has POST /contracts/:id/signature-sessions, which is not present in the provided list.
A10: No | B10: Requirement Name | C10: Class Name | D10: Function Name | E10: Function Code(Optional) | F10: Sheet Name | G10: Description | H10: Pre-Condition
A11: 1 | B11: UC-20 View Contract | C11: ContractsService | D11: List Contracts | E11: EP-043 | F11: List Contracts | G11: GET /contracts/list | H11: Authenticated user and contract participation or accepted staff role
A12: 2 | B12: UC-20 View Contract | C12: ContractsService | D12: Get Contract | E12: EP-044 | F12: Get Contract | G12: GET /contracts/:id | H12: Authenticated viewer and contract id and contract visibility rules
A13: 3 | B13: UC-102 Create Contract | C13: ContractsService | D13: Initialize Contract With Body | E13: EP-045 | F13: Init Contract Body | G13: POST /contracts/initialize | H13: Authenticated broker and dto.specId, optional freelancerId
A14: 4 | B14: UC-102 Create Contract | C14: ContractsService | D14: Initialize Contract | E14: EP-046 | F14: Init Contract Param | G14: POST /contracts/initialize/:specId | H14: Authenticated broker and specId path param and accepted freelancer resolution
A15: 5 | B15: UC-63 Sign Contract | C15: ContractsService | D15: Sign Contract | E15: EP-047 | F15: Sign Contract | G15: POST /contracts/sign/:contractId | H15: Authenticated user and contractId and contentHash and signing transaction
A16: 6 | B16: UC-102 Create Contract | C16: ContractsService | D16: Update Draft | E16: EP-048 | F16: Update Draft | G16: PATCH /contracts/:id/draft | H16: Authenticated broker and draft contract id and patch dto
A17: 7 | B17: UC-102 Create Contract | C17: ContractsService | D17: Send Draft | E17: EP-049 | F17: Send Draft | G17: POST /contracts/:id/send | H17: Authenticated broker and draft contract id
A18: 8 | B18: UC-102 Create Contract | C18: ContractsService | D18: Discard Draft | E18: EP-050 | F18: Discard Draft | G18: POST /contracts/:id/discard | H18: Authenticated broker and pre-sign contract id
A19: 9 | B19: UC-21 Finalizing Contract | C19: ContractsService | D19: Activate Project | E19: EP-051 | F19: Activate Project | G19: POST /contracts/activate/:contractId | H19: Authenticated contract party and signed contract id
A20: 10 | B20: UC-20 View Contract | C20: ContractsService | D20: Download Pdf | E20: EP-052 | F20: Download Pdf | G20: GET /contracts/:id/pdf | H20: Authenticated user and contract id and response object
A21: 11 | B21: UC-51 Choose Payment Method | C21: PaymentMethodsController | D21: List Payment Methods | E21: EP-182 | F21: List Payment Methods | G21: GET /payment-methods | H21: Authenticated CLIENT/BROKER/FREELANCER user invokes payment-method listing | Saved methods may exist or be empty | Unsupported roles are blocked before listing
A22: 12 | B22: UC-51 Choose Payment Method | C22: PaymentMethodsController | D22: Create Payment Method | E22: EP-183 | F22: Create Payment Method | G22: POST /payment-methods | H22: Authenticated CLIENT/BROKER/FREELANCER user submits create-payment-method payload | First method may become default automatically | Invalid card/bank payloads are rejected
... A30: 20 | B30: UC-27 Review Client's Specs | C30: ProjectSpecsController | D30: Get Pending Client Review | E30: EP-212 | F30: Get Pending Client Review | G30: GET /project-specs/client-review | H30: Authenticated CLIENT user opens the client-review queue | Client id is read from auth context | Service may return specs or bubble an error

Sheet Test Report
A2: UNIT TEST REPORT
A4: Project Name | B4: =Cover!B4 | D4: Creator | F4: Nguyen Phuc An
A5: Project Code | B5: =Cover!B5 | D5: Reviewer/Approver | F5: Pending review
A6: Document Code | B6: =Cover!B5&"_Test Report_"&"v0.8" | D6: Issue Date | F6: 46111
B7: This preview covers 20 endpoints from the provided list. Layout now keeps section labels on dedicated rows, hides filler rows, and uses denser UTC matrices for heavier flows. Additional contracts route found in code but not in the list: POST /contracts/:id/signature-sessions.
A11: No | B11: Function code | C11: Passed | D11: Failed | E11: Untested | F11: N | G11: A | H11: B | I11: Total Test Cases
A12: 1 | B12: EP-043 | C12: ='List Contracts'!A7 | D12: ='List Contracts'!C7 | E12: ='List Contracts'!F7 | F12: ='List Contracts'!L7 | G12: ='List Contracts'!M7 | H12: ='List Contracts'!N7 | I12: ='List Contracts'!O7
A13: 2 | B13: EP-044 | C13: ='Get Contract'!A7 | D13: ='Get Contract'!C7 | E13: ='Get Contract'!F7 | F13: ='Get Contract'!L7 | G13: ='Get Contract'!M7 | H13: ='Get Contract'!N7 | I13: ='Get Contract'!O7
A14: 3 | B14: EP-045 | C14: ='Init Contract Body'!A7 | D14: ='Init Contract Body'!C7 | E14: ='Init Contract Body'!F7 | F14: ='Init Contract Body'!L7 | G14: ='Init Contract Body'!M7 | H14: ='Init Contract Body'!N7 | I14: ='Init Contract Body'!O7
A15: 4 | B15: EP-046 | C15: ='Init Contract Param'!A7 | D15: ='Init Contract Param'!C7 | E15: ='Init Contract Param'!F7 | F15: ='Init Contract Param'!L7 | G15: ='Init Contract Param'!M7 | H15: ='Init Contract Param'!N7 | I15: ='Init Contract Param'!O7
A16: 5 | B16: EP-047 | C16: ='Sign Contract'!A7 | D16: ='Sign Contract'!C7 | E16: ='Sign Contract'!F7 | F16: ='Sign Contract'!L7 | G16: ='Sign Contract'!M7 | H16: ='Sign Contract'!N7 | I16: ='Sign Contract'!O7
A17: 6 | B17: EP-048 | C17: ='Update Draft'!A7 | D17: ='Update Draft'!C7 | E17: ='Update Draft'!F7 | F17: ='Update Draft'!L7 | G17: ='Update Draft'!M7 | H17: ='Update Draft'!N7 | I17: ='Update Draft'!O7
A18: 7 | B18: EP-049 | C18: ='Send Draft'!A7 | D18: ='Send Draft'!C7 | E18: ='Send Draft'!F7 | F18: ='Send Draft'!L7 | G18: ='Send Draft'!M7 | H18: ='Send Draft'!N7 | I18: ='Send Draft'!O7
A19: 8 | B19: EP-050 | C19: ='Discard Draft'!A7 | D19: ='Discard Draft'!C7 | E19: ='Discard Draft'!F7 | F19: ='Discard Draft'!L7 | G19: ='Discard Draft'!M7 | H19: ='Discard Draft'!N7 | I19: ='Discard Draft'!O7
A20: 9 | B20: EP-051 | C20: ='Activate Project'!A7 | D20: ='Activate Project'!C7 | E20: ='Activate Project'!F7 | F20: ='Activate Project'!L7 | G20: ='Activate Project'!M7 | H20: ='Activate Project'!N7 | I20: ='Activate Project'!O7
A21: 10 | B21: EP-052 | C21: ='Download Pdf'!A7 | D21: ='Download Pdf'!C7 | E21: ='Download Pdf'!F7 | F21: ='Download Pdf'!L7 | G21: ='Download Pdf'!M7 | H21: ='Download Pdf'!N7 | I21: ='Download Pdf'!O7
A22: 11 | B22: EP-182 | C22: ='List Payment Methods'!A7 | D22: ='List Payment Methods'!C7 | E22: ='List Payment Methods'!F7 | F22: ='List Payment Methods'!L7 | G22: ='List Payment Methods'!M7 | H22: ='List Payment Methods'!N7 | I22: ='List Payment Methods'!O7
A23: 12 | B23: EP-183 | C23: ='Create Payment Method'!A7 | D23: ='Create Payment Method'!C7 | E23: ='Create Payment Method'!F7 | F23: ='Create Payment Method'!L7 | G23: ='Create Payment Method'!M7 | H23: ='Create Payment Method'!N7 | I23: ='Create Payment Method'!O7
A24: 13 | B24: EP-184 | C24: ='Set Default Payment Method'!A7 | D24: ='Set Default Payment Method'!C7 | E24: ='Set Default Payment Method'!F7 | F24: ='Set Default Payment Method'!L7 | G24: ='Set Default Payment Method'!M7 | H24: ='Set Default Payment Method'!N7 | I24: ='Set Default Payment Method'!O7
A25: 14 | B25: EP-185 | C25: ='Fund Milestone'!A7 | D25: ='Fund Milestone'!C7 | E25: ='Fund Milestone'!F7 | F25: ='Fund Milestone'!L7 | G25: ='Fund Milestone'!M7 | H25: ='Fund Milestone'!N7 | I25: ='Fund Milestone'!O7
A26: 15 | B26: EP-186 | C26: ='Get My Wallet'!A7 | D26: ='Get My Wallet'!C7 | E26: ='Get My Wallet'!F7 | F26: ='Get My Wallet'!L7 | G26: ='Get My Wallet'!M7 | H26: ='Get My Wallet'!N7 | I26: ='Get My Wallet'!O7
A27: 16 | B27: EP-187 | C27: ='Get My Wallet Transactions'!A7 | D27: ='Get My Wallet Transactions'!C7 | E27: ='Get My Wallet Transactions'!F7 | F27: ='Get My Wallet Transactions'!L7 | G27: ='Get My Wallet Transactions'!M7 | H27: ='Get My Wallet Transactions'!N7 | I27: ='Get My Wallet Transactions'!O7
A28: 17 | B28: EP-208 | C28: ='Approve Specs'!A7 | D28: ='Approve Specs'!C7 | E28: ='Approve Specs'!F7 | F28: ='Approve Specs'!L7 | G28: ='Approve Specs'!M7 | H28: ='Approve Specs'!N7 | I28: ='Approve Specs'!O7
A29: 18 | B29: EP-209 | C29: ='Convert To Project'!A7 | D29: ='Convert To Project'!C7 | E29: ='Convert To Project'!F7 | F29: ='Convert To Project'!L7 | G29: ='Convert To Project'!M7 | H29: ='Convert To Project'!N7 | I29: ='Convert To Project'!O7
A30: 19 | B30: EP-211 | C30: ='Get Pending Specs'!A7 | D30: ='Get Pending Specs'!C7 | E30: ='Get Pending Specs'!F7 | F30: ='Get Pending Specs'!L7 | G30: ='Get Pending Specs'!M7 | H30: ='Get Pending Specs'!N7 | I30: ='Get Pending Specs'!O7
A31: 20 | B31: EP-212 | C31: ='Get Pending Client Review'!A7 | D31: ='Get Pending Client Review'!C7 | E31: ='Get Pending Client Review'!F7 | F31: ='Get Pending Client Review'!L7 | G31: ='Get Pending Client Review'!M7 | H31: ='Get Pending Client Review'!N7 | I31: ='Get Pending Client Review'!O7
B33: Sub total | C33: =SUM(C12:C32) | D33: =SUM(D12:D32) | E33: =SUM(E12:E32) | F33: =SUM(F12:F32) | G33: =SUM(G12:G32) | H33: =SUM(H12:H32) | I33: =SUM(I12:I32)
B35: Test coverage | D35: =IF(I33=0,0,(C33+D33)*100/I33) | E35: %
B36: Test successful coverage | D36: =IF(I33=0,0,C33*100/I33) | E36: %
B37: Normal case | D37: =IF(I33=0,0,F33*100/I33) | E37: %
B38: Abnormal case | D38: =IF(I33=0,0,G33*100/I33) | E38: %
B39: Boundary case | D39: =IF(I33=0,0,H33*100/I33) | E39: %

Sheet List Contracts
A2: Function Code | C2: ='Function List'!E11 | F2: Function Name | L2: ='Function List'!D11
A3: Created By | C3: Nguyen Phuc An | F3: Executed By | L3: Nguyen Phuc An
A4: Lines of code | C4: 42 | F4: Lack of test cases | L4: 0
A5: Test requirement | C5: Verify listByUser returns active contract summaries for permitted participants, excludes archived contracts, supports empty results, and surfaces repository failures.
A6: Passed | C6: Failed | F6: Untested | L6: N/A/B | O6: Total Test Cases
A7: =COUNTIF(F51:HQ51,"P") | C7: =COUNTIF(F51:HQ51,"F") | F7: =SUM(O7,- A7,- C7) | L7: =COUNTIF(E50:HQ50,"N") | M7: =COUNTIF(E50:HQ50,"A") | N7: =COUNTIF(E50:HQ50,"B") | O7: =COUNTA(E9:HT9)
F9: UTCID01 | G9: UTCID02 | H9: UTCID03 | I9: UTCID04 | J9: UTCID05
A10: Condition | B10: Precondition
B11: auth context
D12: Authenticated user is available | F12: O | G12: O | H12: O | I12: O | J12: O
B13: access role
D14: User is linked as client / broker / freelancer | F14: O | I14: O
D15: User is accepted supervising staff | J15: O
B16: repository result
D17: Query returns one or more active contracts | F17: O | I17: O | J17: O
D18: Query returns no accessible contracts | G18: O
B19: archived data
D20: Archived contracts exist in storage | I20: O
B21: error source
D22: Query builder / repository throws | H22: O
A37: Confirm | B37: Return
D38: Return contract summary list | F38: O | I38: O | J38: O
D39: Return empty array | G39: O
B40: Exception
D41: Propagate repository failure | H41: O
B42: Verification
D43: Filter out ARCHIVED status contracts | I43: O
D44: Map summary fields for list response | F44: O | I44: O | J44: O
D45: Query by current user id across participant roles | F45: O | G45: O | H45: O | I45: O | J45: O
A50: Result | B50: Type(N : Normal, A : Abnormal, B : Boundary) | F50: N | G50: N | H50: A | I50: A | J50: N
B51: Passed/Failed | F51: P | G51: P | H51: P
B52: Executed Date | F52: 46111 | G52: 46111 | H52: 46111 | I52: 46111 | J52: 46111
B53: Defect ID

Sheet Get Contract
A2: Function Code | C2: ='Function List'!E12 | F2: Function Name | L2: ='Function List'!D12
A3: Created By | C3: Nguyen Phuc An | F3: Executed By | L3: Nguyen Phuc An
A4: Lines of code | C4: 13 | F4: Lack of test cases | L4: 0
A5: Test requirement | C5: Verify findOneForUser enforces contract visibility, hydrates the read model, self-heals stale content hashes, and propagates lookup failures.
A6: Passed | C6: Failed | F6: Untested | L6: N/A/B | O6: Total Test Cases
A7: =COUNTIF(F51:HQ51,"P") | C7: =COUNTIF(F51:HQ51,"F") | F7: =SUM(O7,- A7,- C7) | L7: =COUNTIF(E50:HQ50,"N") | M7: =COUNTIF(E50:HQ50,"A") | N7: =COUNTIF(E50:HQ50,"B") | O7: =COUNTA(E9:HT9)
F9: UTCID01 | G9: UTCID02 | H9: UTCID03 | I9: UTCID04 | J9: UTCID05
A10: Condition | B10: Precondition
B11: auth context
D12: Authenticated user is available | F12: O | G12: O | H12: O | I12: O | J12: O
B13: contract id
D14: Loadable contract id is provided | F14: O | G14: O | H14: O | I14: O
B15: viewer role
D16: User is a contract party | F16: O | I16: O
D17: User is accepted supervising staff | G17: O
D18: User is outside the contract parties | H18: O
B19: content hash
D20: Stored contentHash is stale | I20: O
B21: error source
D22: Read model / repository throws lookup error | J22: O
A37: Confirm | B37: Return
D38: Return hydrated contract detail | F38: O | G38: O | I38: O
D39: Include requiredSignerCount and signedCount | F39: O | G39: O | I39: O
B40: Exception
D41: Reject unauthorized viewer | H41: O
B42: Verification
D43: Self-heal stale contentHash before response | I43: O
D44: Assert viewer permission before return | F44: O | G44: O | H44: O | I44: O
D45: Propagate lookup failure | J45: O
A50: Result | B50: Type(N : Normal, A : Abnormal, B : Boundary) | F50: N | G50: A | H50: A | I50: N | J50: A
B51: Passed/Failed | F51: P | I51: P | J51: P
B52: Executed Date | F52: 46111 | G52: 46111 | H52: 46111 | I52: 46111 | J52: 46111
B53: Defect ID

Sheet Init Contract Body
A2: Function Code | C2: ='Function List'!E13 | F2: Function Name | L2: ='Function List'!D13
A3: Created By | C3: Nguyen Phuc An | F3: Executed By | L3: Nguyen Phuc An
A4: Lines of code | C4: 132 | F4: Lack of test cases | L4: 0
A5: Test requirement | C5: Verify body-based initialization forwards dto values and creates a SENT contract with frozen snapshot, contentHash, and spec lock when the source spec is eligible.
A6: Passed | C6: Failed | F6: Untested | L6: N/A/B | O6: Total Test Cases
A7: =COUNTIF(F51:HQ51,"P") | C7: =COUNTIF(F51:HQ51,"F") | F7: =SUM(O7,- A7,- C7) | L7: =COUNTIF(E50:HQ50,"N") | M7: =COUNTIF(E50:HQ50,"A") | N7: =COUNTIF(E50:HQ50,"B") | O7: =COUNTA(E9:HT9)
F9: UTCID01 | G9: UTCID02 | H9: UTCID03 | I9: UTCID04
A10: Condition | B10: Precondition
B11: auth context
D12: Authenticated user is available | F12: O | G12: O | H12: O | I12: O
B13: user role
D14: Current user role is BROKER | F14: O | G14: O | H14: O | I14: O
B15: dto.specId
D16: specId is present in request body | F16: O | G16: O | H16: O | I16: O
B17: dto.freelancerId
D18: freelancerId is provided explicitly | F18: O
D19: freelancerId is omitted | G19: O | H19: O | I19: O
B20: spec state
D21: Spec is unlocked | H21: O
B22: spec eligibility
D23: Spec is eligible for contract init | H23: O
B24: freelancer
D25: Accepted freelancer is resolved for the request | H25: O
B26: snapshot
D27: Milestones are frozen into snapshot | H27: O
B28: contract terms
D29: Terms are derived from frozen snapshot | H29: O
B30: Exception source
D31: Initialization fails in service | I31: O
A37: Confirm | B37: Return
D38: Initialize with specId and freelancerId | F38: O
D39: Initialize with specId only | G39: O
B40: Exception
D41: Propagate initialization error | I41: O
B42: Verification
D43: Create SENT contract with frozen snapshot and contentHash | H43: O
D44: Lock spec to saved contract id | H44: O
D45: Emit initialized contract update and participant notice | H45: O
D46: Service receives dto.specId + optional freelancerId | F46: O | G46: O | I46: O
A50: Result | B50: Type(N : Normal, A : Abnormal, B : Boundary) | F50: N | G50: N | H50: N | I50: A
...

Sheet Init Contract Param
A2: Function Code | C2: ='Function List'!E14 | F2: Function Name | L2: ='Function List'!D14
A3: Created By | C3: Nguyen Phuc An | F3: Executed By | L3: Nguyen Phuc An
A4: Lines of code | C4: 103 | F4: Lack of test cases | L4: 0
A5: Test requirement | C5: Verify path-based initialization reuses initializeProjectAndContract rules for spec existence, lock/duplicate state, broker access, freelancer readiness, and controller error propagation.
A6: Passed | C6: Failed | F6: Untested | L6: N/A/B | O6: Total Test Cases
A7: =COUNTIF(F51:HQ51,"P") | C7: =COUNTIF(F51:HQ51,"F") | F7: =SUM(O7,- A7,- C7) | L7: =COUNTIF(E50:HQ50,"N") | M7: =COUNTIF(E50:HQ50,"A") | N7: =COUNTIF(E50:HQ50,"B") | O7: =COUNTA(E9:HT9)
F9: UTCID01 | G9: UTCID02 | H9: UTCID03 | I9: UTCID04 | J9: UTCID05 | K9: UTCID06
A10: Condition | B10: Precondition
B11: auth context
D12: Authenticated user is available | F12: O | G12: O | H12: O | I12: O | J12: O | K12: O
B13: specId
D14: specId path param is supplied | F14: O | G14: O | H14: O | I14: O | J14: O | K14: O
B15: spec lookup
D16: Spec exists | F16: O | H16: O | I16: O | J16: O
B17: spec lock
D18: Spec is unlocked | F18: O | G18: O | I18: O | J18: O
B19: active contract
D20: No active contract exists for the spec | F20: O | G20: O | I20: O | J20: O
B21: broker auth
D22: Caller is the request broker | F22: O | G22: O | H22: O | J22: O
B23: freelancer resolution
D24: Accepted freelancer exists for phased flow | F24: O | G24: O | H24: O | I24: O
B25: error source
D26: Initialization flow throws service error | K26: O
A37: Confirm | B37: Return
D38: Return initialized contract | F38: O
D39: Use path specId when calling service | F39: O | G39: O | H39: O | I39: O | J39: O | K39: O
B40: Exception
D41: Reject invalid precondition and stop initialization | G41: O | H41: O | I41: O | J41: O
B42: Verification
D43: Create SENT contract and shell project on success | F43: O
D44: Propagate initialization failure | K44: O
A50: Result | B50: Type(N : Normal, A : Abnormal, B : Boundary) | F50: N | G50: A | H50: A | I50: A | J50: A | K50: A
B51: Passed/Failed | F51: P | K51: P
B52: Executed Date | F52: 46111 | G52: 46111 | H52: 46111 | I52: 46111 | J52: 46111 | K52: 46111
B53: Defect ID

Sheet Sign Contract
A2: Function Code | C2: ='Function List'!E15 | F2: Function Name | L2: ='Function List'!D15
A3: Created By | C3: Nguyen Phuc An | F3: Executed By | L3: Nguyen Phuc An
A4: Lines of code | C4: 133 | F4: Lack of test cases | L4: 0
A5: Test requirement | C5: Verify service-level signContract rules for content hash validation, signer access, SENT-only signing, duplicate protection, legacy snapshot hydration, pending/full-sign outcomes, and degraded archive persistence.
A6: Passed | C6: Failed | F6: Untested | L6: N/A/B | O6: Total Test Cases
A7: =COUNTIF(F51:HQ51,"P") | C7: =COUNTIF(F51:HQ51,"F") | F7: =SUM(O7,- A7,- C7) | L7: =COUNTIF(E50:HQ50,"N") | M7: =COUNTIF(E50:HQ50,"A") | N7: =COUNTIF(E50:HQ50,"B") | O7: =COUNTA(E9:HT9)
F9: UTCID01 | G9: UTCID02 | H9: UTCID03 | I9: UTCID04 | J9: UTCID05 | K9: UTCID06 | L9: UTCID07 | M9: UTCID08 | N9: UTCID09 | O9: UTCID10
A10: Condition | B10: Precondition
B11: auth context
D12: Authenticated user is available | F12: O | G12: O | H12: O | I12: O | J12: O | K12: O | L12: O | M12: O | N12: O | O12: O
B13: contract context
D14: Contract is loadable | G14: O | H14: O | I14: O | J14: O | K14: O | L14: O | M14: O | N14: O | O14: O
B15: project context
D16: Project context is loadable | G16: O | H16: O | I16: O | J16: O | K16: O | L16: O | M16: O | N16: O | O16: O
B17: contentHash
D18: contentHash is blank | F18: O
D19: contentHash is whitespace-only | F19: O
D20: Matches latest signable content | G20: O | H20: O | J20: O | K20: O | L20: O | M20: O | N20: O | O20: O
B21: signer access
D22: User is a required contract party | H22: O | I22: O | J22: O | K22: O | L22: O | M22: O | N22: O | O22: O
B23: contract status
D24: Contract status = SENT | I24: O | J24: O | K24: O | L24: O | M24: O | N24: O | O24: O
B25: legacy data
D26: commercialContext or snapshot is missing | M26: O
B27: existing sign
D28: Digital signature already exists | J28: O
B29: save result
D30: save(DigitalSignatureEntity) raises 23505 | K30: O
B31: remaining signers
D32: Required signers still missing after save | L32: O | M32: O
B33: archive persist
D34: Archive persistence unavailable | O34: O
B35: final signer
D36: Current signer completes all required signatures | N36: O | O36: O
A37: Confirm | B37: Return
D38: Return Pending Signatures | L38: O | M38: O
D39: Return Signed | N39: O | O39: O
B40: Exception
D41: Throw validation / conflict / duplicate-sign error | F41: O | G41: O | H41: O | I41: O | J41: O | K41: O
B42: Verification
...

Sheet Update Draft
A2: Function Code | C2: ='Function List'!E16 | F2: Function Name | L2: ='Function List'!D16
A3: Created By | C3: Nguyen Phuc An | F3: Executed By | L3: Nguyen Phuc An
A4: Lines of code | C4: 67 | F4: Lack of test cases | L4: 0
A5: Test requirement | C5: Verify updateDraft forwards dto values and enforces DRAFT-only edits, no-signature guardrails, legal-signature reset, and contentHash recomputation.
A6: Passed | C6: Failed | F6: Untested | L6: N/A/B | O6: Total Test Cases
A7: =COUNTIF(F51:HQ51,"P") | C7: =COUNTIF(F51:HQ51,"F") | F7: =SUM(O7,- A7,- C7) | L7: =COUNTIF(E50:HQ50,"N") | M7: =COUNTIF(E50:HQ50,"A") | N7: =COUNTIF(E50:HQ50,"B") | O7: =COUNTA(E9:HT9)
F9: UTCID01 | G9: UTCID02 | H9: UTCID03 | I9: UTCID04 | J9: UTCID05
A10: Condition | B10: Precondition
B11: auth context
D12: Authenticated user is available | F12: O | G12: O | H12: O | I12: O | J12: O
B13: user role
D14: Current user role is BROKER | F14: O | G14: O | H14: O | I14: O | J14: O
B15: contractId
D16: Draft contract id is supplied | F16: O | G16: O | H16: O | I16: O | J16: O
B17: draft dto
D18: title patch is provided | F18: O | G18: O | J18: O
D19: currency patch is provided | F19: O | G19: O | J19: O
D20: milestoneSnapshot patch is provided | F20: O | G20: O | J20: O
B21: status
D22: Contract status is DRAFT | F22: O | G22: O | I22: O | J22: O
B23: signatures
D24: No digital signatures exist yet | G24: O
B25: guardrail
D26: Contract is not editable | H26: O
D27: Signing already started on the draft | I27: O
B28: Exception source
D29: Update fails in service / controller | J29: O
A37: Confirm | B37: Return
D38: Return updated draft | F38: O | G38: O
D39: Reject non-editable draft update | H39: O | I39: O
B40: Exception
D41: Propagate draft update error | J41: O
B42: Verification
D43: Service receives user, id, and dto | F43: O | J43: O
D44: Rebuild terms, commercialContext, and contentHash | G44: O
D45: Reset signature provider / legal progress | G45: O
D46: Update shell project currency and totalBudget | G46: O
A50: Result | B50: Type(N : Normal, A : Abnormal, B : Boundary) | F50: N | G50: N | H50: A | I50: A | J50: A
B51: Passed/Failed | F51: P | G51: P | H51: P | I51: P | J51: P
B52: Executed Date | F52: 46111 | G52: 46111 | H52: 46111 | I52: 46111 | J52: 46111
...

Sheet Send Draft
A2: Function Code | C2: ='Function List'!E17 | F2: Function Name | L2: ='Function List'!D17
A3: Created By | C3: Nguyen Phuc An | F3: Executed By | L3: Nguyen Phuc An
A4: Lines of code | C4: 53 | F4: Lack of test cases | L4: 0
A5: Test requirement | C5: Verify sendDraft only sends editable DRAFT contracts, recomputes terms/contentHash, and moves the contract into SENT for all required signers.
A6: Passed | C6: Failed | F6: Untested | L6: N/A/B | O6: Total Test Cases
A7: =COUNTIF(F51:HQ51,"P") | C7: =COUNTIF(F51:HQ51,"F") | F7: =SUM(O7,- A7,- C7) | L7: =COUNTIF(E50:HQ50,"N") | M7: =COUNTIF(E50:HQ50,"A") | N7: =COUNTIF(E50:HQ50,"B") | O7: =COUNTA(E9:HT9)
F9: UTCID01 | G9: UTCID02 | H9: UTCID03 | I9: UTCID04
A10: Condition | B10: Precondition
B11: auth context
D12: Authenticated user is available | F12: O | G12: O | H12: O | I12: O
B13: user role
D14: Current user role is BROKER | F14: O | G14: O | H14: O | I14: O
B15: contractId
D16: Draft contract id is supplied | F16: O | G16: O | H16: O | I16: O
B17: status
D18: Contract status is DRAFT | F18: O | G18: O | I18: O
B19: signatures
D20: No signatures exist before sending | G20: O
B21: terms
D22: Snapshot / commercialContext are valid for signing | G22: O
B23: guardrail
D24: Contract is not DRAFT anymore | H24: O
B25: Exception source
D26: Send draft fails in service / controller | I26: O
A37: Confirm | B37: Return
D38: Return sent draft result | F38: O | G38: O
D39: Reject non-DRAFT contract send | H39: O
B40: Exception
D41: Propagate send draft error | I41: O
B42: Verification
D43: Recompute terms and contentHash, then set status SENT | G43: O
D44: Emit sent-for-signing update + participant notice | G44: O
D45: Service receives user and id | F45: O | I45: O
A50: Result | B50: Type(N : Normal, A : Abnormal, B : Boundary) | F50: N | G50: N | H50: A | I50: A
B51: Passed/Failed | F51: P | G51: P | H51: P | I51: P
B52: Executed Date | F52: 46111 | G52: 46111 | H52: 46111 | I52: 46111
B53: Defect ID

Sheet Discard Draft
A2: Function Code | C2: ='Function List'!E18 | F2: Function Name | L2: ='Function List'!D18
A3: Created By | C3: Nguyen Phuc An | F3: Executed By | L3: Nguyen Phuc An
A4: Lines of code | C4: 55 | F4: Lack of test cases | L4: 0
A5: Test requirement | C5: Verify discardDraft archives a pre-sign contract, cancels the shell project, unlocks the linked spec, and propagates discard failures.
A6: Passed | C6: Failed | F6: Untested | L6: N/A/B | O6: Total Test Cases
A7: =COUNTIF(F51:HQ51,"P") | C7: =COUNTIF(F51:HQ51,"F") | F7: =SUM(O7,- A7,- C7) | L7: =COUNTIF(E50:HQ50,"N") | M7: =COUNTIF(E50:HQ50,"A") | N7: =COUNTIF(E50:HQ50,"B") | O7: =COUNTA(E9:HT9)
F9: UTCID01 | G9: UTCID02 | H9: UTCID03 | I9: UTCID04
A10: Condition | B10: Precondition
B11: auth context
D12: Authenticated user is available | F12: O | G12: O | H12: O | I12: O
B13: user role
D14: Current user role is BROKER | F14: O | G14: O | H14: O | I14: O
B15: contractId
D16: Pre-sign contract id is supplied | F16: O | G16: O | H16: O | I16: O
B17: status
D18: Contract status is DRAFT | G18: O | H18: O
D19: Contract is SENT with zero signatures | G19: O | H19: O
B20: project shell
D21: Linked project can be canceled | G21: O | H21: O
B22: spec lock
D23: sourceSpec lock matches this contract | H23: O
B24: Exception source
D25: Discard fails in service / controller | I25: O
A37: Confirm | B37: Return
D38: Return archived draft result | F38: O | G38: O | H38: O
D39: Propagate discard error | I39: O
B40: Exception
B42: Verification
D43: Set contract status ARCHIVED and reset legal progress | G43: O | H43: O
D44: Cancel shell project | G44: O | H44: O
D45: Unlock source spec when lock matches contract id | H45: O
D46: Service receives user and id | F46: O | I46: O
A50: Result | B50: Type(N : Normal, A : Abnormal, B : Boundary) | F50: N | G50: N | H50: N | I50: A
B51: Passed/Failed | F51: P | G51: P | H51: P | I51: P
B52: Executed Date | F52: 46111 | G52: 46111 | H52: 46111 | I52: 46111
B53: Defect ID

Sheet Activate Project
A2: Function Code | C2: ='Function List'!E19 | F2: Function Name | L2: ='Function List'!D19
A3: Created By | C3: Nguyen Phuc An | F3: Executed By | L3: Nguyen Phuc An
A4: Lines of code | C4: 112 | F4: Lack of test cases | L4: 0
A5: Test requirement | C5: Verify activateProject clones runtime milestones from the frozen contract snapshot, creates escrows, updates project/contract status, and fails fast on stale runtime data.
A6: Passed | C6: Failed | F6: Untested | L6: N/A/B | O6: Total Test Cases
A7: =COUNTIF(F51:HQ51,"P") | C7: =COUNTIF(F51:HQ51,"F") | F7: =SUM(O7,- A7,- C7) | L7: =COUNTIF(E50:HQ50,"N") | M7: =COUNTIF(E50:HQ50,"A") | N7: =COUNTIF(E50:HQ50,"B") | O7: =COUNTA(E9:HT9)
F9: UTCID01 | G9: UTCID02 | H9: UTCID03 | I9: UTCID04
A10: Condition | B10: Precondition
B11: auth context
D12: Authenticated user is available | F12: O | G12: O | H12: O | I12: O
B13: access rule
D14: Current user is a contract party | F14: O | G14: O | H14: O | I14: O
B15: contractId
D16: Signed contract id is supplied | F16: O | G16: O | H16: O | I16: O
B17: contract state
D18: Contract is SIGNED + legally verified | G18: O | H18: O
B19: signatures
D20: All required parties have signed | G20: O | H20: O
B21: runtime data
D22: No existing milestones or they match snapshot | G22: O
D23: Existing project milestones are stale vs snapshot | H23: O
B24: Exception source
D25: Activation fails in service / controller | I25: O
A37: Confirm | B37: Return
D38: Return activated project result | F38: O | G38: O
D39: Fail fast on stale milestone mismatch | H39: O
B40: Exception
D41: Propagate activation error | I41: O
B42: Verification
D43: Clone runtime milestones + create escrows from snapshot | G43: O
D44: Set project IN_PROGRESS + contract ACTIVATED | G44: O
D45: Service receives user and contractId | F45: O | I45: O
A50: Result | B50: Type(N : Normal, A : Abnormal, B : Boundary) | F50: N | G50: N | H50: A | I50: A
B51: Passed/Failed | F51: P | G51: P | H51: P | I51: P
B52: Executed Date | F52: 46111 | G52: 46111 | H52: 46111 | I52: 46111
B53: Defect ID

Sheet Download Pdf
A2: Function Code | C2: ='Function List'!E20 | F2: Function Name | L2: ='Function List'!D20
A3: Created By | C3: Nguyen Phuc An | F3: Executed By | L3: Nguyen Phuc An
A4: Lines of code | C4: 24 | F4: Lack of test cases | L4: 0
A5: Test requirement | C5: Verify pdf download prefers archived artifacts, falls back to dynamic rendering when needed, writes attachment headers, and avoids partial response writes on failure.
A6: Passed | C6: Failed | F6: Untested | L6: N/A/B | O6: Total Test Cases
A7: =COUNTIF(F51:HQ51,"P") | C7: =COUNTIF(F51:HQ51,"F") | F7: =SUM(O7,- A7,- C7) | L7: =COUNTIF(E50:HQ50,"N") | M7: =COUNTIF(E50:HQ50,"A") | N7: =COUNTIF(E50:HQ50,"B") | O7: =COUNTA(E9:HT9)
F9: UTCID01 | G9: UTCID02 | H9: UTCID03 | I9: UTCID04
A10: Condition | B10: Precondition
B11: auth context
D12: Authenticated user is available | F12: O | G12: O | H12: O | I12: O
B13: contractId
D14: Contract id is supplied | F14: O | G14: O | H14: O | I14: O
B15: response
D16: Response object supports set + end | F16: O | I16: O
B17: archive pdf
D18: Archived artifact exists | G18: O
D19: Archived artifact is downloadable | G19: O
D20: Archive artifact is missing so dynamic rendering is required | H20: O
B21: Exception source
D22: PDF generation fails before response write | I22: O
A37: Confirm | B37: Return
D38: Set PDF attachment headers and end response buffer | F38: O
D39: Return archived PDF buffer | G39: O
B40: Exception
D41: Propagate pdf generation error | I41: O
B42: Verification
D43: Fallback to dynamic PDF rendering | H43: O
D44: Do not write response when service fails | I44: O
D45: Service receives user and contractId | F45: O | I45: O
A50: Result | B50: Type(N : Normal, A : Abnormal, B : Boundary) | F50: N | G50: N | H50: N | I50: A
B51: Passed/Failed | F51: P | G51: P | H51: P | I51: P
B52: Executed Date | F52: 46111 | G52: 46111 | H52: 46111 | I52: 46111
B53: Defect ID

Sheet List Payment Methods
A2: Function Code | C2: ='Function List'!E21 | F2: Function Name | L2: ='Function List'!D21
A3: Created By | C3: Nguyen Phuc An | F3: Executed By | L3: Nguyen Phuc An
A4: Lines of code | C4: 25 | F4: Lack of test cases | L4: 0
A5: Test requirement | C5: Cover GET /payment-methods with executed evidence for masked bank output, vaulted PayPal email fallback, empty-list handling, and unsupported-role rejection before service execution.
A6: Passed | C6: Failed | F6: Untested | L6: N/A/B | O6: Total Test Cases
A7: =COUNTIF(F51:HQ51,"P") | C7: =COUNTIF(F51:HQ51,"F") | F7: =SUM(O7,- A7,- C7) | L7: =COUNTIF(E50:HQ50,"N") | M7: =COUNTIF(E50:HQ50,"A") | N7: =COUNTIF(E50:HQ50,"B") | O7: =COUNTA(E9:HT9)
F9: UTCID01 | G9: UTCID02 | H9: UTCID03 | I9: UTCID04
A10: Condition | B10: Precondition
B11: auth context
D12: Authenticated user is available | F12: O | G12: O | H12: O | I12: O
B13: account role
D14: Role is supported for payment-method management | F14: O | G14: O | H14: O
D15: Role is unsupported for payment-method management | I15: O
B16: saved methods
D17: User has a saved bank account method | F17: O
D18: User has a vaulted PayPal method with metadata email only | G18: O
D19: User has no saved payment methods | H19: O
A37: Confirm | B37: Return
D38: returns saved payment method list | F38: O | G38: O
D39: returns empty array | H39: O
B40: Exception
D41: ForbiddenException: unsupported role cannot list payment methods | I41: O
B42: Verification
D43: masks bank account numbers in the response payload | F43: O
D44: falls back to vaulted payer email when paypalEmail is empty | G44: O
D45: calls listForUser with authenticated user.id | F45: O | G45: O | H45: O
A50: Result | B50: Type(N : Normal, A : Abnormal, B : Boundary) | F50: N | G50: N | H50: B | I50: A
B51: Passed/Failed | F51: P | G51: P | H51: P | I51: P
B52: Executed Date | F52: 46111 | G52: 46111 | H52: 46111 | I52: 46111
B53: Defect ID

Sheet Create Payment Method
A2: Function Code | C2: ='Function List'!E22 | F2: Function Name | L2: ='Function List'!D22
A3: Created By | C3: Nguyen Phuc An | F3: Executed By | L3: Nguyen Phuc An
A4: Lines of code | C4: 41 | F4: Lack of test cases | L4: 0
A5: Test requirement | C5: Cover POST /payment-methods with executed evidence for first-method default promotion, card creation, invalid card expiry, incomplete bank payload rejection, and unsupported-role blocking.
A6: Passed | C6: Failed | F6: Untested | L6: N/A/B | O6: Total Test Cases
A7: =COUNTIF(F51:HQ51,"P") | C7: =COUNTIF(F51:HQ51,"F") | F7: =SUM(O7,- A7,- C7) | L7: =COUNTIF(E50:HQ50,"N") | M7: =COUNTIF(E50:HQ50,"A") | N7: =COUNTIF(E50:HQ50,"B") | O7: =COUNTA(E9:HT9)
F9: UTCID01 | G9: UTCID02 | H9: UTCID03 | I9: UTCID04 | J9: UTCID05
A10: Condition | B10: Precondition
B11: auth context
D12: Authenticated user is available | F12: O | G12: O | H12: O | I12: O | J12: O
B13: account role
D14: Role is supported for payment-method management | F14: O | G14: O | H14: O | I14: O
D15: Role is unsupported for payment-method management | J15: O
B16: payment type
D17: Payload type is PAYPAL_ACCOUNT | F17: O
D18: Payload type is CARD_ACCOUNT | G18: O | H18: O
D19: Payload type is BANK_ACCOUNT with incomplete required fields | I19: O
B20: default rule
D21: This is the first saved method for the user | F21: O
B22: card expiry
D23: Card expiry month/year is already expired | H23: O
A37: Confirm | B37: Return
D38: returns created PayPal method with isDefault = TRUE | F38: O
D39: returns created card method with masked card metadata | G39: O
B40: Exception
D41: BadRequestException: expired card payload | H41: O
B42: Verification | D42: BadRequestException: incomplete bank account payload | I42: O
D43: auto-clears previous defaults when the first method becomes default | F43: O | J43: O
D44: builds displayName from the saved payment-method payload | F44: O | G44: O
D45: calls createForUser with authenticated user.id and dto | F45: O | G45: O | H45: O | I45: O
A50: Result | B50: Type(N : Normal, A : Abnormal, B : Boundary) | F50: N | G50: N | H50: B | I50: A | J50: A
B51: Passed/Failed | F51: P | G51: P | H51: P | I51: P | J51: P
B52: Executed Date | F52: 46111 | G52: 46111 | H52: 46111 | I52: 46111 | J52: 46111
B53: Defect ID

Sheet Set Default Payment Method
A2: Function Code | C2: ='Function List'!E23 | F2: Function Name | L2: ='Function List'!D23
A3: Created By | C3: Nguyen Phuc An | F3: Executed By | L3: Nguyen Phuc An
A4: Lines of code | C4: 20 | F4: Lack of test cases | L4: 0
A5: Test requirement | C5: Cover PATCH /payment-methods/:id/default with executed evidence for successful default switching, missing-method rejection, and unsupported-role blocking before service execution.
A6: Passed | C6: Failed | F6: Untested | L6: N/A/B | O6: Total Test Cases
A7: =COUNTIF(F51:HQ51,"P") | C7: =COUNTIF(F51:HQ51,"F") | F7: =SUM(O7,- A7,- C7) | L7: =COUNTIF(E50:HQ50,"N") | M7: =COUNTIF(E50:HQ50,"A") | N7: =COUNTIF(E50:HQ50,"B") | O7: =COUNTA(E9:HT9)
F9: UTCID01 | G9: UTCID02 | H9: UTCID03
A10: Condition | B10: Precondition
B11: auth context
D12: Authenticated user is available | F12: O | G12: O | H12: O
B13: account role
D14: Role is supported for payment-method management | F14: O | G14: O
D15: Role is unsupported for payment-method management | H15: O
B16: paymentMethodId
D17: Saved payment method id is supplied | F17: O
D18: Target payment method id does not exist for the current user | G18: O
A37: Confirm | B37: Return
D38: returns selected payment method with isDefault = TRUE | F38: O
B40: Exception
D41: NotFoundException: payment method does not exist for the current user | G41: O
B42: Verification | D42: ForbiddenException: unsupported role cannot set default payment method | H42: O
D43: clears any previous default before saving the selected method | F43: O
D44: calls setDefault with authenticated user.id and payment method id | F44: O | G44: O
A50: Result | B50: Type(N : Normal, A : Abnormal, B : Boundary) | F50: N | G50: A | H50: A
B51: Passed/Failed | F51: P | G51: P | H51: P
B52: Executed Date | F52: 46111 | G52: 46111 | H52: 46111
B53: Defect ID

Sheet Fund Milestone
A2: Function Code | C2: ='Function List'!E24 | F2: Function Name | L2: ='Function List'!D24
A3: Created By | C3: Nguyen Phuc An | F3: Executed By | L3: Nguyen Phuc An
A4: Lines of code | C4: 172 | F4: Lack of test cases | L4: 0
A5: Test requirement | C5: Cover milestone funding from controller header validation down to funding-service branches, including successful funding, card/sandbox flow, idempotent replay, key reuse conflicts, role checks, gateway checks, and escrow guardrails.
A6: Passed | C6: Failed | F6: Untested | L6: N/A/B | O6: Total Test Cases
A7: =COUNTIF(F51:HQ51,"P") | C7: =COUNTIF(F51:HQ51,"F") | F7: =SUM(O7,- A7,- C7) | L7: =COUNTIF(E50:HQ50,"N") | M7: =COUNTIF(E50:HQ50,"A") | N7: =COUNTIF(E50:HQ50,"B") | O7: =COUNTA(E9:HT9)
F9: UTCID01 | G9: UTCID02 | H9: UTCID03 | I9: UTCID04 | J9: UTCID05 | K9: UTCID06 | L9: UTCID07 | M9: UTCID08 | N9: UTCID09 | O9: UTCID10 | P9: UTCID11
A10: Condition | B10: Precondition
B11: auth context
D12: Authenticated user is available | G12: O | H12: O | I12: O | J12: O
B13: user role
D14: Authenticated user role is not CLIENT | K14: O
B15: milestoneId
D16: Milestone id path param is supplied | G16: O | H16: O | I16: O | J16: O | K16: O | L16: O | M16: O | N16: O | O16: O | P16: O
B17: idempotency key
D18: Idempotency-Key header is blank or missing | F18: O
D19: Idempotency-Key header is present | G19: O | H19: O | I19: O | J19: O | K19: O | L19: O | M19: O | N19: O | O19: O | P19: O
B20: funding dto
D21: gateway = INTERNAL_SANDBOX | G21: O | I21: O | J21: O | K21: O
D22: gateway = STRIPE | H22: O
D23: gateway is unsupported | L23: O
B24: payment method
D25: Selected payment method is CARD_ACCOUNT | H25: O | J25: O
D26: Selected payment method is BANK_ACCOUNT | M26: O
B27: idempotent replay
D28: Existing funding intent already completed for the same key | I28: O
D29: Same key is reused with a different payment method | J29: O
B30: escrow state
D31: Escrow is already fully funded | N31: O
D32: Escrow is under dispute | O32: O
D33: Escrow amount does not match milestone amount | P33: O
A37: Confirm | B37: Return
D38: returns successful funding result with escrow and wallet updates | G38: O | H38: O
D39: returns previously completed funding intent without duplicating side effects | I39: O
B40: Exception
D41: BadRequestException: Idempotency-Key header is required | F41: O
B42: Verification | D42: ConflictException: idempotency key is reused with a different payment method | J42: O
D43: persists one deposit transaction and one hold transaction on successful funding | G43: O | K43: O
D44: creates Stripe checkout session for saved card funding | H44: O | L44: O
D45: calls fundMilestone with milestoneId, payerId, dto, and idempotency key | G45: O | H45: O | I45: O | J45: O | K45: O | L45: O | M45: O | N45: O | O45: O | P45: O
...

Sheet Get My Wallet
A2: Function Code | C2: ='Function List'!E25 | F2: Function Name | L2: ='Function List'!D25
A3: Created By | C3: Nguyen Phuc An | F3: Executed By | L3: Nguyen Phuc An
A4: Lines of code | C4: 18 | F4: Lack of test cases | L4: 0
A5: Test requirement | C5: Cover GET /wallet/me with executed evidence for first-time wallet creation, freelancer awaiting-release computation, and broker awaiting-release computation in the returned snapshot.
A6: Passed | C6: Failed | F6: Untested | L6: N/A/B | O6: Total Test Cases
A7: =COUNTIF(F51:HQ51,"P") | C7: =COUNTIF(F51:HQ51,"F") | F7: =SUM(O7,- A7,- C7) | L7: =COUNTIF(E50:HQ50,"N") | M7: =COUNTIF(E50:HQ50,"A") | N7: =COUNTIF(E50:HQ50,"B") | O7: =COUNTA(E9:HT9)
F9: UTCID01 | G9: UTCID02 | H9: UTCID03
A10: Condition | B10: Precondition
B11: auth context
D12: Authenticated user is available | F12: O | G12: O | H12: O
B13: wallet state
D14: Wallet does not exist yet for the current user | F14: O
D15: Wallet already exists for the current user | G15: O | H15: O
B16: viewer role
D17: Authenticated user role is FREELANCER | G17: O
D18: Authenticated user role is BROKER | H18: O
B19: awaiting release
D20: Funded and disputed escrows contribute awaitingReleaseAmount | G20: O | H20: O
A37: Confirm | B37: Return
D38: returns wallet snapshot payload | F38: O | G38: O | H38: O
D39: returns awaitingReleaseAmount derived from escrow state | G39: O | H39: O
B40: Exception
B42: Verification
D43: creates a wallet record with USD defaults on first access | F43: O
D44: computes freelancer awaitingReleaseAmount from funded and disputed escrows | G44: O
D45: computes broker awaitingReleaseAmount from funded and disputed escrows | H45: O
A50: Result | B50: Type(N : Normal, A : Abnormal, B : Boundary) | F50: B | G50: N | H50: N
B51: Passed/Failed | F51: P | G51: P | H51: P
B52: Executed Date | F52: 46111 | G52: 46111 | H52: 46111
B53: Defect ID

Sheet Get My Wallet Transactions
A2: Function Code | C2: ='Function List'!E26 | F2: Function Name | L2: ='Function List'!D26
A3: Created By | C3: Nguyen Phuc An | F3: Executed By | L3: Nguyen Phuc An
A4: Lines of code | C4: 38 | F4: Lack of test cases | L4: 0
A5: Test requirement | C5: Cover GET /wallet/me/transactions with executed evidence for paged transaction listing, plus feature-level UTCs for paging normalization and range-filter query handling.
A6: Passed | C6: Failed | F6: Untested | L6: N/A/B | O6: Total Test Cases
A7: =COUNTIF(F51:HQ51,"P") | C7: =COUNTIF(F51:HQ51,"F") | F7: =SUM(O7,- A7,- C7) | L7: =COUNTIF(E50:HQ50,"N") | M7: =COUNTIF(E50:HQ50,"A") | N7: =COUNTIF(E50:HQ50,"B") | O7: =COUNTA(E9:HT9)
F9: UTCID01 | G9: UTCID02 | H9: UTCID03
A10: Condition | B10: Precondition
B11: auth context
D12: Authenticated user is available | F12: O | G12: O | H12: O
B13: query
D14: page query is supplied | F14: O | G14: O | H14: O
D15: limit query is supplied | F15: O | G15: O | H15: O
D16: range filter is supplied | F16: O | G16: O | H16: O
B17: paging
D18: page and limit values are positive integers | F18: O
D19: page or limit values are invalid and need normalization | G19: O
B20: range filter
D21: range query is supplied | H21: O
B22: service result
D23: WalletService resolves paged transactions | F23: O | G23: O | H23: O
A37: Confirm | B37: Return
D38: returns paged wallet transactions with wallet snapshot | F38: O | G38: O | H38: O
B40: Exception
B42: Verification
D43: normalizes invalid page and limit values to safe defaults | G43: O
D44: applies the requested createdAt range filter before querying transactions | H44: O
D45: calls listTransactions with authenticated user and paging filters | F45: O | G45: O | H45: O
A50: Result | B50: Type(N : Normal, A : Abnormal, B : Boundary) | F50: N | G50: B | H50: A
B51: Passed/Failed | F51: P | G51: P | H51: P
B52: Executed Date | F52: 46111 | G52: 46111 | H52: 46111
B53: Defect ID

Sheet Approve Specs
A2: Function Code | C2: ='Function List'!E27 | F2: Function Name | L2: ='Function List'!D27
A3: Created By | C3: Nguyen Phuc An | F3: Executed By | L3: Nguyen Phuc An
A4: Lines of code | C4: 31 | F4: Lack of test cases | L4: 0
A5: Test requirement | C5: Cover approve-specs with executed evidence for controller delegation, propagated service failures, BROKER_ASSIGNED approval, and unexpected-status warning flow.
A6: Passed | C6: Failed | F6: Untested | L6: N/A/B | O6: Total Test Cases
A7: =COUNTIF(F51:HQ51,"P") | C7: =COUNTIF(F51:HQ51,"F") | F7: =SUM(O7,- A7,- C7) | L7: =COUNTIF(E50:HQ50,"N") | M7: =COUNTIF(E50:HQ50,"A") | N7: =COUNTIF(E50:HQ50,"B") | O7: =COUNTA(E9:HT9)
F9: UTCID01 | G9: UTCID02 | H9: UTCID03 | I9: UTCID04
A10: Condition | B10: Precondition
D11: Project request id "req-1" is supplied | F11: O | G11: O | H11: O | I11: O
B12: service
D13: ProjectRequestsService.approveSpecs resolves successfully | F13: O | H13: O | I13: O
D14: ProjectRequestsService.approveSpecs throws an error | G14: O
B15: request status
D16: Request status is BROKER_ASSIGNED | H16: O
D17: Request status is DRAFT and still enters the approval flow | I17: O
A37: Confirm | B37: Return
D38: returns approve-specs result for request "req-1" | F38: O | H38: O | I38: O
D39: re-throws approve-specs service failure | G39: O
B40: Exception
B42: Verification
D43: persists request status = SPEC_APPROVED | H43: O | I43: O
D44: notifies both client and broker after the approval event | H44: O
D45: records a warning when specs are approved from an unexpected status | I45: O
D46: calls approveSpecs with the supplied request id | F46: O | G46: O
A50: Result | B50: Type(N : Normal, A : Abnormal, B : Boundary) | F50: N | G50: A | H50: N | I50: A
B51: Passed/Failed | F51: P | G51: P | H51: P | I51: P
B52: Executed Date | F52: 46111 | G52: 46111 | H52: 46111 | I52: 46111
B53: Defect ID

Sheet Convert To Project
A2: Function Code | C2: ='Function List'!E28 | F2: Function Name | L2: ='Function List'!D28
A3: Created By | C3: Nguyen Phuc An | F3: Executed By | L3: Nguyen Phuc An
A4: Lines of code | C4: 74 | F4: Lack of test cases | L4: 0
A5: Test requirement | C5: Cover convert-to-project with executed evidence for controller delegation, propagated service failures, successful linked-project conversion, missing finalized-spec rejection, and unauthorized-broker rejection.
A6: Passed | C6: Failed | F6: Untested | L6: N/A/B | O6: Total Test Cases
A7: =COUNTIF(F51:HQ51,"P") | C7: =COUNTIF(F51:HQ51,"F") | F7: =SUM(O7,- A7,- C7) | L7: =COUNTIF(E50:HQ50,"N") | M7: =COUNTIF(E50:HQ50,"A") | N7: =COUNTIF(E50:HQ50,"B") | O7: =COUNTA(E9:HT9)
F9: UTCID01 | G9: UTCID02 | H9: UTCID03 | I9: UTCID04 | J9: UTCID05
A10: Condition | B10: Precondition
D11: Project request id "req-1" is supplied | F11: O | G11: O | H11: O | I11: O | J11: O
B12: actor
D13: Authenticated actor is broker "broker-1" | F13: O | H13: O | I13: O
D14: Authenticated actor is broker "broker-2" | J14: O
B15: linked project
D16: Project "project-1" is already linked to request "req-1" | H16: O
B17: full spec
D18: No finalized full spec exists for request "req-1" | I18: O
B19: service
D20: ProjectRequestsService.convertToProject throws an error | G20: O
A37: Confirm | B37: Return
D38: returns project-conversion result for request "req-1" | F38: O | H38: O
D39: re-throws convert-to-project service failure | G39: O
B40: Exception
D41: BadRequestException: cannot convert request without a finalized full specification | I41: O
B42: Verification
D43: ForbiddenException: only the assigned broker or internal staff can convert this request | J43: O
D44: persists request status = CONVERTED_TO_PROJECT | H44: O
D45: emits system message for linked project "Kickoff Project" | H45: O
D46: calls convertToProject with request id and authenticated user | F46: O | G46: O
A50: Result | B50: Type(N : Normal, A : Abnormal, B : Boundary) | F50: N | G50: A | H50: N | I50: A | J50: A
B51: Passed/Failed | F51: P | G51: P | H51: P | I51: P | J51: P
B52: Executed Date | F52: 46111 | G52: 46111 | H52: 46111 | I52: 46111 | J52: 46111
B53: Defect ID

Sheet Get Pending Specs
A2: Function Code | C2: ='Function List'!E29 | F2: Function Name | L2: ='Function List'!D29
A3: Created By | C3: Nguyen Phuc An | F3: Executed By | L3: Nguyen Phuc An
A4: Lines of code | C4: 8 | F4: Lack of test cases | L4: 0
A5: Test requirement | C5: Cover GET /project-specs/pending with executed evidence for successful staff retrieval and propagated pending-spec lookup failures.
A6: Passed | C6: Failed | F6: Untested | L6: N/A/B | O6: Total Test Cases
A7: =COUNTIF(F51:HQ51,"P") | C7: =COUNTIF(F51:HQ51,"F") | F7: =SUM(O7,- A7,- C7) | L7: =COUNTIF(E50:HQ50,"N") | M7: =COUNTIF(E50:HQ50,"A") | N7: =COUNTIF(E50:HQ50,"B") | O7: =COUNTA(E9:HT9)
F9: UTCID01 | G9: UTCID02
A10: Condition | B10: Precondition
D11: Pending-specs route is invoked by staff or admin | F11: O | G11: O
B12: service
D13: ProjectSpecsService.findPendingSpecs resolves pending items | F13: O
D14: ProjectSpecsService.findPendingSpecs throws an error | G14: O
A37: Confirm | B37: Return
D38: returns pending specs for staff review | F38: O
B40: Exception
D41: re-throws pending-spec lookup failure | G41: O
B42: Verification
D43: calls findPendingSpecs without extra query parameters | F43: O | G43: O
A50: Result | B50: Type(N : Normal, A : Abnormal, B : Boundary) | F50: N | G50: A
B51: Passed/Failed | F51: P | G51: P
B52: Executed Date | F52: 46111 | G52: 46111
B53: Defect ID

Sheet Get Pending Client Review
A2: Function Code | C2: ='Function List'!E30 | F2: Function Name | L2: ='Function List'!D30
A3: Created By | C3: Nguyen Phuc An | F3: Executed By | L3: Nguyen Phuc An
A4: Lines of code | C4: 9 | F4: Lack of test cases | L4: 0
A5: Test requirement | C5: Cover GET /project-specs/client-review with executed evidence for successful client-specific retrieval and propagated client-review lookup failures.
A6: Passed | C6: Failed | F6: Untested | L6: N/A/B | O6: Total Test Cases
A7: =COUNTIF(F51:HQ51,"P") | C7: =COUNTIF(F51:HQ51,"F") | F7: =SUM(O7,- A7,- C7) | L7: =COUNTIF(E50:HQ50,"N") | M7: =COUNTIF(E50:HQ50,"A") | N7: =COUNTIF(E50:HQ50,"B") | O7: =COUNTA(E9:HT9)
F9: UTCID01 | G9: UTCID02
A10: Condition | B10: Precondition
D11: Authenticated client context is available | F11: O | G11: O
B12: clientId
D13: Client id "client-1" is available from auth context | F13: O | G13: O
B14: service
D15: ProjectSpecsService.findPendingClientReview resolves specs | F15: O
D16: ProjectSpecsService.findPendingClientReview throws an error | G16: O
A37: Confirm | B37: Return
D38: returns pending client-review specs for client "client-1" | F38: O
B40: Exception
D41: re-throws pending client-review lookup failure | G41: O
B42: Verification
D43: calls findPendingClientReview with authenticated client id "client-1" | F43: O | G43: O
A50: Result | B50: Type(N : Normal, A : Abnormal, B : Boundary) | F50: N | G50: A
B51: Passed/Failed | F51: P | G51: P
B52: Executed Date | F52: 46111 | G52: 46111
B53: Defect ID
