Workbook

Sheet Cover
B2: UNIT TEST CASE
A4: Project Name | B4: InterDev Platform | E4: Creator | F4: Nguyen Phuc An
A5: Project Code | B5: INTERDEV | E5: Reviewer/Approver | F5: Pending review
A6: Document Code | B6: =B5&"_UTC_"&"v2.0" | E6: Issue Date | F6: 46112
E7: Version | F7: 2
A10: Record of change
A11: Effective Date | B11: Version | C11: Change Item | D11: *A,D,M | E11: Change description | F11: Reference
A12: 46112 | B12: 2.0 | C12: API full endpoint coverage | D12: A | E12: All 40 requested API endpoints are covered in this final workbook. Layout keeps the mandatory Precondition row, renders subgroup labels under Condition, adapts Return/Exception/post-check sections to each sheet, and backs all 170 UTC with executed Jest tests. | F12: Current codebase + contracts.controller.spec.ts + contracts.service.spec.ts

Sheet Function List
E2: UNIT TEST CASE LIST
A4: Project Name | E4: InterDev Platform
A5: Project Code | E5: INTERDEV
A6: Normal number of Test cases/KLOC | E6: 300
A7: Test Environment Setup Description | E7: Source of truth: current codebase and executed Jest tests. Heavy flows expand from service/business rules, lighter routes stay controller-oriented. Note: code also has POST /contracts/:id/signature-sessions, which is not present in the provided list.
A10: No | B10: Requirement Name | C10: Class Name | D10: Function Name | E10: Function Code(Optional) | F10: Sheet Name | G10: Description | H10: Pre-Condition
A11: 1 | B11: UC-20 View Contract | C11: ContractsService | D11: List Contracts | E11: EP-043 | F11: List Contracts | G11: GET /contracts/list | H11: Authenticated user and contract participation or accepted staff role
A12: 2 | B12: UC-20 View Contract | C12: ContractsService | D12: Get Contract | E12: EP-044 | F12: Get Contract | G12: GET /contracts/:id | H12: Authenticated viewer and contract id and contract visibility rules
A13: 3 | B13: UC-102 Create Contract | C13: ContractsService | D13: Initialize Contract With Body | E13: EP-045 | F13: Init Contract Body | G13: POST /contracts/initialize | H13: Authenticated broker and dto.specId, optional freelancerId
A14: 4 | B14: UC-102 Create Contract | C14: ContractsService | D14: Initialize Contract | E14: EP-046 | F14: Init Contract Param | G14: POST /contracts/initialize/:specId | H14: Authenticated broker and specId path param and accepted freelancer resolution
A15: 5 | B15: UC-63 Sign Contract | C15: ContractsService | D15: Sign Contract | E15: EP-047 | F15: Sign Contract | G15: POST /contracts/sign/:contractId | H15: Authenticated user and contractId and contentHash and signing transaction
A16: 6 | B16: UC-102 Create Contract | C16: ContractsService | D16: Update Draft | E16: EP-048 | F16: Update Draft | G16: PATCH /contracts/:id/draft | H16: Authenticated broker and draft contract id and patch dto
A17: 7 | B17: UC-102 Create Contract | C17: ContractsService | D17: Send Draft | E17: EP-049 | F17: Send Draft | G17: POST /contracts/:id/send | H17: Authenticated broker and draft contract id
A18: 8 | B18: UC-102 Create Contract | C18: ContractsService | D18: Discard Draft | E18: EP-050 | F18: Discard Draft | G18: POST /contracts/:id/discard | H18: Authenticated broker and pre-sign contract id
A19: 9 | B19: UC-21 Finalizing Contract | C19: ContractsService | D19: Activate Project | E19: EP-051 | F19: Activate Project | G19: POST /contracts/activate/:contractId | H19: Authenticated contract party and signed contract id
A20: 10 | B20: UC-20 View Contract | C20: ContractsService | D20: Download Pdf | E20: EP-052 | F20: Download Pdf | G20: GET /contracts/:id/pdf | H20: Authenticated user and contract id and response object
A21: 11 | B21: UC-51 Choose Payment Method | C21: PaymentMethodsController | D21: List Payment Methods | E21: EP-182 | F21: List Payment Methods | G21: GET /payment-methods | H21: Authenticated CLIENT/BROKER/FREELANCER user invokes payment-method listing | Saved methods may exist or be empty | Unsupported roles are blocked before listing
A22: 12 | B22: UC-51 Choose Payment Method | C22: PaymentMethodsController | D22: Create Payment Method | E22: EP-183 | F22: Create Payment Method | G22: POST /payment-methods | H22: Authenticated CLIENT/BROKER/FREELANCER user submits create-payment-method payload | First method may become default automatically | Invalid card/bank payloads are rejected
... A50: 40 | B50: UC-105 Delete Milestone | C50: ProjectsService | D50: Delete Milestone | E50: EP-238 | F50: Delete Milestone | G50: DELETE /projects/milestones/:id | H50: Authenticated user deletes a milestone

Sheet Test Report
A2: UNIT TEST REPORT
A4: Project Name | B4: =Cover!B4 | D4: Creator | F4: Nguyen Phuc An
A5: Project Code | B5: =Cover!B5 | D5: Reviewer/Approver | F5: Pending review
A6: Document Code | B6: =Cover!B5&"_Test Report_"&"v2.0" | D6: Issue Date | F6: 46112
B7: This workbook covers all 40 endpoints from the provided list. Condition sections keep a mandatory Precondition row plus subgroup labels, post-check sections use Log message on business flows and Verification on technical flows, and all 170 UTC are backed by executed Jest tests. Additional contracts route found in code but not in the list: POST /contracts/:id/signature-sessions.
A11: No | B11: Function code | C11: Passed | D11: Failed | E11: Untested | F11: N | G11: A | H11: B | I11: Total Test Cases
A12: 1 | B12: EP-043 | C12: ='List Contracts'!A7 | D12: ='List Contracts'!C7 | E12: ='List Contracts'!F7 | F12: ='List Contracts'!L7 | G12: ='List Contracts'!M7 | H12: ='List Contracts'!N7 | I12: ='List Contracts'!O7
A13: 2 | B13: EP-044 | C13: ='Get Contract'!A7 | D13: ='Get Contract'!C7 | E13: ='Get Contract'!F7 | F13: ='Get Contract'!L7 | G13: ='Get Contract'!M7 | H13: ='Get Contract'!N7 | I13: ='Get Contract'!O7
A14: 3 | B14: EP-045 | C14: ='Init Contract Body'!A7 | D14: ='Init Contract Body'!C7 | E14: ='Init Contract Body'!F7 | F14: ='Init Contract Body'!L7 | G14: ='Init Contract Body'!M7 | H14: ='Init Contract Body'!N7 | I14: ='Init Contract Body'!O7
A15: 4 | B15: EP-046 | C15: ='Init Contract Param'!A7 | D15: ='Init Contract Param'!C7 | E15: ='Init Contract Param'!F7 | F15: ='Init Contract Param'!L7 | G15: ='Init Contract Param'!M7 | H15: ='Init Contract Param'!N7 | I15: ='Init Contract Param'!O7
A16: 5 | B16: EP-047 | C16: ='Sign Contract'!A7 | D16: ='Sign Contract'!C7 | E16: ='Sign Contract'!F7 | F16: ='Sign Contract'!L7 | G16: ='Sign Contract'!M7 | H16: ='Sign Contract'!N7 | I16: ='Sign Contract'!O7
A17: 6 | B17: EP-048 | C17: ='Update Draft'!A7 | D17: ='Update Draft'!C7 | E17: ='Update Draft'!F7 | F17: ='Update Draft'!L7 | G17: ='Update Draft'!M7 | H17: ='Update Draft'!N7 | I17: ='Update Draft'!O7
A18: 7 | B18: EP-049 | C18: ='Send Draft'!A7 | D18: ='Send Draft'!C7 | E18: ='Send Draft'!F7 | F18: ='Send Draft'!L7 | G18: ='Send Draft'!M7 | H18: ='Send Draft'!N7 | I18: ='Send Draft'!O7
A19: 8 | B19: EP-050 | C19: ='Discard Draft'!A7 | D19: ='Discard Draft'!C7 | E19: ='Discard Draft'!F7 | F19: ='Discard Draft'!L7 | G19: ='Discard Draft'!M7 | H19: ='Discard Draft'!N7 | I19: ='Discard Draft'!O7
A20: 9 | B20: EP-051 | C20: ='Activate Project'!A7 | D20: ='Activate Project'!C7 | E20: ='Activate Project'!F7 | F20: ='Activate Project'!L7 | G20: ='Activate Project'!M7 | H20: ='Activate Project'!N7 | I20: ='Activate Project'!O7
A21: 10 | B21: EP-052 | C21: ='Download Pdf'!A7 | D21: ='Download Pdf'!C7 | E21: ='Download Pdf'!F7 | F21: ='Download Pdf'!L7 | G21: ='Download Pdf'!M7 | H21: ='Download Pdf'!N7 | I21: ='Download Pdf'!O7
A22: 11 | B22: EP-182 | C22: ='List Payment Methods'!A7 | D22: ='List Payment Methods'!C7 | E22: ='List Payment Methods'!F7 | F22: ='List Payment Methods'!L7 | G22: ='List Payment Methods'!M7 | H22: ='List Payment Methods'!N7 | I22: ='List Payment Methods'!O7
A23: 12 | B23: EP-183 | C23: ='Create Payment Method'!A7 | D23: ='Create Payment Method'!C7 | E23: ='Create Payment Method'!F7 | F23: ='Create Payment Method'!L7 | G23: ='Create Payment Method'!M7 | H23: ='Create Payment Method'!N7 | I23: ='Create Payment Method'!O7
A24: 13 | B24: EP-184 | C24: ='Set Default Payment Method'!A7 | D24: ='Set Default Payment Method'!C7 | E24: ='Set Default Payment Method'!F7 | F24: ='Set Default Payment Method'!L7 | G24: ='Set Default Payment Method'!M7 | H24: ='Set Default Payment Method'!N7 | I24: ='Set Default Payment Method'!O7
A25: 14 | B25: EP-185 | C25: ='Fund Milestone'!A7 | D25: ='Fund Milestone'!C7 | E25: ='Fund Milestone'!F7 | F25: ='Fund Milestone'!L7 | G25: ='Fund Milestone'!M7 | H25: ='Fund Milestone'!N7 | I25: ='Fund Milestone'!O7
A26: 15 | B26: EP-186 | C26: ='Get My Wallet'!A7 | D26: ='Get My Wallet'!C7 | E26: ='Get My Wallet'!F7 | F26: ='Get My Wallet'!L7 | G26: ='Get My Wallet'!M7 | H26: ='Get My Wallet'!N7 | I26: ='Get My Wallet'!O7
A27: 16 | B27: EP-187 | C27: ='Get My Wallet Transactions'!A7 | D27: ='Get My Wallet Transactions'!C7 | E27: ='Get My Wallet Transactions'!F7 | F27: ='Get My Wallet Transactions'!L7 | G27: ='Get My Wallet Transactions'!M7 | H27: ='Get My Wallet Transactions'!N7 | I27: ='Get My Wallet Transactions'!O7
A28: 17 | B28: EP-208 | C28: ='Approve Specs'!A7 | D28: ='Approve Specs'!C7 | E28: ='Approve Specs'!F7 | F28: ='Approve Specs'!L7 | G28: ='Approve Specs'!M7 | H28: ='Approve Specs'!N7 | I28: ='Approve Specs'!O7
A29: 18 | B29: EP-209 | C29: ='Convert To Project'!A7 | D29: ='Convert To Project'!C7 | E29: ='Convert To Project'!F7 | F29: ='Convert To Project'!L7 | G29: ='Convert To Project'!M7 | H29: ='Convert To Project'!N7 | I29: ='Convert To Project'!O7
A30: 19 | B30: EP-211 | C30: ='Get Pending Specs'!A7 | D30: ='Get Pending Specs'!C7 | E30: ='Get Pending Specs'!F7 | F30: ='Get Pending Specs'!L7 | G30: ='Get Pending Specs'!M7 | H30: ='Get Pending Specs'!N7 | I30: ='Get Pending Specs'!O7
A31: 20 | B31: EP-212 | C31: ='Get Pending Client Review'!A7 | D31: ='Get Pending Client Review'!C7 | E31: ='Get Pending Client Review'!F7 | F31: ='Get Pending Client Review'!L7 | G31: ='Get Pending Client Review'!M7 | H31: ='Get Pending Client Review'!N7 | I31: ='Get Pending Client Review'!O7
A32: 21 | B32: EP-213 | C32: ='Get Specs In Final Review'!A7 | D32: ='Get Specs In Final Review'!C7 | E32: ='Get Specs In Final Review'!F7 | F32: ='Get Specs In Final Review'!L7 | G32: ='Get Specs In Final Review'!M7 | H32: ='Get Specs In Final Review'!N7 | I32: ='Get Specs In Final Review'!O7
A33: 22 | B33: EP-214 | C33: ='Get Specs By Request'!A7 | D33: ='Get Specs By Request'!C7 | E33: ='Get Specs By Request'!F7 | F33: ='Get Specs By Request'!L7 | G33: ='Get Specs By Request'!M7 | H33: ='Get Specs By Request'!N7 | I33: ='Get Specs By Request'!O7
A34: 23 | B34: EP-215 | C34: ='Get Client Spec'!A7 | D34: ='Get Client Spec'!C7 | E34: ='Get Client Spec'!F7 | F34: ='Get Client Spec'!L7 | G34: ='Get Client Spec'!M7 | H34: ='Get Client Spec'!N7 | I34: ='Get Client Spec'!O7
A35: 24 | B35: EP-216 | C35: ='Get Full Spec'!A7 | D35: ='Get Full Spec'!C7 | E35: ='Get Full Spec'!F7 | F35: ='Get Full Spec'!L7 | G35: ='Get Full Spec'!M7 | H35: ='Get Full Spec'!N7 | I35: ='Get Full Spec'!O7
A36: 25 | B36: EP-217 | C36: ='Get Spec'!A7 | D36: ='Get Spec'!C7 | E36: ='Get Spec'!F7 | F36: ='Get Spec'!L7 | G36: ='Get Spec'!M7 | H36: ='Get Spec'!N7 | I36: ='Get Spec'!O7
A37: 26 | B37: EP-218 | C37: ='Create Client Spec'!A7 | D37: ='Create Client Spec'!C7 | E37: ='Create Client Spec'!F7 | F37: ='Create Client Spec'!L7 | G37: ='Create Client Spec'!M7 | H37: ='Create Client Spec'!N7 | I37: ='Create Client Spec'!O7
A38: 27 | B38: EP-219 | C38: ='Update Client Spec'!A7 | D38: ='Update Client Spec'!C7 | E38: ='Update Client Spec'!F7 | F38: ='Update Client Spec'!L7 | G38: ='Update Client Spec'!M7 | H38: ='Update Client Spec'!N7 | I38: ='Update Client Spec'!O7
A39: 28 | B39: EP-220 | C39: ='Submit For Client Review'!A7 | D39: ='Submit For Client Review'!C7 | E39: ='Submit For Client Review'!F7 | F39: ='Submit For Client Review'!L7 | G39: ='Submit For Client Review'!M7 | H39: ='Submit For Client Review'!N7 | I39: ='Submit For Client Review'!O7
A40: 29 | B40: EP-221 | C40: ='Client Review'!A7 | D40: ='Client Review'!C7 | E40: ='Client Review'!F7 | F40: ='Client Review'!L7 | G40: ='Client Review'!M7 | H40: ='Client Review'!N7 | I40: ='Client Review'!O7
A41: 30 | B41: EP-222 | C41: ='Create Full Spec'!A7 | D41: ='Create Full Spec'!C7 | E41: ='Create Full Spec'!F7 | F41: ='Create Full Spec'!L7 | G41: ='Create Full Spec'!M7 | H41: ='Create Full Spec'!N7 | I41: ='Create Full Spec'!O7
A42: 31 | B42: EP-223 | C42: ='Update Full Spec'!A7 | D42: ='Update Full Spec'!C7 | E42: ='Update Full Spec'!F7 | F42: ='Update Full Spec'!L7 | G42: ='Update Full Spec'!M7 | H42: ='Update Full Spec'!N7 | I42: ='Update Full Spec'!O7
A43: 32 | B43: EP-224 | C43: ='Submit For Final Review'!A7 | D43: ='Submit For Final Review'!C7 | E43: ='Submit For Final Review'!F7 | F43: ='Submit For Final Review'!L7 | G43: ='Submit For Final Review'!M7 | H43: ='Submit For Final Review'!N7 | I43: ='Submit For Final Review'!O7
A44: 33 | B44: EP-225 | C44: ='Sign Spec'!A7 | D44: ='Sign Spec'!C7 | E44: ='Sign Spec'!F7 | F44: ='Sign Spec'!L7 | G44: ='Sign Spec'!M7 | H44: ='Sign Spec'!N7 | I44: ='Sign Spec'!O7
A45: 34 | B45: EP-226 | C45: ='Request Full Spec Changes'!A7 | D45: ='Request Full Spec Changes'!C7 | E45: ='Request Full Spec Changes'!F7 | F45: ='Request Full Spec Changes'!L7 | G45: ='Request Full Spec Changes'!M7 | H45: ='Request Full Spec Changes'!N7 | I45: ='Request Full Spec Changes'!O7
...

Sheet List Contracts
A2: Function Code | C2: ='Function List'!E11 | F2: Function Name | L2: ='Function List'!D11
A3: Created By | C3: Nguyen Phuc An | F3: Executed By | L3: Nguyen Phuc An
A4: Lines of code | C4: 42 | F4: Lack of test cases | L4: 0
A5: Test requirement | C5: Verify listByUser returns active contract summaries for permitted participants, excludes archived contracts, supports empty results, and surfaces repository failures.
A6: Passed | C6: Failed | F6: Untested | L6: N/A/B | O6: Total Test Cases
A7: =COUNTIF(F51:HQ51,"P") | C7: =COUNTIF(F51:HQ51,"F") | F7: =SUM(O7,- A7,- C7) | L7: =COUNTIF(E50:HQ50,"N") | M7: =COUNTIF(E50:HQ50,"A") | N7: =COUNTIF(E50:HQ50,"B") | O7: =COUNTA(E9:HT9)
F9: UTCID01 | G9: UTCID02 | H9: UTCID03 | I9: UTCID04 | J9: UTCID05
A10: Condition | B10: Precondition
D11: Authenticated user "user-1" is available | F11: O | G11: O | H11: O | I11: O | J11: O
D12: Authenticated user "user-1" participates in at least one active contract as client, broker, or freelancer | F12: O | I12: O
D13: Staff viewer "staff-1" is accepted on project "project-1" | J13: O
D14: Contract query returns one or more non-archived contracts for the authenticated user | F14: O | I14: O | J14: O
D15: Contract query returns no accessible contracts for the authenticated user | G15: O
D16: Archived contracts exist in storage but must be excluded from the returned list | I16: O
D17: Contracts repository throws an unexpected error during list lookup | H17: O
B18: userId
D19: "user-1" | F19: O | G19: O | H19: O | I19: O | J19: O
A41: Confirm | B41: Return
D42: Return contract summary list | F42: O | I42: O | J42: O
D43: Return empty array | G43: O
B44: Exception
D45: Propagate repository failure | H45: O
B46: Verification
D47: Filter out ARCHIVED status contracts | I47: O
D48: Map summary fields for list response | F48: O | I48: O | J48: O
D49: Query by current user id across participant roles | F49: O | G49: O | H49: O | I49: O | J49: O
A50: Result | B50: Type(N : Normal, A : Abnormal, B : Boundary) | F50: N | G50: N | H50: A | I50: A | J50: N
B51: Passed/Failed | F51: P | G51: P | H51: P | I51: P | J51: P
B52: Executed Date | F52: 46112 | G52: 46112 | H52: 46112 | I52: 46112 | J52: 46112
B53: Defect ID

Sheet Get Contract
A2: Function Code | C2: ='Function List'!E12 | F2: Function Name | L2: ='Function List'!D12
A3: Created By | C3: Nguyen Phuc An | F3: Executed By | L3: Nguyen Phuc An
A4: Lines of code | C4: 13 | F4: Lack of test cases | L4: 0
A5: Test requirement | C5: Verify findOneForUser enforces contract visibility, hydrates the read model, self-heals stale content hashes, and propagates lookup failures.
A6: Passed | C6: Failed | F6: Untested | L6: N/A/B | O6: Total Test Cases
A7: =COUNTIF(F51:HQ51,"P") | C7: =COUNTIF(F51:HQ51,"F") | F7: =SUM(O7,- A7,- C7) | L7: =COUNTIF(E50:HQ50,"N") | M7: =COUNTIF(E50:HQ50,"A") | N7: =COUNTIF(E50:HQ50,"B") | O7: =COUNTA(E9:HT9)
F9: UTCID01 | G9: UTCID02 | H9: UTCID03 | I9: UTCID04 | J9: UTCID05
A10: Condition | B10: Precondition
D11: Authenticated user "user-1" is available | F11: O | G11: O | H11: O | I11: O | J11: O
D12: Authenticated viewer belongs to contract "contract-1" | F12: O | I12: O
D13: Staff viewer "staff-1" is accepted on project "project-1" | G13: O
D14: Authenticated viewer is not a party of contract "contract-1" | H14: O
D15: Contract "contract-1" has a stale stored contentHash | I15: O
D16: Contract lookup for "contract-1" throws an unexpected error | J16: O
B17: viewerId
D18: "user-1" | F18: O | G18: O | H18: O | I18: O | J18: O
B19: contractId
D20: "contract-1" | F20: O | G20: O | H20: O | I20: O
A41: Confirm | B41: Return
D42: Return hydrated contract detail | F42: O | G42: O | I42: O
D43: Include requiredSignerCount and signedCount | F43: O | G43: O | I43: O
B44: Exception
D45: Reject unauthorized viewer | H45: O
B46: Verification
D47: Self-heal stale contentHash before response | I47: O
D48: Assert viewer permission before return | F48: O | G48: O | H48: O | I48: O
D49: Propagate lookup failure | J49: O
A50: Result | B50: Type(N : Normal, A : Abnormal, B : Boundary) | F50: N | G50: A | H50: A | I50: N | J50: A
B51: Passed/Failed | F51: P | G51: P | H51: P | I51: P | J51: P
B52: Executed Date | F52: 46112 | G52: 46112 | H52: 46112 | I52: 46112 | J52: 46112
B53: Defect ID

Sheet Init Contract Body
A2: Function Code | C2: ='Function List'!E13 | F2: Function Name | L2: ='Function List'!D13
A3: Created By | C3: Nguyen Phuc An | F3: Executed By | L3: Nguyen Phuc An
A4: Lines of code | C4: 132 | F4: Lack of test cases | L4: 0
A5: Test requirement | C5: Verify body-based initialization forwards dto values and creates a SENT contract with frozen snapshot, contentHash, and spec lock when the source spec is eligible.
A6: Passed | C6: Failed | F6: Untested | L6: N/A/B | O6: Total Test Cases
A7: =COUNTIF(F51:HQ51,"P") | C7: =COUNTIF(F51:HQ51,"F") | F7: =SUM(O7,- A7,- C7) | L7: =COUNTIF(E50:HQ50,"N") | M7: =COUNTIF(E50:HQ50,"A") | N7: =COUNTIF(E50:HQ50,"B") | O7: =COUNTA(E9:HT9)
F9: UTCID01 | G9: UTCID02 | H9: UTCID03 | I9: UTCID04
A10: Condition | B10: Precondition
D11: Authenticated broker "broker-1" is available | F11: O | G11: O | H11: O | I11: O
D12: freelancerId is omitted | G12: O | H12: O | I12: O
D13: Spec "spec-1" is unlocked and eligible for contract initialization | H13: O
D14: Spec "spec-1" milestones are frozen into snapshot and contract terms | H14: O
B15: brokerId
D16: "broker-1" | F16: O | G16: O | H16: O | I16: O
B17: specId
D18: "spec-1" | F18: O | G18: O | H18: O | I18: O
B19: freelancerId
D20: "freelancer-1" | F20: O
B21: freelancer
D22: Accepted freelancer is resolved for the request | H22: O
B23: Exception source
D24: Initialization fails in service | I24: O
A40: Confirm | B40: Return
D41: Initialize with specId and freelancerId | F41: O
D42: Initialize with specId only | G42: O
B43: Exception
D44: Propagate initialization error | I44: O
B45: Verification
D46: Create SENT contract with frozen snapshot and contentHash | H46: O
D47: Lock spec to saved contract id | H47: O
D48: Emit initialized contract update and participant notice | H48: O
D49: Service receives dto.specId + optional freelancerId | F49: O | G49: O | I49: O
A50: Result | B50: Type(N : Normal, A : Abnormal, B : Boundary) | F50: N | G50: N | H50: N | I50: A
B51: Passed/Failed | F51: P | G51: P | H51: P | I51: P
B52: Executed Date | F52: 46112 | G52: 46112 | H52: 46112 | I52: 46112
B53: Defect ID

Sheet Init Contract Param
A2: Function Code | C2: ='Function List'!E14 | F2: Function Name | L2: ='Function List'!D14
A3: Created By | C3: Nguyen Phuc An | F3: Executed By | L3: Nguyen Phuc An
A4: Lines of code | C4: 103 | F4: Lack of test cases | L4: 0
A5: Test requirement | C5: Verify path-based initialization reuses initializeProjectAndContract rules for spec existence, lock/duplicate state, broker access, freelancer readiness, and controller error propagation.
A6: Passed | C6: Failed | F6: Untested | L6: N/A/B | O6: Total Test Cases
A7: =COUNTIF(F51:HQ51,"P") | C7: =COUNTIF(F51:HQ51,"F") | F7: =SUM(O7,- A7,- C7) | L7: =COUNTIF(E50:HQ50,"N") | M7: =COUNTIF(E50:HQ50,"A") | N7: =COUNTIF(E50:HQ50,"B") | O7: =COUNTA(E9:HT9)
F9: UTCID01 | G9: UTCID02 | H9: UTCID03 | I9: UTCID04 | J9: UTCID05 | K9: UTCID06
A10: Condition | B10: Precondition
D11: Authenticated broker "broker-1" is available | F11: O | G11: O | H11: O | I11: O | J11: O | K11: O
D12: Spec "spec-1" exists | F12: O | H12: O | I12: O | J12: O
D13: Spec "spec-1" is unlocked and no active contract exists for it | F13: O | G13: O | I13: O | J13: O
D14: Authenticated broker "broker-1" owns request "req-1" | F14: O | G14: O | H14: O | J14: O
D15: Request "req-1" has accepted freelancer "freelancer-1" for phased flow | F15: O | G15: O | H15: O | I15: O
D16: Contract initialization for spec "spec-1" throws an unexpected error | K16: O
B17: brokerId
D18: "broker-1" | F18: O | G18: O | H18: O | I18: O | J18: O | K18: O
B19: specId
D20: "spec-1" | F20: O | G20: O | H20: O | I20: O | J20: O | K20: O
A42: Confirm | B42: Return
D43: Return initialized contract | F43: O
D44: Use path specId when calling service | F44: O | G44: O | H44: O | I44: O | J44: O | K44: O
B45: Exception
D46: Reject invalid precondition and stop initialization | G46: O | H46: O | I46: O | J46: O
B47: Verification
D48: Create SENT contract and shell project on success | F48: O
D49: Propagate initialization failure | K49: O
A50: Result | B50: Type(N : Normal, A : Abnormal, B : Boundary) | F50: N | G50: A | H50: A | I50: A | J50: A | K50: A
B51: Passed/Failed | F51: P | G51: P | H51: P | I51: P | J51: P | K51: P
B52: Executed Date | F52: 46112 | G52: 46112 | H52: 46112 | I52: 46112 | J52: 46112 | K52: 46112
B53: Defect ID

Sheet Sign Contract
A2: Function Code | C2: ='Function List'!E15 | F2: Function Name | L2: ='Function List'!D15
A3: Created By | C3: Nguyen Phuc An | F3: Executed By | L3: Nguyen Phuc An
A4: Lines of code | C4: 133 | F4: Lack of test cases | L4: 0
A5: Test requirement | C5: Verify service-level signContract rules for content hash validation, signer access, SENT-only signing, duplicate protection, legacy snapshot hydration, pending/full-sign outcomes, and degraded archive persistence.
A6: Passed | C6: Failed | F6: Untested | L6: N/A/B | O6: Total Test Cases
A7: =COUNTIF(F51:HQ51,"P") | C7: =COUNTIF(F51:HQ51,"F") | F7: =SUM(O7,- A7,- C7) | L7: =COUNTIF(E50:HQ50,"N") | M7: =COUNTIF(E50:HQ50,"A") | N7: =COUNTIF(E50:HQ50,"B") | O7: =COUNTA(E9:HT9)
F9: UTCID01 | G9: UTCID02 | H9: UTCID03 | I9: UTCID04 | J9: UTCID05 | K9: UTCID06 | L9: UTCID07 | M9: UTCID08 | N9: UTCID09 | O9: UTCID10
A10: Condition | B10: Precondition
D11: Authenticated user "broker-1" is available | F11: O | G11: O | H11: O | I11: O | J11: O | K11: O | L11: O | M11: O | N11: O | O11: O
D12: Contract "contract-1" and project "project-1" are loadable | G12: O | H12: O | I12: O | J12: O | K12: O | L12: O | M12: O | N12: O | O12: O
D13: Submitted contentHash is blank or contains only whitespace | F13: O
D14: Matches latest signable content | G14: O | H14: O | J14: O | K14: O | L14: O | M14: O | N14: O | O14: O
D15: User is a required contract party | H15: O | I15: O | J15: O | K15: O | L15: O | M15: O | N15: O | O15: O
D16: Contract status = SENT | I16: O | J16: O | K16: O | L16: O | M16: O | N16: O | O16: O
D17: Contract "contract-1" is missing commercialContext or milestone snapshot | M17: O
D18: Digital signature already exists | J18: O
D19: save(DigitalSignatureEntity) raises 23505 | K19: O
D20: Required signers still missing after save | L20: O | M20: O
D21: Archive persistence unavailable | O21: O
D22: Current signer completes all required signatures | N22: O | O22: O
B23: signerId
D24: "client-1" | F24: O | G24: O | H24: O | I24: O | J24: O | K24: O | L24: O | M24: O | N24: O | O24: O
A37: Confirm | B37: Return
D38: Return Pending Signatures | L38: O | M38: O
D39: Return Signed | N39: O | O39: O
B40: Exception
D41: Throw validation / conflict / duplicate-sign error | F41: O | G41: O | H41: O | I41: O | J41: O | K41: O
B42: Log message
D43: Do not open transaction for blank contentHash | F43: O
D44: Hydrate legacy snapshot before hash comparison | M44: O
D45: Save audit-only digital signature record | L45: O | M45: O | N45: O | O45: O
D46: Capture signer IP and user-agent metadata | M46: O | N46: O | O46: O
D47: Keep contract unsigned while signers remain | L47: O | M47: O
D48: Write SIGNED status, audit log, and full-sign notice | N48: O
D49: Still return Signed when archive persist is skipped | O49: O
A50: Result | B50: Type(N : Normal, A : Abnormal, B : Boundary) | F50: A | G50: A | H50: A | I50: A | J50: A | K50: A | L50: N | M50: N | N50: N | O50: A
B51: Passed/Failed | F51: P | G51: P | H51: P | I51: P | J51: P | K51: P | L51: P | M51: P | N51: P | O51: P
B52: Executed Date | F52: 46112 | G52: 46112 | H52: 46112 | I52: 46112 | J52: 46112 | K52: 46112 | L52: 46112 | M52: 46112 | N52: 46112 | O52: 46112
B53: Defect ID

Sheet Update Draft
A2: Function Code | C2: ='Function List'!E16 | F2: Function Name | L2: ='Function List'!D16
A3: Created By | C3: Nguyen Phuc An | F3: Executed By | L3: Nguyen Phuc An
A4: Lines of code | C4: 67 | F4: Lack of test cases | L4: 0
A5: Test requirement | C5: Verify updateDraft forwards dto values and enforces DRAFT-only edits, no-signature guardrails, legal-signature reset, and contentHash recomputation.
A6: Passed | C6: Failed | F6: Untested | L6: N/A/B | O6: Total Test Cases
A7: =COUNTIF(F51:HQ51,"P") | C7: =COUNTIF(F51:HQ51,"F") | F7: =SUM(O7,- A7,- C7) | L7: =COUNTIF(E50:HQ50,"N") | M7: =COUNTIF(E50:HQ50,"A") | N7: =COUNTIF(E50:HQ50,"B") | O7: =COUNTA(E9:HT9)
F9: UTCID01 | G9: UTCID02 | H9: UTCID03 | I9: UTCID04 | J9: UTCID05
A10: Condition | B10: Precondition
D11: Authenticated broker "broker-1" is available | F11: O | G11: O | H11: O | I11: O | J11: O
D12: Contract status is DRAFT | F12: O | G12: O | I12: O | J12: O
D13: No digital signatures exist yet | G13: O
D14: Contract "contract-1" is already SENT and no longer editable | H14: O
D15: Signing already started on the draft | I15: O
B16: brokerId
D17: "broker-1" | F17: O | G17: O | H17: O | I17: O | J17: O
B18: contractId
D19: "contract-1" | F19: O | G19: O | H19: O | I19: O | J19: O
B20: request body
D21: title patch is provided | F21: O | G21: O | J21: O
D22: currency patch is provided | F22: O | G22: O | J22: O
D23: milestoneSnapshot patch is provided | F23: O | G23: O | J23: O
B24: Exception source
D25: Update fails in service / controller | J25: O
A40: Confirm | B40: Return
D41: Return updated draft | F41: O | G41: O
D42: Reject non-editable draft update | H42: O | I42: O
B43: Exception
D44: Propagate draft update error | J44: O
B45: Verification
D46: Service receives user, id, and dto | F46: O | J46: O
D47: Rebuild terms, commercialContext, and contentHash | G47: O
D48: Reset signature provider / legal progress | G48: O
D49: Update shell project currency and totalBudget | G49: O
A50: Result | B50: Type(N : Normal, A : Abnormal, B : Boundary) | F50: N | G50: N | H50: A | I50: A | J50: A
B51: Passed/Failed | F51: P | G51: P | H51: P | I51: P | J51: P
B52: Executed Date | F52: 46112 | G52: 46112 | H52: 46112 | I52: 46112 | J52: 46112
B53: Defect ID

Sheet Send Draft
A2: Function Code | C2: ='Function List'!E17 | F2: Function Name | L2: ='Function List'!D17
A3: Created By | C3: Nguyen Phuc An | F3: Executed By | L3: Nguyen Phuc An
A4: Lines of code | C4: 53 | F4: Lack of test cases | L4: 0
A5: Test requirement | C5: Verify sendDraft only sends editable DRAFT contracts, recomputes terms/contentHash, and moves the contract into SENT for all required signers.
A6: Passed | C6: Failed | F6: Untested | L6: N/A/B | O6: Total Test Cases
A7: =COUNTIF(F51:HQ51,"P") | C7: =COUNTIF(F51:HQ51,"F") | F7: =SUM(O7,- A7,- C7) | L7: =COUNTIF(E50:HQ50,"N") | M7: =COUNTIF(E50:HQ50,"A") | N7: =COUNTIF(E50:HQ50,"B") | O7: =COUNTA(E9:HT9)
F9: UTCID01 | G9: UTCID02 | H9: UTCID03 | I9: UTCID04
A10: Condition | B10: Precondition
D11: Authenticated broker "broker-1" is available | F11: O | G11: O | H11: O | I11: O
D12: Contract status is DRAFT | F12: O | G12: O | I12: O
D13: No signatures exist before sending | G13: O
D14: Snapshot / commercialContext are valid for signing | G14: O
D15: Contract is not DRAFT anymore | H15: O
B16: brokerId
D17: "broker-1" | F17: O | G17: O | H17: O | I17: O
B18: contractId
D19: "contract-1" | F19: O | G19: O | H19: O | I19: O
B20: Exception source
D21: Send draft fails in service / controller | I21: O
A41: Confirm | B41: Return
D42: Return sent draft result | F42: O | G42: O
D43: Reject non-DRAFT contract send | H43: O
B44: Exception
D45: Propagate send draft error | I45: O
B46: Log message
D47: Recompute terms and contentHash, then set status SENT | G47: O
D48: Emit sent-for-signing update + participant notice | G48: O
D49: Service receives user and id | F49: O | I49: O
A50: Result | B50: Type(N : Normal, A : Abnormal, B : Boundary) | F50: N | G50: N | H50: A | I50: A
B51: Passed/Failed | F51: P | G51: P | H51: P | I51: P
B52: Executed Date | F52: 46112 | G52: 46112 | H52: 46112 | I52: 46112
B53: Defect ID

Sheet Discard Draft
A2: Function Code | C2: ='Function List'!E18 | F2: Function Name | L2: ='Function List'!D18
A3: Created By | C3: Nguyen Phuc An | F3: Executed By | L3: Nguyen Phuc An
A4: Lines of code | C4: 55 | F4: Lack of test cases | L4: 0
A5: Test requirement | C5: Verify discardDraft archives a pre-sign contract, cancels the shell project, unlocks the linked spec, and propagates discard failures.
A6: Passed | C6: Failed | F6: Untested | L6: N/A/B | O6: Total Test Cases
A7: =COUNTIF(F51:HQ51,"P") | C7: =COUNTIF(F51:HQ51,"F") | F7: =SUM(O7,- A7,- C7) | L7: =COUNTIF(E50:HQ50,"N") | M7: =COUNTIF(E50:HQ50,"A") | N7: =COUNTIF(E50:HQ50,"B") | O7: =COUNTA(E9:HT9)
F9: UTCID01 | G9: UTCID02 | H9: UTCID03 | I9: UTCID04
A10: Condition | B10: Precondition
D11: Authenticated broker "broker-1" is available | F11: O | G11: O | H11: O | I11: O
D12: Contract "contract-1" is DRAFT or still SENT with zero signatures | G12: O | H12: O
D13: Linked project can be canceled | G13: O | H13: O
B14: brokerId
D15: "broker-1" | F15: O | G15: O | H15: O | I15: O
B16: contractId
D17: "contract-1" | F17: O | G17: O | H17: O | I17: O
B18: spec lock
D19: sourceSpec lock matches this contract | H19: O
B20: Exception source
D21: Discard fails in service / controller | I21: O
A40: Confirm | B40: Return
D41: Return archived draft result | F41: O | G41: O | H41: O
D42: Propagate discard error | I42: O
B43: Exception
B45: Log message
D46: Set contract status ARCHIVED and reset legal progress | G46: O | H46: O
D47: Cancel shell project | G47: O | H47: O
D48: Unlock source spec when lock matches contract id | H48: O
D49: Service receives user and id | F49: O | I49: O
A50: Result | B50: Type(N : Normal, A : Abnormal, B : Boundary) | F50: N | G50: N | H50: N | I50: A
B51: Passed/Failed | F51: P | G51: P | H51: P | I51: P
B52: Executed Date | F52: 46112 | G52: 46112 | H52: 46112 | I52: 46112
B53: Defect ID

Sheet Activate Project
A2: Function Code | C2: ='Function List'!E19 | F2: Function Name | L2: ='Function List'!D19
A3: Created By | C3: Nguyen Phuc An | F3: Executed By | L3: Nguyen Phuc An
A4: Lines of code | C4: 112 | F4: Lack of test cases | L4: 0
A5: Test requirement | C5: Verify activateProject clones runtime milestones from the frozen contract snapshot, creates escrows, updates project/contract status, and fails fast on stale runtime data.
A6: Passed | C6: Failed | F6: Untested | L6: N/A/B | O6: Total Test Cases
A7: =COUNTIF(F51:HQ51,"P") | C7: =COUNTIF(F51:HQ51,"F") | F7: =SUM(O7,- A7,- C7) | L7: =COUNTIF(E50:HQ50,"N") | M7: =COUNTIF(E50:HQ50,"A") | N7: =COUNTIF(E50:HQ50,"B") | O7: =COUNTA(E9:HT9)
F9: UTCID01 | G9: UTCID02 | H9: UTCID03 | I9: UTCID04
A10: Condition | B10: Precondition
D11: Authenticated contract party "client-1" is available | F11: O | G11: O | H11: O | I11: O
D12: Contract is SIGNED + legally verified | G12: O | H12: O
D13: All required parties have signed | G13: O | H13: O
D14: No existing milestones or they match snapshot | G14: O
D15: Existing project milestones are stale vs snapshot | H15: O
B16: userId
D17: "user-1" | F17: O | G17: O | H17: O | I17: O
B18: contractId
D19: "contract-1" | F19: O | G19: O | H19: O | I19: O
B20: Exception source
D21: Activation fails in service / controller | I21: O
A41: Confirm | B41: Return
D42: Return activated project result | F42: O | G42: O
D43: Fail fast on stale milestone mismatch | H43: O
B44: Exception
D45: Propagate activation error | I45: O
B46: Log message
D47: Clone runtime milestones + create escrows from snapshot | G47: O
D48: Set project IN_PROGRESS + contract ACTIVATED | G48: O
D49: Service receives user and contractId | F49: O | I49: O
A50: Result | B50: Type(N : Normal, A : Abnormal, B : Boundary) | F50: N | G50: N | H50: A | I50: A
B51: Passed/Failed | F51: P | G51: P | H51: P | I51: P
B52: Executed Date | F52: 46112 | G52: 46112 | H52: 46112 | I52: 46112
B53: Defect ID

Sheet Download Pdf
A2: Function Code | C2: ='Function List'!E20 | F2: Function Name | L2: ='Function List'!D20
A3: Created By | C3: Nguyen Phuc An | F3: Executed By | L3: Nguyen Phuc An
A4: Lines of code | C4: 24 | F4: Lack of test cases | L4: 0
A5: Test requirement | C5: Verify pdf download prefers archived artifacts, falls back to dynamic rendering when needed, writes attachment headers, and avoids partial response writes on failure.
A6: Passed | C6: Failed | F6: Untested | L6: N/A/B | O6: Total Test Cases
A7: =COUNTIF(F51:HQ51,"P") | C7: =COUNTIF(F51:HQ51,"F") | F7: =SUM(O7,- A7,- C7) | L7: =COUNTIF(E50:HQ50,"N") | M7: =COUNTIF(E50:HQ50,"A") | N7: =COUNTIF(E50:HQ50,"B") | O7: =COUNTA(E9:HT9)
F9: UTCID01 | G9: UTCID02 | H9: UTCID03 | I9: UTCID04
A10: Condition | B10: Precondition
D11: Authenticated user "user-1" is available | F11: O | G11: O | H11: O | I11: O
D12: Response object supports set + end | F12: O | I12: O
D13: Archived PDF artifact exists for contract "contract-1" and is downloadable | G13: O
D14: Archive artifact is missing so dynamic rendering is required | H14: O
B15: userId
D16: "user-1" | F16: O | G16: O | H16: O | I16: O
B17: contractId
D18: "contract-1" | F18: O | G18: O | H18: O | I18: O
B19: Exception source
D20: PDF generation fails before response write | I20: O
A41: Confirm | B41: Return
D42: Set PDF attachment headers and end response buffer | F42: O
D43: Return archived PDF buffer | G43: O
B44: Exception
D45: Propagate pdf generation error | I45: O
B46: Verification
D47: Fallback to dynamic PDF rendering | H47: O
D48: Do not write response when service fails | I48: O
D49: Service receives user and contractId | F49: O | I49: O
A50: Result | B50: Type(N : Normal, A : Abnormal, B : Boundary) | F50: N | G50: N | H50: N | I50: A
B51: Passed/Failed | F51: P | G51: P | H51: P | I51: P
B52: Executed Date | F52: 46112 | G52: 46112 | H52: 46112 | I52: 46112
B53: Defect ID

Sheet List Payment Methods
A2: Function Code | C2: ='Function List'!E21 | F2: Function Name | L2: ='Function List'!D21
A3: Created By | C3: Nguyen Phuc An | F3: Executed By | L3: Nguyen Phuc An
A4: Lines of code | C4: 25 | F4: Lack of test cases | L4: 0
A5: Test requirement | C5: Cover GET /payment-methods with executed evidence for masked bank output, vaulted PayPal email fallback, empty-list handling, and unsupported-role rejection before service execution.
A6: Passed | C6: Failed | F6: Untested | L6: N/A/B | O6: Total Test Cases
A7: =COUNTIF(F51:HQ51,"P") | C7: =COUNTIF(F51:HQ51,"F") | F7: =SUM(O7,- A7,- C7) | L7: =COUNTIF(E50:HQ50,"N") | M7: =COUNTIF(E50:HQ50,"A") | N7: =COUNTIF(E50:HQ50,"B") | O7: =COUNTA(E9:HT9)
F9: UTCID01 | G9: UTCID02 | H9: UTCID03 | I9: UTCID04
A10: Condition | B10: Precondition
D11: Authenticated broker "broker-1" is available | F11: O | G11: O | H11: O | I11: O
D12: Authenticated user role is CLIENT, BROKER, or FREELANCER | F12: O | G12: O | H12: O
D13: Role is unsupported for payment-method management | I13: O
D14: User has a saved bank account method | F14: O
D15: User has a vaulted PayPal method with metadata email only | G15: O
D16: User has no saved payment methods | H16: O
B17: brokerId
D18: "broker-1" | F18: O | G18: O | H18: O | I18: O
A41: Confirm | B41: Return
D42: returns saved payment method list | F42: O | G42: O
D43: returns empty array | H43: O
B44: Exception
D45: ForbiddenException: unsupported role cannot list payment methods | I45: O
B46: Verification
D47: masks bank account numbers in the response payload | F47: O
D48: falls back to vaulted payer email when paypalEmail is empty | G48: O
D49: calls listForUser with authenticated user.id | F49: O | G49: O | H49: O
A50: Result | B50: Type(N : Normal, A : Abnormal, B : Boundary) | F50: N | G50: N | H50: B | I50: A
B51: Passed/Failed | F51: P | G51: P | H51: P | I51: P
B52: Executed Date | F52: 46112 | G52: 46112 | H52: 46112 | I52: 46112
B53: Defect ID

Sheet Create Payment Method
A2: Function Code | C2: ='Function List'!E22 | F2: Function Name | L2: ='Function List'!D22
A3: Created By | C3: Nguyen Phuc An | F3: Executed By | L3: Nguyen Phuc An
A4: Lines of code | C4: 41 | F4: Lack of test cases | L4: 0
A5: Test requirement | C5: Cover POST /payment-methods with executed evidence for first-method default promotion, card creation, invalid card expiry, incomplete bank payload rejection, and unsupported-role blocking.
A6: Passed | C6: Failed | F6: Untested | L6: N/A/B | O6: Total Test Cases
A7: =COUNTIF(F51:HQ51,"P") | C7: =COUNTIF(F51:HQ51,"F") | F7: =SUM(O7,- A7,- C7) | L7: =COUNTIF(E50:HQ50,"N") | M7: =COUNTIF(E50:HQ50,"A") | N7: =COUNTIF(E50:HQ50,"B") | O7: =COUNTA(E9:HT9)
F9: UTCID01 | G9: UTCID02 | H9: UTCID03 | I9: UTCID04 | J9: UTCID05
A10: Condition | B10: Precondition
D11: Authenticated broker "broker-1" is available | F11: O | G11: O | H11: O | I11: O | J11: O
D12: Authenticated user role is CLIENT, BROKER, or FREELANCER | F12: O | G12: O | H12: O | I12: O
D13: Role is unsupported for payment-method management | J13: O
D14: Payload type is PAYPAL_ACCOUNT | F14: O
D15: Payload type is CARD_ACCOUNT | G15: O | H15: O
D16: Payload type is BANK_ACCOUNT with incomplete required fields | I16: O
B17: brokerId
D18: "broker-1" | F18: O | G18: O | H18: O | I18: O | J18: O
B19: default rule
D20: This is the first saved method for the user | F20: O
B21: card expiry
D22: Card expiry month/year is already expired | H22: O
A39: Confirm | B39: Return
D40: returns created PayPal method with isDefault = TRUE | F40: O
D41: returns created card method with masked card metadata | G41: O
B42: Exception
D43: BadRequestException: expired card payload | H43: O
D44: BadRequestException: incomplete bank account payload | I44: O
D45: ForbiddenException: unsupported role cannot create payment methods | J45: O
B46: Verification
D47: auto-clears previous defaults when the first method becomes default | F47: O
D48: builds displayName from the saved payment-method payload | F48: O | G48: O
D49: calls createForUser with authenticated user.id and dto | F49: O | G49: O | H49: O | I49: O
A50: Result | B50: Type(N : Normal, A : Abnormal, B : Boundary) | F50: N | G50: N | H50: B | I50: A | J50: A
B51: Passed/Failed | F51: P | G51: P | H51: P | I51: P | J51: P
B52: Executed Date | F52: 46112 | G52: 46112 | H52: 46112 | I52: 46112 | J52: 46112
B53: Defect ID

Sheet Set Default Payment Method
A2: Function Code | C2: ='Function List'!E23 | F2: Function Name | L2: ='Function List'!D23
A3: Created By | C3: Nguyen Phuc An | F3: Executed By | L3: Nguyen Phuc An
A4: Lines of code | C4: 20 | F4: Lack of test cases | L4: 0
A5: Test requirement | C5: Cover PATCH /payment-methods/:id/default with executed evidence for successful default switching, missing-method rejection, and unsupported-role blocking before service execution.
A6: Passed | C6: Failed | F6: Untested | L6: N/A/B | O6: Total Test Cases
A7: =COUNTIF(F51:HQ51,"P") | C7: =COUNTIF(F51:HQ51,"F") | F7: =SUM(O7,- A7,- C7) | L7: =COUNTIF(E50:HQ50,"N") | M7: =COUNTIF(E50:HQ50,"A") | N7: =COUNTIF(E50:HQ50,"B") | O7: =COUNTA(E9:HT9)
F9: UTCID01 | G9: UTCID02 | H9: UTCID03
A10: Condition | B10: Precondition
D11: Authenticated broker "broker-1" is available | F11: O | G11: O | H11: O
D12: Authenticated user role is CLIENT, BROKER, or FREELANCER | F12: O | G12: O
D13: Role is unsupported for payment-method management | H13: O
D14: Target payment method id does not exist for the current user | G14: O
B15: brokerId
D16: "broker-1" | F16: O | G16: O | H16: O
B17: paymentMethodId
D18: "payment-method-1" | F18: O
A42: Confirm | B42: Return
D43: returns selected payment method with isDefault = TRUE | F43: O
B44: Exception
D45: NotFoundException: payment method does not exist for the current user | G45: O
D46: ForbiddenException: unsupported role cannot set default payment method | H46: O
B47: Verification
D48: clears any previous default before saving the selected method | F48: O
D49: calls setDefault with authenticated user.id and payment method id | F49: O | G49: O
A50: Result | B50: Type(N : Normal, A : Abnormal, B : Boundary) | F50: N | G50: A | H50: A
B51: Passed/Failed | F51: P | G51: P | H51: P
B52: Executed Date | F52: 46112 | G52: 46112 | H52: 46112
B53: Defect ID

Sheet Fund Milestone
A2: Function Code | C2: ='Function List'!E24 | F2: Function Name | L2: ='Function List'!D24
A3: Created By | C3: Nguyen Phuc An | F3: Executed By | L3: Nguyen Phuc An
A4: Lines of code | C4: 172 | F4: Lack of test cases | L4: 0
A5: Test requirement | C5: Cover milestone funding from controller header validation down to funding-service branches, including successful funding, card/sandbox flow, idempotent replay, key reuse conflicts, role checks, gateway checks, and escrow guardrails.
A6: Passed | C6: Failed | F6: Untested | L6: N/A/B | O6: Total Test Cases
A7: =COUNTIF(F51:HQ51,"P") | C7: =COUNTIF(F51:HQ51,"F") | F7: =SUM(O7,- A7,- C7) | L7: =COUNTIF(E50:HQ50,"N") | M7: =COUNTIF(E50:HQ50,"A") | N7: =COUNTIF(E50:HQ50,"B") | O7: =COUNTA(E9:HT9)
F9: UTCID01 | G9: UTCID02 | H9: UTCID03 | I9: UTCID04 | J9: UTCID05 | K9: UTCID06 | L9: UTCID07 | M9: UTCID08 | N9: UTCID09 | O9: UTCID10 | P9: UTCID11
A10: Condition | B10: Precondition
D11: Authenticated client "client-1" is available | G11: O | H11: O | I11: O | J11: O
D12: Authenticated user role is not CLIENT | K12: O
D13: Idempotency-Key header = "fund-key-1" is present | G13: O | H13: O | I13: O | J13: O | K13: O | L13: O | M13: O | N13: O | O13: O | P13: O
D14: Funding gateway is unsupported | L14: O
D15: Payment method "payment-method-1" is CARD_ACCOUNT | H15: O | J15: O
D16: Payment method "payment-method-1" is BANK_ACCOUNT | M16: O
D17: Idempotency key "fund-key-1" already completed a funding intent | I17: O
D18: Idempotency key "fund-key-1" is reused with a different payment method | J18: O
D19: Escrow linked to milestone "milestone-1" is already fully funded | N19: O
D20: Escrow linked to milestone "milestone-1" is currently under dispute | O20: O
D21: Escrow amount does not match milestone "milestone-1" amount | P21: O
B22: clientId
D23: "client-1" | G23: O | H23: O | I23: O | J23: O
B24: milestoneId
D25: "milestone-1" | G25: O | H25: O | I25: O | J25: O | K25: O | L25: O | M25: O | N25: O | O25: O | P25: O
B26: Idempotency-Key
D27: Idempotency-Key header is blank or missing | F27: O
B28: gateway
D29: "INTERNAL_SANDBOX" | G29: O | I29: O | J29: O | K29: O
B30: gateway
D31: "STRIPE" | H31: O
A34: Confirm | B34: Return
D35: returns successful funding result with escrow and wallet updates | G35: O | H35: O
D36: returns previously completed funding intent without duplicating side effects | I36: O
B37: Exception
D38: BadRequestException: Idempotency-Key header is required | F38: O
D39: ConflictException: idempotency key is reused with a different payment method | J39: O
D40: ForbiddenException: only the client can fund the milestone | K40: O
D41: NotImplementedException: gateway adapter is not wired | L41: O
D42: BadRequestException: bank methods cannot fund milestones | M42: O
D43: BadRequestException: escrow is already funded | N43: O
D44: ConflictException: disputed escrow cannot be funded | O44: O
...

Sheet Get My Wallet
A2: Function Code | C2: ='Function List'!E25 | F2: Function Name | L2: ='Function List'!D25
A3: Created By | C3: Nguyen Phuc An | F3: Executed By | L3: Nguyen Phuc An
A4: Lines of code | C4: 18 | F4: Lack of test cases | L4: 0
A5: Test requirement | C5: Cover GET /wallet/me with executed evidence for first-time wallet creation, freelancer awaiting-release computation, and broker awaiting-release computation in the returned snapshot.
A6: Passed | C6: Failed | F6: Untested | L6: N/A/B | O6: Total Test Cases
A7: =COUNTIF(F51:HQ51,"P") | C7: =COUNTIF(F51:HQ51,"F") | F7: =SUM(O7,- A7,- C7) | L7: =COUNTIF(E50:HQ50,"N") | M7: =COUNTIF(E50:HQ50,"A") | N7: =COUNTIF(E50:HQ50,"B") | O7: =COUNTA(E9:HT9)
F9: UTCID01 | G9: UTCID02 | H9: UTCID03
A10: Condition | B10: Precondition
D11: Authenticated broker "broker-1" is available | F11: O | G11: O | H11: O
D12: Wallet does not exist yet for the current user | F12: O
D13: Wallet already exists for the current user | G13: O | H13: O
D14: Authenticated user role is FREELANCER | G14: O
D15: Authenticated user role is BROKER | H15: O
D16: Funded and disputed escrows contribute awaitingReleaseAmount | G16: O | H16: O
B17: brokerId
D18: "broker-1" | F18: O | G18: O | H18: O
A41: Confirm | B41: Return
D42: returns wallet snapshot payload | F42: O | G42: O | H42: O
D43: returns awaitingReleaseAmount derived from escrow state | G43: O | H43: O
B44: Exception
B46: Verification
D47: creates a wallet record with USD defaults on first access | F47: O
D48: computes freelancer awaitingReleaseAmount from funded and disputed escrows | G48: O
D49: computes broker awaitingReleaseAmount from funded and disputed escrows | H49: O
A50: Result | B50: Type(N : Normal, A : Abnormal, B : Boundary) | F50: B | G50: N | H50: N
B51: Passed/Failed | F51: P | G51: P | H51: P
B52: Executed Date | F52: 46112 | G52: 46112 | H52: 46112
B53: Defect ID

Sheet Get My Wallet Transactions
A2: Function Code | C2: ='Function List'!E26 | F2: Function Name | L2: ='Function List'!D26
A3: Created By | C3: Nguyen Phuc An | F3: Executed By | L3: Nguyen Phuc An
A4: Lines of code | C4: 38 | F4: Lack of test cases | L4: 0
A5: Test requirement | C5: Cover GET /wallet/me/transactions with executed evidence for paged transaction listing, plus feature-level UTCs for paging normalization and range-filter query handling.
A6: Passed | C6: Failed | F6: Untested | L6: N/A/B | O6: Total Test Cases
A7: =COUNTIF(F51:HQ51,"P") | C7: =COUNTIF(F51:HQ51,"F") | F7: =SUM(O7,- A7,- C7) | L7: =COUNTIF(E50:HQ50,"N") | M7: =COUNTIF(E50:HQ50,"A") | N7: =COUNTIF(E50:HQ50,"B") | O7: =COUNTA(E9:HT9)
F9: UTCID01 | G9: UTCID02 | H9: UTCID03
A10: Condition | B10: Precondition
D11: Authenticated user "client-1" is available | F11: O | G11: O | H11: O
D12: page and limit values are positive integers | F12: O
D13: page or limit values are invalid and need normalization | G13: O
D14: range query is supplied | H14: O
D15: WalletService resolves paged transactions | F15: O | G15: O | H15: O
B16: userId
D17: "user-1" | F17: O | G17: O | H17: O
B18: page
D19: "1" | F19: O | G19: O | H19: O
B20: limit
D21: "10" | F21: O | G21: O | H21: O
B22: range
D23: "THIS_MONTH" | F23: O | G23: O | H23: O
A42: Confirm | B42: Return
D43: returns paged wallet transactions with wallet snapshot | F43: O | G43: O | H43: O
B44: Exception
B46: Verification
D47: normalizes invalid page and limit values to safe defaults | G47: O
D48: applies the requested createdAt range filter before querying transactions | H48: O
D49: calls listTransactions with authenticated user and paging filters | F49: O | G49: O | H49: O
A50: Result | B50: Type(N : Normal, A : Abnormal, B : Boundary) | F50: N | G50: B | H50: A
B51: Passed/Failed | F51: P | G51: P | H51: P
B52: Executed Date | F52: 46112 | G52: 46112 | H52: 46112
B53: Defect ID

Sheet Approve Specs
A2: Function Code | C2: ='Function List'!E27 | F2: Function Name | L2: ='Function List'!D27
A3: Created By | C3: Nguyen Phuc An | F3: Executed By | L3: Nguyen Phuc An
A4: Lines of code | C4: 31 | F4: Lack of test cases | L4: 0
A5: Test requirement | C5: Cover approve-specs with executed evidence for controller delegation, propagated service failures, BROKER_ASSIGNED approval, and unexpected-status warning flow.
A6: Passed | C6: Failed | F6: Untested | L6: N/A/B | O6: Total Test Cases
A7: =COUNTIF(F51:HQ51,"P") | C7: =COUNTIF(F51:HQ51,"F") | F7: =SUM(O7,- A7,- C7) | L7: =COUNTIF(E50:HQ50,"N") | M7: =COUNTIF(E50:HQ50,"A") | N7: =COUNTIF(E50:HQ50,"B") | O7: =COUNTA(E9:HT9)
F9: UTCID01 | G9: UTCID02 | H9: UTCID03 | I9: UTCID04
A10: Condition | B10: Precondition
D11: ProjectRequestsService.approveSpecs resolves successfully | F11: O | H11: O | I11: O
D12: ProjectRequestsService.approveSpecs throws an error | G12: O
D13: Request status is BROKER_ASSIGNED | H13: O
D14: Request status is DRAFT and still enters the approval flow | I14: O
B15: clientId
D16: "client-1" | F16: O | G16: O | H16: O | I16: O
B17: requestId
D18: "req-1" | F18: O | G18: O | H18: O | I18: O
A40: Confirm | B40: Return
D41: returns approve-specs result for request "req-1" | F41: O | H41: O | I41: O
D42: re-throws approve-specs service failure | G42: O
B43: Exception
B45: Log message
D46: persists request status = SPEC_APPROVED | H46: O | I46: O
D47: notifies both client and broker after the approval event | H47: O
D48: records a warning when specs are approved from an unexpected status | I48: O
D49: calls approveSpecs with the supplied request id | F49: O | G49: O
A50: Result | B50: Type(N : Normal, A : Abnormal, B : Boundary) | F50: N | G50: A | H50: N | I50: A
B51: Passed/Failed | F51: P | G51: P | H51: P | I51: P
B52: Executed Date | F52: 46112 | G52: 46112 | H52: 46112 | I52: 46112
B53: Defect ID

Sheet Convert To Project
A2: Function Code | C2: ='Function List'!E28 | F2: Function Name | L2: ='Function List'!D28
A3: Created By | C3: Nguyen Phuc An | F3: Executed By | L3: Nguyen Phuc An
A4: Lines of code | C4: 74 | F4: Lack of test cases | L4: 0
A5: Test requirement | C5: Cover convert-to-project with executed evidence for controller delegation, propagated service failures, successful linked-project conversion, missing finalized-spec rejection, and unauthorized-broker rejection.
A6: Passed | C6: Failed | F6: Untested | L6: N/A/B | O6: Total Test Cases
A7: =COUNTIF(F51:HQ51,"P") | C7: =COUNTIF(F51:HQ51,"F") | F7: =SUM(O7,- A7,- C7) | L7: =COUNTIF(E50:HQ50,"N") | M7: =COUNTIF(E50:HQ50,"A") | N7: =COUNTIF(E50:HQ50,"B") | O7: =COUNTA(E9:HT9)
F9: UTCID01 | G9: UTCID02 | H9: UTCID03 | I9: UTCID04 | J9: UTCID05
A10: Condition | B10: Precondition
D11: Authenticated actor is broker "broker-1" | F11: O | H11: O | I11: O
D12: Authenticated actor is broker "broker-2" | J12: O
D13: Project "project-1" is already linked to request "req-1" | H13: O
D14: No finalized full spec exists for request "req-1" | I14: O
D15: ProjectRequestsService.convertToProject throws an error | G15: O
B16: brokerId
D17: "broker-1" | F17: O | G17: O | H17: O | I17: O | J17: O
B18: requestId
D19: "req-1" | F19: O | G19: O | H19: O | I19: O | J19: O
A40: Confirm | B40: Return
D41: returns project-conversion result for request "req-1" | F41: O | H41: O
D42: re-throws convert-to-project service failure | G42: O
B43: Exception
D44: BadRequestException: cannot convert request without a finalized full specification | I44: O
B45: Log message
D46: ForbiddenException: only the assigned broker or internal staff can convert this request | J46: O
D47: persists request status = CONVERTED_TO_PROJECT | H47: O
D48: emits system message for linked project "Kickoff Project" | H48: O
D49: calls convertToProject with request id and authenticated user | F49: O | G49: O
A50: Result | B50: Type(N : Normal, A : Abnormal, B : Boundary) | F50: N | G50: A | H50: N | I50: A | J50: A
B51: Passed/Failed | F51: P | G51: P | H51: P | I51: P | J51: P
B52: Executed Date | F52: 46112 | G52: 46112 | H52: 46112 | I52: 46112 | J52: 46112
B53: Defect ID

Sheet Get Pending Specs
A2: Function Code | C2: ='Function List'!E29 | F2: Function Name | L2: ='Function List'!D29
A3: Created By | C3: Nguyen Phuc An | F3: Executed By | L3: Nguyen Phuc An
A4: Lines of code | C4: 8 | F4: Lack of test cases | L4: 0
A5: Test requirement | C5: Cover GET /project-specs/pending with executed evidence for successful staff retrieval and propagated pending-spec lookup failures.
A6: Passed | C6: Failed | F6: Untested | L6: N/A/B | O6: Total Test Cases
A7: =COUNTIF(F51:HQ51,"P") | C7: =COUNTIF(F51:HQ51,"F") | F7: =SUM(O7,- A7,- C7) | L7: =COUNTIF(E50:HQ50,"N") | M7: =COUNTIF(E50:HQ50,"A") | N7: =COUNTIF(E50:HQ50,"B") | O7: =COUNTA(E9:HT9)
F9: UTCID01 | G9: UTCID02
A10: Condition | B10: Precondition
D11: Pending-specs route is invoked by staff or admin | F11: O | G11: O
D12: ProjectSpecsService.findPendingSpecs resolves pending items | F12: O
D13: ProjectSpecsService.findPendingSpecs throws an error | G13: O
B14: userId
D15: "user-1" | F15: O | G15: O
A44: Confirm | B44: Return
D45: returns pending specs for staff review | F45: O
B46: Exception
D47: re-throws pending-spec lookup failure | G47: O
B48: Verification
D49: calls findPendingSpecs without extra query parameters | F49: O | G49: O
A50: Result | B50: Type(N : Normal, A : Abnormal, B : Boundary) | F50: N | G50: A
B51: Passed/Failed | F51: P | G51: P
B52: Executed Date | F52: 46112 | G52: 46112
B53: Defect ID

Sheet Get Pending Client Review
A2: Function Code | C2: ='Function List'!E30 | F2: Function Name | L2: ='Function List'!D30
A3: Created By | C3: Nguyen Phuc An | F3: Executed By | L3: Nguyen Phuc An
A4: Lines of code | C4: 9 | F4: Lack of test cases | L4: 0
A5: Test requirement | C5: Cover GET /project-specs/client-review with executed evidence for successful client-specific retrieval and propagated client-review lookup failures.
A6: Passed | C6: Failed | F6: Untested | L6: N/A/B | O6: Total Test Cases
A7: =COUNTIF(F51:HQ51,"P") | C7: =COUNTIF(F51:HQ51,"F") | F7: =SUM(O7,- A7,- C7) | L7: =COUNTIF(E50:HQ50,"N") | M7: =COUNTIF(E50:HQ50,"A") | N7: =COUNTIF(E50:HQ50,"B") | O7: =COUNTA(E9:HT9)
F9: UTCID01 | G9: UTCID02
A10: Condition | B10: Precondition
D11: Authenticated client "client-1" is available | F11: O | G11: O
D12: ProjectSpecsService.findPendingClientReview resolves specs | F12: O
D13: ProjectSpecsService.findPendingClientReview throws an error | G13: O
B14: clientId
D15: "client-1" | F15: O | G15: O
A44: Confirm | B44: Return
D45: returns pending client-review specs for client "client-1" | F45: O
B46: Exception
D47: re-throws pending client-review lookup failure | G47: O
B48: Verification
D49: calls findPendingClientReview with authenticated client id "client-1" | F49: O | G49: O
A50: Result | B50: Type(N : Normal, A : Abnormal, B : Boundary) | F50: N | G50: A
B51: Passed/Failed | F51: P | G51: P
B52: Executed Date | F52: 46112 | G52: 46112
B53: Defect ID

Sheet Get Specs In Final Review
A2: Function Code | C2: ='Function List'!E31 | F2: Function Name | L2: ='Function List'!D31
A3: Created By | C3: Nguyen Phuc An | F3: Executed By | L3: Nguyen Phuc An
A4: Lines of code | C4: 9 | F4: Lack of test cases | L4: 0
A5: Test requirement | C5: Cover GET /project-specs/final-review with executed evidence for successful party-specific retrieval and propagated lookup failures.
A6: Passed | C6: Failed | F6: Untested | L6: N/A/B | O6: Total Test Cases
A7: =COUNTIF(F51:HQ51,"P") | C7: =COUNTIF(F51:HQ51,"F") | F7: =SUM(O7,- A7,- C7) | L7: =COUNTIF(E50:HQ50,"N") | M7: =COUNTIF(E50:HQ50,"A") | N7: =COUNTIF(E50:HQ50,"B") | O7: =COUNTA(E9:HT9)
F9: UTCID01 | G9: UTCID02
A10: Condition | B10: Precondition
D11: Authenticated project party "user-1" is available | F11: O | G11: O
D12: Final-review query resolves specs for the authenticated party | F12: O
D13: Final-review query throws an unexpected error | G13: O
B14: userId
D15: "user-1" | F15: O | G15: O
A44: Confirm | B44: Return
D45: Return specs currently in FINAL_REVIEW for the authenticated party | F45: O
B46: Exception
D47: Propagate final-review lookup failure | G47: O
B48: Verification
D49: Call findSpecsInFinalReview with authenticated user id | F49: O | G49: O
A50: Result | B50: Type(N : Normal, A : Abnormal, B : Boundary) | F50: N | G50: A
B51: Passed/Failed | F51: P | G51: P
B52: Executed Date | F52: 46112 | G52: 46112
B53: Defect ID

Sheet Get Specs By Request
A2: Function Code | C2: ='Function List'!E32 | F2: Function Name | L2: ='Function List'!D32
A3: Created By | C3: Nguyen Phuc An | F3: Executed By | L3: Nguyen Phuc An
A4: Lines of code | C4: 10 | F4: Lack of test cases | L4: 0
A5: Test requirement | C5: Cover GET /project-specs/by-request/:requestId with executed evidence for successful request-scoped retrieval and propagated lookup failures.
A6: Passed | C6: Failed | F6: Untested | L6: N/A/B | O6: Total Test Cases
A7: =COUNTIF(F51:HQ51,"P") | C7: =COUNTIF(F51:HQ51,"F") | F7: =SUM(O7,- A7,- C7) | L7: =COUNTIF(E50:HQ50,"N") | M7: =COUNTIF(E50:HQ50,"A") | N7: =COUNTIF(E50:HQ50,"B") | O7: =COUNTA(E9:HT9)
F9: UTCID01 | G9: UTCID02
A10: Condition | B10: Precondition
D11: Authenticated user "user-1" is available | F11: O | G11: O
D12: Request-scoped spec query resolves specs for request "req-1" | F12: O
D13: Request-scoped spec query throws an unexpected error for request "req-1" | G13: O
B14: userId
D15: "user-1" | F15: O | G15: O
B16: requestId
D17: "req-1" | F17: O | G17: O
A44: Confirm | B44: Return
D45: Return specs linked to request "req-1" | F45: O
B46: Exception
D47: Propagate request-scoped spec lookup failure | G47: O
B48: Verification
D49: Call findSpecsByRequestIdForUser with authenticated user and request "req-1" | F49: O | G49: O
A50: Result | B50: Type(N : Normal, A : Abnormal, B : Boundary) | F50: N | G50: A
B51: Passed/Failed | F51: P | G51: P
B52: Executed Date | F52: 46112 | G52: 46112
B53: Defect ID

Sheet Get Client Spec
A2: Function Code | C2: ='Function List'!E33 | F2: Function Name | L2: ='Function List'!D33
A3: Created By | C3: Nguyen Phuc An | F3: Executed By | L3: Nguyen Phuc An
A4: Lines of code | C4: 10 | F4: Lack of test cases | L4: 0
A5: Test requirement | C5: Cover GET /project-specs/client-spec/:requestId with executed evidence for successful request-scoped client-spec retrieval and propagated lookup failures.
A6: Passed | C6: Failed | F6: Untested | L6: N/A/B | O6: Total Test Cases
A7: =COUNTIF(F51:HQ51,"P") | C7: =COUNTIF(F51:HQ51,"F") | F7: =SUM(O7,- A7,- C7) | L7: =COUNTIF(E50:HQ50,"N") | M7: =COUNTIF(E50:HQ50,"A") | N7: =COUNTIF(E50:HQ50,"B") | O7: =COUNTA(E9:HT9)
F9: UTCID01 | G9: UTCID02
A10: Condition | B10: Precondition
D11: Authenticated user "user-1" is available | F11: O | G11: O
D12: Client-spec lookup resolves the client spec for request "req-1" | F12: O
D13: Client-spec lookup throws an unexpected error for request "req-1" | G13: O
B14: clientId
D15: "client-1" | F15: O | G15: O
B16: requestId
D17: "req-1" | F17: O | G17: O
A44: Confirm | B44: Return
D45: Return the client spec linked to request "req-1" | F45: O
B46: Exception
D47: Propagate client-spec lookup failure | G47: O
B48: Verification
D49: Call findClientSpecForUser with authenticated user and request "req-1" | F49: O | G49: O
A50: Result | B50: Type(N : Normal, A : Abnormal, B : Boundary) | F50: N | G50: A
B51: Passed/Failed | F51: P | G51: P
B52: Executed Date | F52: 46112 | G52: 46112
B53: Defect ID

Sheet Get Full Spec
