Workbook
Name ACTION: #REF!

Sheet Guideline
A1: Guideline to make and understand Unit Test Case
A3: 1. Overview
A4: - In the template, Unit test cases are based on functions. Each sheet presents test cases for one function.
A5: - Cover: General information of the project and Unit Test cases
A6: - FunctionList: The list of Classes and Functions in the document. + To control that the number of Unit TC meets customer's requirement or the norm, user should fill value for 'Normal number of Test cases/KLOC'.
A7: + Click on Function link to open the related Test cases of the function. Note: You should create new Function sheet before creating the link
A8: - Test Report: provive the overview results of Functions Unit test: Test coverage, Test successful coverage (Summary, for normal/abnormal/boundary cases)
A9: Note: Should check the formula of "Sub Total" if you add more functions
A11: 2. Content in Test function sheet
A12: 2.1 Combination of test cases.
A13: - To verify that number of Unit TC meets customer's requirement or not. User has to fill number LOC of tested function and fill value of 'Normal number test cases/KLOC' item in FunctionList sheet, which is required by customer or normal value. The number of lacked TC is shown in 'Lack of test cases' item.
A14: - If the number of Unit TC does not meet the requirement, creator should explain the reasons.
... A47: - Test requirement: Brief description about requirements which are tested in this function, it is not mandatory.

Sheet Cover
B2: UNIT TEST CASE
A4: Project Name | B4: Edu Resource Management | E4: Creator | F4: Nguyễn Hữu Duy
A5: Project Code | B5: ERM | E5: Reviewer/Approver | F5: Nguyễn Chí Hậu
A6: Document Code | B6: =B5&"_"&"XXX"&"_"&"vx.x" -> ERM_XXX_vx.x | E6: Issue Date | F6: 45694
E7: Version | F7: 1.2
A10: Record of change
A11: Effective Date | B11: Version | C11: Change Item | D11: *A,D,M | E11: Change description | F11: Reference
A12: 45700 | B12: 1 | D12: A | E12: Add Test for Get All Room, Get Room Detail, Add Room, Update Room and Entry Excel To Room | F12: ERM_V.1
A13: 45700 | B13: 1.2 | D13: A | E13: Add Test for Get All Roles, Get Roles Detail, Add New Role, Update Role

Sheet Function List
E2: UNIT TEST CASE LIST
A4: Project Name | E4: Edu Resource Management
A5: Project Code | E5: ERM
A6: Normal number of Test cases/KLOC | E6: 300
A7: Test Environment Setup Description | E7: 1. SQL Server
A10: No | B10: Requirement Name | C10: Class Name | D10: Function Name | E10: Function Code(Optional) | F10: Sheet Name | G10: Description | H10: Pre-Condition
A11: 1 | C11: Room | D11: Get All Room | E11: Room - 1 | F11: Get All Room | G11: Get All Room with Detail | H11: Login as Authorize Account
A12: 2 | C12: Room | D12: Get Room Detail | E12: Room - 2 | F12: Get Room Detail | G12: Get Room Detail of One Room | H12: Login as Authorize Account
A13: 3 | C13: Room | D13: Add Room | E13: Room - 3 | F13: Add Room | G13: Add New Room | H13: Login as Authorize Account
A14: 4 | C14: Room | D14: Update Room | E14: Room - 4 | F14: Update Room | G14: Update Existing Room | H14: Login as Authorize Account
A15: 5 | C15: Room | D15: Entry Excel To Room | E15: Room - 5 | F15: Entry Excel To Room | G15: Entry Excel To Room | H15: Login as Authorize Account
A16: 6 | C16: Role | D16: Get All Role | E16: Role - 1 | F16: Get All Roles | G16: Get All Roles | H16: Login as Authorize Account
A17: 7 | C17: Role | D17: Get Role Detail | E17: Role - 2 | F17: Get Role Detail | G17: Get Role Detail | H17: Login as Authorize Account
A18: 8 | C18: Role | D18: Add New Role | E18: Role - 3 | F18: Add New Role | G18: Add New Role into Database | H18: Login as Authorize Account
A19: 9 | C19: Role | D19: Update Role | E19: Role - 4 | F19: Update Role | G19: Update Existing Role | H19: Login as Authorize Account
A20: 10
A21: 11
A22: 12
A23: 13
A24: 14
A25: 15
A26: 16
A27: 17
A28: 18
A29: 19
A30: 20
A31: 21
... A73: 64

Sheet Test Report
A2: UNIT TEST REPORT
A4: Project Name | B4: =Cover!B4 -> Edu Resource Management | D4: Creator | F4: Nguyễn Hữu Duy
A5: Project Code | B5: =Cover!B5 -> ERM | D5: Reviewer/Approver | F5: Nguyễn Hữu Duy
A6: Document Code | B6: =B5&"_"&"Test Report"&"_"&"v1.2" -> ERM_Test Report_v1.2 | D6: Issue Date | F6: 45695
A7: Notes
A11: No | B11: Function code | C11: Passed | D11: Failed | E11: Untested | F11: N | G11: A | H11: B | I11: Total Test Cases
A12: 1 | B12: Room - 1 | C12: ='Get All Room'!A7 -> 3 | D12: ='Get All Room'!C7 -> 0 | E12: ='Get All Room'!F7 -> 0 | F12: ='Get All Room'!L7 -> 2 | G12: ='Get All Room'!M7 -> 1 | H12: ='Get All Room'!N7 -> 0 | I12: ='Get All Room'!O7 -> 3
A13: 2 | B13: Room - 2 | C13: ='Get Room Detail'!A7 -> 4 | D13: ='Get Room Detail'!C7 -> 0 | E13: ='Get Room Detail'!F7 -> 0 | F13: ='Get Room Detail'!L7 -> 3 | G13: ='Get Room Detail'!M7 -> 1 | H13: ='Get Room Detail'!N7 -> 0 | I13: ='Get Room Detail'!O7 -> 4
A14: 3 | B14: Room - 3 | C14: ='Add Room'!A7 -> 6 | D14: ='Add Room'!C7 -> 0 | E14: ='Add Room'!F7 -> 0 | F14: ='Add Room'!L7 -> 1 | G14: ='Add Room'!M7 -> 5 | H14: ='Add Room'!N7 -> 0 | I14: ='Add Room'!O7 -> 6
A15: 4 | B15: Room - 4 | C15: ='Update Room'!A7 -> 5 | D15: ='Update Room'!C7 -> 0 | E15: ='Update Room'!F7 -> 0 | F15: ='Update Room'!L7 -> 1 | G15: ='Update Room'!M7 -> 4 | H15: ='Update Room'!N7 -> 0 | I15: ='Update Room'!O7 -> 5
A16: 5 | B16: Room - 5 | C16: ='Entry Excel To Room'!A7 -> 4 | D16: ='Entry Excel To Room'!B7 -> 0 | E16: ='Entry Excel To Room'!C7 -> 0 | F16: ='Entry Excel To Room'!L7 -> 1 | G16: ='Entry Excel To Room'!M7 -> 3 | H16: ='Entry Excel To Room'!N7 -> 0 | I16: ='Entry Excel To Room'!O7 -> 4
A17: 6 | B17: Role - 1 | C17: ='Get All Roles'!A7 -> 3 | D17: ='Get All Roles'!B7 -> 0 | E17: ='Get All Roles'!C7 -> 0 | F17: ='Get All Roles'!L7 -> 1 | G17: ='Get All Roles'!M7 -> 2 | H17: ='Get All Roles'!N7 -> 0 | I17: ='Get All Roles'!O7 -> 3
A18: 7 | B18: Role - 2 | C18: ='Get Role Detail'!A7 -> 4 | D18: ='Get Role Detail'!B7 -> 0 | E18: ='Get Role Detail'!C7 -> 0 | F18: ='Get Role Detail'!L7 -> 3 | G18: ='Get Role Detail'!M7 -> 1 | H18: ='Get Role Detail'!N7 -> 0 | I18: ='Get Role Detail'!O7 -> 4
A19: 8 | B19: Role - 3 | C19: ='Add New Role'!A7 -> 11 | D19: ='Add New Role'!B7 -> 0 | E19: ='Add New Role'!C7 -> 0 | F19: ='Add New Role'!L7 -> 1 | G19: ='Add New Role'!M7 -> 6 | H19: ='Add New Role'!N7 -> 4 | I19: ='Add New Role'!O7 -> 11
A20: 9 | B20: Role - 4 | C20: ='Update Role'!A7 -> 10 | D20: ='Update Role'!B7 -> 0 | E20: ='Update Role'!C7 -> 0 | F20: ='Update Role'!L7 -> 1 | G20: ='Update Role'!M7 -> 5 | H20: ='Update Role'!N7 -> 4 | I20: ='Update Role'!O7 -> 10
A21: 10
A22: 11
A23: 12
A24: 13
A25: 14
A26: 15
A27: 16
A28: 17
A29: 18
A30: 19
A31: 20
A32: 21
... A69: 58
B96: Sub total | C96: =SUM(C10:C95) -> 50 | D96: =SUM(D10:D95) -> 0 | E96: =SUM(E10:E95) -> 0 | F96: =SUM(F10:F95) -> 14 | G96: =SUM(G10:G95) -> 28 | H96: =SUM(H10:H95) -> 8 | I96: =SUM(I10:I95) -> 50
B98: Test coverage | D98: =(C96+D96)*100/(I96) -> 100 | E98: %
B99: Test successful coverage | D99: =C96*100/(I96) -> 100 | E99: %
B100: Normal case | D100: =F96*100/I96 -> 28 | E100: %
B101: Abnormal case | D101: =G96*100/I96 -> 56 | E101: %
B102: Boundary case | D102: =H96*100/I96 -> 16 | E102: %

Sheet Get All Room
A2: Function Code | C2: ='Function List'!E11 -> Room - 1 | F2: Function Name | L2: ='Function List'!D11 -> Get All Room
A3: Created By | C3: Nguyễn Hữu Duy | F3: Executed By | L3: Nguyễn Hữu Duy
A4: Lines of code | C4: 100 | F4: Lack of test cases | L4: 0
A5: Test requirement | C5: <Brief description about requirements which are tested in this function>
A6: Passed | C6: Failed | F6: Untested | L6: N/A/B | O6: Total Test Cases
A7: =COUNTIF(F23:HQ23,"P") -> 3 | C7: =COUNTIF(F23:HQ23,"F") -> 0 | F7: =SUM(O7,- A7,- C7) -> 0 | L7: =COUNTIF(E22:HQ22,"N") -> 2 | M7: =COUNTIF(E22:HQ22,"A") -> 1 | N7: =COUNTIF(E22:HQ22,"B") -> 0 | O7: =COUNTA(E9:HT9) -> 3
F9: UTCID01 | G9: UTCID02 | H9: UTCID03
A10: Condition | B10: Precondition
D11: Can connect with SQL Server | F11: O | G11: O
D12: Login with Authorize Account | F12: O | G12: O | H12: O
D13: No Entry In Database | G13: O
D14: Room Entry In Database | F14: O | H14: O
A15: Confirm | B15: Return
D16: Room List | F16: O
D17: Null | G17: O
B18: Exception
D19: InvalidOperationException | H19: O
B20: Exception
D21: "Database error" | H21: O
A22: Result | B22: Type(N : Normal, A : Abnormal, B : Boundary) | F22: N | G22: N | H22: A
B23: Passed/Failed | F23: P | G23: P | H23: P
B24: Executed Date | F24: 45700 | G24: 45700 | H24: 45700
B25: Defect ID

Sheet Get Room Detail
A2: Function Code | C2: ='Function List'!E12 -> Room - 2 | F2: Function Name | L2: ='Function List'!D12 -> Get Room Detail
A3: Created By | C3: Nguyễn Hữu Duy | F3: Executed By | L3: Nguyễn Hữu Duy
A4: Lines of code | C4: 150 | F4: Lack of test cases | L4: =U5 -> 0
A5: Test requirement | C5: Get Detail Successfully
A6: Passed | C6: Failed | F6: Untested | L6: N/A/B | O6: Total Test Cases
A7: =COUNTIF(F28:HQ28,"P") -> 4 | C7: =COUNTIF(F28:HQ28,"F") -> 0 | F7: =SUM(O7,- A7,- C7) -> 0 | L7: =COUNTIF(E27:HQ27,"N") -> 3 | M7: =COUNTIF(E27:HQ27,"A") -> 1 | N7: =COUNTIF(E27:HQ27,"B") -> 0 | O7: =COUNTA(E9:HT9) -> 4
F9: UTCID01 | G9: UTCID02 | H9: UTCID03 | I9: UTCID04
A10: Condition | B10: Precondition
D11: Can connect with SQL Server | F11: O | G11: O | H11: O | I11: O
D12: Login with Authorize Account | F12: O | G12: O | H12: O | I12: O
D13: Room Code Exist | F13: O | G13: O | H13: O
D14: Room Code Doesn't Exist | I14: O
B15: RoomCode
D16: "A101" | F16: O
D17: "" | G17: O
D18: "B202" | H18: O
D19: "Z999" | I19: O
A20: Confirm | B20: Return
D21: Room Detail | F21: O
D22: Null | G22: O | I22: O
B23: Exception
D24: InvalidOperationException | H24: O
B25: Log Message
D26: "Database error" | H26: O
A27: Result | B27: Type(N : Normal, A : Abnormal, B : Boundary) | F27: N | G27: N | H27: A | I27: N
B28: Passed/Failed | F28: P | G28: P | H28: P | I28: P
B29: Executed Date | F29: 45700 | G29: 45700 | H29: 45700 | I29: 45700
B30: Defect ID

Sheet Add Room
A2: Function Code | C2: ='Function List'!E13 -> Room - 3 | F2: Function Name | L2: ='Function List'!D13 -> Add Room
A3: Created By | C3: Nguyễn Hữu Duy | F3: Executed By | L3: Nguyễn Hữu Duy
A4: Lines of code | C4: 160 | F4: Lack of test cases | L4: 0
A5: Test requirement
A6: Passed | C6: Failed | F6: Untested | L6: N/A/B | O6: Total Test Cases
A7: =COUNTIF(F38:HQ38,"P") -> 6 | C7: =COUNTIF(F38:HQ38,"F") -> 0 | F7: =SUM(O7,- A7,- C7) -> 0 | L7: =COUNTIF(E37:HQ37,"N") -> 1 | M7: =COUNTIF(E37:HQ37,"A") -> 5 | N7: =COUNTIF(E37:HQ37,"B") -> 0 | O7: =COUNTA(E9:HT9) -> 6
F9: UTCID01 | G9: UTCID02 | H9: UTCID03 | I9: UTCID04 | J9: UTCID05 | K9: UTCID06
A10: Condition | B10: Precondition
D11: Can connect with SQL Server | F11: O | G11: O | H11: O | I11: O | J11: O
D12: Login with Authorize Account | F12: O | G12: O | H12: O | I12: O | J12: O | K12: O
B13: BuildingId
D14: 1 | F14: O | H14: O | J14: O | K14: O
D15: 0 | I15: O
D16: null | G16: O
B17: RoomCode
D18: "A101" | F18: O | J18: O | K18: O
D19: "B200" | I19: O
D20: "" | G20: O | H20: O
B21: Description
D22: "Valid room description" | F22: O
D23: "Invalid room code" | H23: O
D24: "Invalid building ID" | I24: O
D25: "Sample room" | K25: O
D26: null | G26: O | J26: O
A27: Confirm | B27: Return
D28: T | F28: O
D29: F | G29: O | H29: O | I29: O | J29: O
B30: Exception
D31: InvalidOperationException | K31: O
B32: Log message
D33: "Expected AddNewRoom to return false for an empty RoomCode." | H33: O
D34: Expected AddNewRoom to return false for a BuildingId of 0. | I34: O
D35: "Expected AddNewRoom to return false when Description is null." | J35: O
D36: "Database insert error" | K36: O
A37: Result | B37: Type(N : Normal, A : Abnormal, B : Boundary) | F37: N | G37: A | H37: A | I37: A | J37: A | K37: A
B38: Passed/Failed | F38: P | G38: P | H38: P | I38: P | J38: P | K38: P
B39: Executed Date | F39: 45700 | G39: 45700 | H39: 45700 | I39: 45700 | J39: 45700 | K39: 45700
B40: Defect ID

Sheet Update Room
A2: Function Code | C2: Room - 4 | F2: Function Name | L2: Update Room
A3: Created By | C3: Nguyễn Hữu Duy | F3: Executed By | L3: Nguyễn Hữu Duy
A4: Lines of code | C4: 200 | F4: Lack of test cases | L4: 0
A5: Test requirement
A6: Passed | C6: Failed | F6: Untested | L6: N/A/B | O6: Total Test Cases
A7: =COUNTIF(F36:HQ36,"P") -> 5 | C7: =COUNTIF(F37:HQ37,"F") -> 0 | F7: =SUM(O7,- A7,- C7) -> 0 | L7: =COUNTIF(E35:HQ35,"N") -> 1 | M7: =COUNTIF(E35:HQ35,"A") -> 4 | N7: =COUNTIF(E35:HQ35,"B") -> 0 | O7: =COUNTA(E9:HT9) -> 5
F9: UTCID01 | G9: UTCID02 | H9: UTCID03 | I9: UTCID04 | J9: UTCID05
A10: Condition | B10: Precondition
D11: Can connect with SQL Server | F11: O | G11: O | H11: O | I11: O | J11: O
D12: Login with Authorize Account | F12: O | G12: O | H12: O | I12: O | J12: O
B13: RoomId
D14: Guid.NewGuid | F14: O | H14: O | I14: O | J14: O
D15: null | G15: O
B16: Status
D17: 1 | F17: O | I17: O | J17: O
D18: -1 | H18: O
D19: null | G19: O
B20: Description
D21: "Description1" | F21: O | H21: O | J21: O
D22: null | G22: O | I22: O
A23: Confirm | B23: Return
D24: T | F24: O
D25: F | G25: O | H25: O | I25: O | J25: O
B26: Exception
D27: InvalidOperationException
B28: Log message
D29: "Expected true for a successful update." | F29: O
D30: "Expected false when provided room is null." | G30: O
D31: "Expected false for invalid status." | H31: O
D32: "Expected false for invalid description." | I32: O
D33: "Database error" | J33: O
A35: Result | B35: Type(N : Normal, A : Abnormal, B : Boundary) | F35: N | G35: A | H35: A | I35: A | J35: A
B36: Passed/Failed | F36: P | G36: P | H36: P | I36: P | J36: P
B37: Executed Date | F37: 45700 | G37: 45700 | H37: 45700 | I37: 45700 | J37: 45700
B38: Defect ID

Sheet Entry Excel To Room
A2: Function Code | C2: Room - 4 | F2: Function Name | L2: Entry Excel to Room
A3: Created By | C3: Nguyễn Hữu Duy | F3: Executed By | L3: Nguyễn Hữu Duy
A4: Lines of code | C4: 100 | F4: Lack of test cases | L4: 0
A5: Test requirement
A6: Passed | C6: Failed | F6: Untested | L6: N/A/B | O6: Total Test Cases
A7: =COUNTIF(F28:HQ28,"P") -> 4 | C7: =COUNTIF(F29:HQ29,"F") -> 0 | F7: =SUM(O7,- A7,- C7) -> 0 | L7: =COUNTIF(E27:HQ27,"N") -> 1 | M7: =COUNTIF(E27:HQ27,"A") -> 3 | N7: =COUNTIF(E27:HQ27,"B") -> 0 | O7: =COUNTA(E9:HT9) -> 4
F9: UTCID01 | G9: UTCID02 | H9: UTCID03 | I9: UTCID04
A10: Condition | B10: Precondition
D11: Can connect with SQL Server | F11: O | G11: O | H11: O | I11: O
D12: Login with Authorize Account | F12: O | G12: O | H12: O | I12: O
B13: filePath
D14: "C:\Temp\rooms.xlsx" | F14: O | I14: O
D15: "C:\Temp\rooms.txt" | H15: O
D16: null | G16: O
A17: Confirm | B17: Return
D18: T | F18: O
D19: F | G19: O | H19: O | I19: O
B20: Exception
D21: IOException | I21: O
B22: Log message
D23: "Expected true when a valid file path is provided." | F23: O
D24: "Expected false when a null file path is provided." | G24: O
D25: "Expected false when an unsupported file format is provided." | H25: O
D26: "Failed to read file" | I26: O
A27: Result | B27: Type(N : Normal, A : Abnormal, B : Boundary) | F27: N | G27: A | H27: A | I27: A
B28: Passed/Failed | F28: P | G28: P | H28: P | I28: P
B29: Executed Date | F29: 45700 | G29: 45700 | H29: 45700 | I29: 45700
B30: Defect ID

Sheet Get All Roles
A2: Function Code | C2: Role - 1 | F2: Function Name | L2: Get All Role
A3: Created By | C3: Nguyễn Chí Hậu | F3: Executed By | L3: Nguyễn Chí Hậu
A4: Lines of code | C4: 100 | F4: Lack of test cases | L4: 0
A5: Test requirement
A6: Passed | C6: Failed | F6: Untested | L6: N/A/B | O6: Total Test Cases
A7: =COUNTIF(F23:HQ23,"P") -> 3 | C7: =COUNTIF(F24:HQ24,"F") -> 0 | F7: =SUM(O7,- A7,- C7) -> 0 | L7: =COUNTIF(E22:HQ22,"N") -> 1 | M7: =COUNTIF(E22:HQ22,"A") -> 2 | N7: =COUNTIF(E22:HQ22,"B") -> 0 | O7: =COUNTA(E9:HT9) -> 3
F9: UTCID01 | G9: UTCID02 | H9: UTCID03
A10: Condition | B10: Precondition
D11: Can connect with SQL Server | F11: O | G11: O
D12: Login with Authorize Account | F12: O | G12: O | H12: O
D13: Have Entry in Database | F13: O
D14: No Entry in Database | G14: O
A15: Confirm | B15: Return
D16: Role List | F16: O
D17: Null | G17: O
B18: Exception
D19: InvalidOperationException | H19: O
B20: Log message
D21: "Database query error" | H21: O
A22: Result | B22: Type(N : Normal, A : Abnormal, B : Boundary) | F22: N | G22: A | H22: A
B23: Passed/Failed | F23: P | G23: P | H23: P
B24: Executed Date | F24: 45695 | G24: 45695 | H24: 45695
B25: Defect ID

Sheet Get Role Detail
A2: Function Code | C2: Role - 2 | F2: Function Name | L2: Get Role Detail
A3: Created By | C3: Nguyễn Chí Hậu | F3: Executed By | L3: Nguyễn Chí Hậu
A4: Lines of code | C4: 100 | F4: Lack of test cases | L4: 0
A5: Test requirement
A6: Passed | C6: Failed | F6: Untested | L6: N/A/B | O6: Total Test Cases
A7: =COUNTIF(F27:HQ27,"P") -> 4 | C7: =COUNTIF(F28:HQ28,"F") -> 0 | F7: =SUM(O7,- A7,- C7) -> 0 | L7: =COUNTIF(E26:HQ276,"N") -> 3 | M7: =COUNTIF(E26:HQ26,"A") -> 1 | N7: =COUNTIF(E26:HQ26,"B") -> 0 | O7: =COUNTA(E9:HT9) -> 4
F9: UTCID01 | G9: UTCID02 | H9: UTCID03 | I9: UTCID04
A10: Condition | B10: Precondition
D11: Can connect with SQL Server | F11: O | H11: O | I11: O
D12: Login with Authorize Account | F12: O | G12: O | H12: O | I12: O
D13: Have Entry in Database | F13: O | I13: O
D14: No Entry in Database | H14: O
B15: roleId
D16: 1 | F16: O | G16: O
D17: 9999 | H17: O
D18: 0 | I18: O
A19: Confirm | B19: Return
D20: Role Detail by the RoleId | F20: O
D21: Null | H21: O | I21: O
B22: Exception
D23: InvalidOperationException | G23: O
B24: Log message
D25: "Database error" | G25: O
A26: Result | B26: Type(N : Normal, A : Abnormal, B : Boundary) | F26: N | G26: A | H26: N | I26: N
B27: Passed/Failed | F27: P | G27: P | H27: P | I27: P
B28: Executed Date | F28: 45695 | G28: 45695 | H28: 45695 | I28: 45695
B29: Defect ID

Sheet Add New Role
A2: Function Code | C2: Role - 3 | F2: Function Name | L2: Add New Role
A3: Created By | C3: Nguyễn Chí Hậu | F3: Executed By | L3: Nguyễn Chí Hậu
A4: Lines of code | C4: 100 | F4: Lack of test cases | L4: 0
A5: Test requirement
A6: Passed | C6: Failed | F6: Untested | L6: N/A/B | O6: Total Test Cases
A7: =COUNTIF(F51:HQ51,"P") -> 11 | C7: =COUNTIF(F52:HQ52,"F") -> 0 | F7: =SUM(O7,- A7,- C7) -> 0 | L7: =COUNTIF(E50:HQ50,"N") -> 1 | M7: =COUNTIF(E50:HQ50,"A") -> 6 | N7: =COUNTIF(E50:HQ50,"B") -> 4 | O7: =COUNTA(E9:HT9) -> 11
F9: UTCID01 | G9: UTCID02 | H9: UTCID03 | I9: UTCID04 | J9: UTCID05 | K9: UTCID06 | L9: UTCID07 | M9: UTCID08 | N9: UTCID09 | O9: UTCID10 | P9: UTCID11
A10: Condition | B10: Precondition
D11: Can connect with SQL Server | F11: O | G11: O | H11: O | I11: O | J11: O | L11: O | M11: O | N11: O
D12: Login with Authorize Account | F12: O | G12: O | H12: O | I12: O | J12: O | K12: O | L12: O | M12: O | N12: O
B13: RoleName
D14: "Admin" | F14: O | I14: O | O14: O | P14: O
D15: null | G15: O | H15: O
D16: "Support" | J16: O
D17: "DatabaseFail" | K17: O
D18: "Viewer" | L18: O
D19: 25 characters string | M19: O
D20: 26 characters string | N20: O
B21: RoleDescription
D22: "Administrator Role" | F22: O | M22: O | N22: O
D23: null | G23: O | I23: O
D24: "Test description" | H24: O
D25: "Support role" | J25: O
D26: "Test for exception scenario" | K26: O
D27: "Role with no explicit permissions" | L27: O
D28: 50 characters string | O28: O
D29: 51 characters string | P29: O
B30: Permissions
D31: { 101, 102 } | F31: O | M31: O | N31: O | O31: O | P31: O
D32: null | G32: O
D33: { 101 } | H33: O | I33: O
D34: { 301, 302 } | J34: O
D35: { 999 } | K35: O
D36: {} | L36: O
A37: Confirm | B37: Return
D38: T | F38: O | M38: O | O38: O
D39: F | G39: O | H39: O | I39: O | J39: O | L39: O | N39: O | P39: O
B40: Exception
D41: InvalidOperationException | K41: O
B42: Log message
...

Sheet Update Role
A2: Function Code | C2: Role - 4 | F2: Function Name | L2: Update Role
A3: Created By | C3: Nguyễn Chí Hậu | F3: Executed By | L3: Nguyễn Chí Hậu
A4: Lines of code | C4: 100 | F4: Lack of test cases | L4: 0
A5: Test requirement
A6: Passed | C6: Failed | F6: Untested | L6: N/A/B | O6: Total Test Cases
A7: =COUNTIF(F52:HQ52,"P") -> 10 | C7: =COUNTIF(F53:HQ53,"F") -> 0 | F7: =SUM(O7,- A7,- C7) -> 0 | L7: =COUNTIF(E51:HQ51,"N") -> 1 | M7: =COUNTIF(E51:HQ51,"A") -> 5 | N7: =COUNTIF(E51:HQ51,"B") -> 4 | O7: =COUNTA(E9:HT9) -> 10
F9: UTCID01 | G9: UTCID02 | H9: UTCID03 | I9: UTCID04 | J9: UTCID05 | K9: UTCID06 | L9: UTCID07 | M9: UTCID08 | N9: UTCID09 | O9: UTCID10
A10: Condition | B10: Precondition
D11: Can connect with SQL Server | F11: O | G11: O | H11: O | I11: O | J11: O | L11: O | M11: O | N11: O | O11: O
D12: Login with Authorize Account | F12: O | G12: O | H12: O | I12: O | J12: O | K12: O | L12: O | M12: O | N12: O | O12: O
B13: RoleId
D14: 1 | F14: O | L14: O | M14: O | N14: O | O14: O
D15: 2 | H15: O | J15: O
D16: 99999 | I16: O
D17: 99 | K17: O
D18: null | G18: O
B19: RoleName
D20: "Moderator" | F20: O | J20: O | N20: O | O20: O
D21: null | G21: O | H21: O
D22: "NonExistentRole" | I22: O
D23: "NewName" | K23: O
D24: 25 characters string | L24: O
D25: 26 characters string | M25: O
B26: RoleDescription
D27: "Updated Description" | F27: O | L27: O | M27: O
D28: null | G28: O | J28: O
D29: "No name provided" | H29: O
D30: "Attempt to update a role that doesn't exist", | I30: O
D31: "Desc" | K31: O
D32: 50 characters string | N32: O
D33: 51 characters string | O33: O
B34: Permissions
D35: { 101, 102 } | F35: O | K35: O | L35: O | M35: O | N35: O | O35: O
D36: null | G36: O
D37: { 101 } | H37: O | I37: O | J37: O
D38: { 103 }
A39: Confirm | B39: Return
D40: T | F40: O | L40: O | N40: O
D41: F | G41: O | H41: O | I41: O | J41: O | M41: O | O41: O
B42: Exception
...
