Workbook
Name ACTION: #REF!

Sheet Guideline
A1: Guideline to make and understand Unit Test Case
A3: 1. Overview
A4: - In the template, Unit test cases are based on functions. Each sheet presents test cases for one function.
A5: - Cover: General information of the project and Unit Test cases
A6: - FunctionList: The list of Classes and Functions in the document. + To control that the number of Unit TC meets customer's requirement or the norm, user should fill value for 'Normal number of Test cases/KLOC'.
A7: + Click on Function link to open the related Test cases of the function. Note: You should create new Function sheet before creating the link
A8: - Test Report: provive the overview results of Functions Unit test: Test coverage, Test successful coverage (Summary, for normal/abnormal/boundary cases)
A9: Note: Should check the formula of "Sub Total" if you add more functions
A11: 2. Content in Test function sheet
A12: 2.1 Combination of test cases.
A13: - To verify that number of Unit TC meets customer's requirement or not. User has to fill number LOC of tested function and fill value of 'Normal number test cases/KLOC' item in FunctionList sheet, which is required by customer or normal value. The number of lacked TC is shown in 'Lack of test cases' item.
A14: - If the number of Unit TC does not meet the requirement, creator should explain the reasons.
... A47: - Test requirement: Brief description about requirements which are tested in this function, it is not mandatory.

Sheet Cover
B2: UNIT TEST CASE
A4: Project Name | B4: Edu Resource Management | E4: Creator | F4: Nguyễn Hữu Duy
A5: Project Code | B5: ERM | E5: Reviewer/Approver | F5: Nguyễn Chí Hậu
A6: Document Code | B6: =B5&"_"&"XXX"&"_"&"vx.x" | E6: Issue Date | F6: 45694
E7: Version | F7: 1.7
A10: Record of change
A11: Effective Date | B11: Version | C11: Change Item | D11: *A,D,M | E11: Change description | F11: Reference
A12: 45700 | B12: 1 | D12: A | E12: Add Test for Get All Room, Get Room Detail, Add Room, Update Room and Entry Excel To Room | F12: ERM_V.1
A13: 45700 | B13: 1.2 | D13: A | E13: Add Test for Get All Roles, Get Roles Detail, Add New Role, Update Role
A14: 45700 | B14: 1.3 | D14: A | E14: Add Test for Get Facilities, Get Facility By Id, Add New Facility, Update Facility, Get Available Facility, Get All Facilities
A15: 45702 | B15: 1.4 | D15: A | E15: Add Test for Get Room Facilities By Room Id, Get Room Facility Detail, Add New Room Facility, Update Room Facility and Delete Room Facility
A16: 45706 | B16: 1.5 | D16: A | E16: Add Test for Get User by Email, Get User by Usercode, Get All Users, Add New User, Edit Password, Get User Profile, Update User Profile, Change User Status, Entry Excel to User and Login
A17: 45708 | B17: 1.6 | D17: A | E17: Add Test Cases for Borrowing
A18: 45709 | B18: 1.7 | D18: A | E18: Add Test Cases for Permissions

Sheet Function List
E2: UNIT TEST CASE LIST
A4: Project Name | E4: Edu Resource Management
A5: Project Code | E5: ERM
A6: Normal number of Test cases/KLOC | E6: 300
A7: Test Environment Setup Description | E7: 1. SQL Server
A10: No | B10: Requirement Name | C10: Class Name | D10: Function Name | E10: Function Code(Optional) | F10: Sheet Name | G10: Description | H10: Pre-Condition
A11: 1 | C11: Room | D11: Get All Room | E11: Room - 1 | F11: Get All Room | G11: Get All Room with Detail | H11: Login as Authorize Account
A12: 2 | C12: Room | D12: Get Room Detail | E12: Room - 2 | F12: Get Room Detail | G12: Get Room Detail of One Room | H12: Login as Authorize Account
A13: 3 | C13: Room | D13: Add Room | E13: Room - 3 | F13: Add Room | G13: Add New Room | H13: Login as Authorize Account
A14: 4 | C14: Room | D14: Update Room | E14: Room - 4 | F14: Update Room | G14: Update Existing Room | H14: Login as Authorize Account
A15: 5 | C15: Room | D15: Entry Excel To Room | E15: Room - 5 | F15: Entry Excel To Room | G15: Entry Excel To Room | H15: Login as Authorize Account
A16: 6 | C16: Role | D16: Get All Role | E16: Role - 1 | F16: Get All Roles | G16: Get All Roles | H16: Login as Authorize Account
A17: 7 | C17: Role | D17: Get Role Detail | E17: Role - 2 | F17: Get Role Detail | G17: Get Role Detail | H17: Login as Authorize Account
A18: 8 | C18: Role | D18: Add New Role | E18: Role - 3 | F18: Add New Role | G18: Add New Role into Database | H18: Login as Authorize Account
A19: 9 | C19: Role | D19: Update Role | E19: Role - 4 | F19: Update Role | G19: Update Existing Role | H19: Login as Authorize Account
A20: 10 | C20: Facility | D20: Get Facilities | E20: Facility - 1 | F20: Get Facilities | G20: Get Facility List by Role id | H20: Login as Authorize Account
A21: 11 | C21: Facility | D21: Get Facility By Id | E21: Facility - 2 | F21: Get Facility By Id | G21: Get One Facility by Id | H21: Login as Authorize Account
A22: 12 | C22: Facility | D22: Add New Facility | E22: Facility - 3 | F22: Add New Facility | G22: Add New Facility | H22: Login as Authorize Account
... A49: 40 | C49: Permissions | D49: Get User Permission | E49: Permissions - 3 | F49: Get User Permission | G49: Get User's Permission | H49: Login as Authorize Account
A50: 41
A51: 42
A52: 43
A53: 44
A54: 45
A55: 46
A56: 47
A57: 48
A58: 49
A59: 50
A60: 51
A61: 52
... A73: 64
A74: 65 | B74: UC-20 View Contract | C74: ContractsController | D74: List Contracts | E74: EP-043 | F74: List Contracts | G74: GET /contracts/list | H74: Authenticated user
A75: 66 | B75: UC-38 Payment | C75: PaymentsController | D75: Fund Milestone | E75: EP-185 | F75: Fund Milestone | G75: POST /payments/milestones/:milestoneId/fund | H75: Authenticated client user and milestone payload
A76: 67 | B76: UC-25 View List Specs; UC-26 View Final Specs | C76: ProjectSpecsController | D76: Audit Spec | E76: EP-228 | F76: Audit Spec | G76: POST /project-specs/:id/audit | H76: Authenticated admin/staff user with a target spec

Sheet Test Report
A2: UNIT TEST REPORT
A4: Project Name | B4: =Cover!B4 | D4: Creator | F4: Nguyễn Hữu Duy
A5: Project Code | B5: =Cover!B5 | D5: Reviewer/Approver | F5: Nguyễn Hữu Duy
A6: Document Code | B6: =B5&"_"&"Test Report"&"_"&"v1.7" | D6: Issue Date | F6: 45695
A7: Notes
A11: No | B11: Function code | C11: Passed | D11: Failed | E11: Untested | F11: N | G11: A | H11: B | I11: Total Test Cases
A12: 1 | B12: Room - 1 | C12: ='Get All Room'!A7 | D12: ='Get All Room'!C7 | E12: ='Get All Room'!F7 | F12: ='Get All Room'!L7 | G12: ='Get All Room'!M7 | H12: ='Get All Room'!N7 | I12: ='Get All Room'!O7
A13: 2 | B13: Room - 2 | C13: ='Get Room Detail'!A7 | D13: ='Get Room Detail'!C7 | E13: ='Get Room Detail'!F7 | F13: ='Get Room Detail'!L7 | G13: ='Get Room Detail'!M7 | H13: ='Get Room Detail'!N7 | I13: ='Get Room Detail'!O7
A14: 3 | B14: Room - 3 | C14: ='Add Room'!A7 | D14: ='Add Room'!C7 | E14: ='Add Room'!F7 | F14: ='Add Room'!L7 | G14: ='Add Room'!M7 | H14: ='Add Room'!N7 | I14: ='Add Room'!O7
A15: 4 | B15: Room - 4 | C15: ='Update Room'!A7 | D15: ='Update Room'!C7 | E15: ='Update Room'!F7 | F15: ='Update Room'!L7 | G15: ='Update Room'!M7 | H15: ='Update Room'!N7 | I15: ='Update Room'!O7
A16: 5 | B16: Room - 5 | C16: ='Entry Excel To Room'!A7 | D16: ='Entry Excel To Room'!B7 | E16: ='Entry Excel To Room'!C7 | F16: ='Entry Excel To Room'!L7 | G16: ='Entry Excel To Room'!M7 | H16: ='Entry Excel To Room'!N7 | I16: ='Entry Excel To Room'!O7
A17: 6 | B17: Role - 1 | C17: ='Get All Roles'!A7 | D17: ='Get All Roles'!B7 | E17: ='Get All Roles'!C7 | F17: ='Get All Roles'!L7 | G17: ='Get All Roles'!M7 | H17: ='Get All Roles'!N7 | I17: ='Get All Roles'!O7
A18: 7 | B18: Role - 2 | C18: ='Get Role Detail'!A7 | D18: ='Get Role Detail'!B7 | E18: ='Get Role Detail'!C7 | F18: ='Get Role Detail'!L7 | G18: ='Get Role Detail'!M7 | H18: ='Get Role Detail'!N7 | I18: ='Get Role Detail'!O7
A19: 8 | B19: Role - 3 | C19: ='Add New Role'!A7 | D19: ='Add New Role'!B7 | E19: ='Add New Role'!C7 | F19: ='Add New Role'!L7 | G19: ='Add New Role'!M7 | H19: ='Add New Role'!N7 | I19: ='Add New Role'!O7
A20: 9 | B20: Role - 4 | C20: ='Update Role'!A7 | D20: ='Update Role'!B7 | E20: ='Update Role'!C7 | F20: ='Update Role'!L7 | G20: ='Update Role'!M7 | H20: ='Update Role'!N7 | I20: ='Update Role'!O7
A21: 10 | B21: Facility - 1 | C21: ='Get Facilities'!A7 | D21: ='Get Facilities'!B7 | E21: ='Get Facilities'!C7 | F21: ='Get Facilities'!L7 | G21: ='Get Facilities'!M7 | H21: ='Get Facilities'!N7 | I21: ='Get Facilities'!O7
A22: 11 | B22: Facility - 2 | C22: ='Get Facility By Id'!A7 | D22: ='Get Facility By Id'!B7 | E22: ='Get Facility By Id'!C7 | F22: ='Get Facility By Id'!L7 | G22: ='Get Facility By Id'!M7 | H22: ='Get Facility By Id'!N7 | I22: ='Get Facility By Id'!O7
A23: 12 | B23: Facility - 3 | C23: ='Add New Facility'!A7 | D23: ='Add New Facility'!B7 | E23: ='Add New Facility'!C7 | F23: ='Add New Facility'!L7 | G23: ='Add New Facility'!M7 | H23: ='Add New Facility'!N7 | I23: ='Add New Facility'!O7
A24: 13 | B24: Facility - 4 | C24: ='Update Facility'!A7 | D24: ='Update Facility'!B7 | E24: ='Update Facility'!C7 | F24: ='Update Facility'!L7 | G24: ='Update Facility'!M7 | H24: ='Update Facility'!N7 | I24: ='Update Facility'!O7
A25: 14 | B25: Facility - 5 | C25: ='Get Available Facilities'!A7 | D25: ='Get Available Facilities'!B7 | E25: ='Get Available Facilities'!C7 | F25: ='Get Available Facilities'!L7 | G25: ='Get Available Facilities'!M7 | H25: ='Get Available Facilities'!N7 | I25: ='Get Available Facilities'!O7
A26: 15 | B26: Facility - 6 | C26: ='Get All Facilities'!A7 | D26: ='Get All Facilities'!B7 | E26: ='Get All Facilities'!C7 | F26: ='Get All Facilities'!L7 | G26: ='Get All Facilities'!M7 | H26: ='Get All Facilities'!N7 | I26: ='Get All Facilities'!O7
A27: 16 | B27: RoomFacility - 1 | C27: ='Get Room Facilities By Room Id'!A7 | D27: ='Get Room Facilities By Room Id'!B7 | E27: ='Get Room Facilities By Room Id'!C7 | F27: ='Get Room Facilities By Room Id'!L7 | G27: ='Get Room Facilities By Room Id'!M7 | H27: ='Get Room Facilities By Room Id'!N7 | I27: ='Get Room Facilities By Room Id'!O7
A28: 17 | B28: RoomFacility - 2 | C28: ='Get Room Facility Detail'!A7 | D28: ='Get Room Facility Detail'!B7 | E28: ='Get Room Facility Detail'!C7 | F28: ='Get Room Facility Detail'!L7 | G28: ='Get Room Facility Detail'!M7 | H28: ='Get Room Facility Detail'!N7 | I28: ='Get Room Facility Detail'!O7
A29: 18 | B29: RoomFacility - 3 | C29: ='Add New Room Facility'!A7 | D29: ='Add New Room Facility'!B7 | E29: ='Add New Room Facility'!C7 | F29: ='Add New Room Facility'!L7 | G29: ='Add New Room Facility'!M7 | H29: ='Add New Room Facility'!N7 | I29: ='Add New Room Facility'!O7
A30: 19 | B30: RoomFacility - 4 | C30: ='Update Room Facility'!A7 | D30: ='Update Room Facility'!B7 | E30: ='Update Room Facility'!C7 | F30: ='Update Room Facility'!L7 | G30: ='Update Room Facility'!M7 | H30: ='Update Room Facility'!N7 | I30: ='Update Room Facility'!O7
A31: 20 | B31: RoomFacility - 5 | C31: ='Delete Room Facility'!A7 | D31: ='Delete Room Facility'!B7 | E31: ='Delete Room Facility'!C7 | F31: ='Delete Room Facility'!L7 | G31: ='Delete Room Facility'!M7 | H31: ='Delete Room Facility'!N7 | I31: ='Delete Room Facility'!O7
A32: 21 | B32: User - 1 | C32: ='Get User By Email'!A7 | D32: ='Get User By Email'!B7 | E32: ='Get User By Email'!C7 | F32: ='Get User By Email'!L7 | G32: ='Get User By Email'!M7 | H32: ='Get User By Email'!N7 | I32: ='Get User By Email'!O7
A33: 22 | B33: User - 2 | C33: ='Get All Users'!A7 | D33: ='Get All Users'!B7 | E33: ='Get All Users'!C7 | F33: ='Get All Users'!L7 | G33: ='Get All Users'!M7 | H33: ='Get All Users'!N7 | I33: ='Get All Users'!O7
A34: 23 | B34: User - 3 | C34: ='Add New User'!A7 | D34: ='Add New User'!B7 | E34: ='Add New User'!C7 | F34: ='Add New User'!L7 | G34: ='Add New User'!M7 | H34: ='Add New User'!N7 | I34: ='Add New User'!O7
A35: 24 | B35: User - 4 | C35: ='Edit Password'!A7 | D35: ='Edit Password'!B7 | E35: ='Edit Password'!C7 | F35: ='Edit Password'!L7 | G35: ='Edit Password'!M7 | H35: ='Edit Password'!N7 | I35: ='Edit Password'!O7
A36: 25 | B36: User - 5 | C36: ='Get User Profile'!A7 | D36: ='Get User Profile'!B7 | E36: ='Get User Profile'!C7 | F36: ='Get User Profile'!L7 | G36: ='Get User Profile'!M7 | H36: ='Get User Profile'!N7 | I36: ='Get User Profile'!O7
A37: 26 | B37: User - 6 | C37: ='Change User Status'!A7 | D37: ='Change User Status'!B7 | E37: ='Change User Status'!C7 | F37: ='Change User Status'!L7 | G37: ='Change User Status'!M7 | H37: ='Change User Status'!N7 | I37: ='Change User Status'!O7
A38: 27 | B38: User - 7 | C38: ='Update User Profile'!A7 | D38: ='Update User Profile'!B7 | E38: ='Update User Profile'!C7 | F38: ='Update User Profile'!L7 | G38: ='Update User Profile'!M7 | H38: ='Update User Profile'!N7 | I38: ='Update User Profile'!O7
A39: 28 | B39: User - 8 | C39: ='Entry Excel To User'!A7 | D39: ='Entry Excel To User'!B7 | E39: ='Entry Excel To User'!C7 | F39: ='Entry Excel To User'!L7 | G39: ='Entry Excel To User'!M7 | H39: ='Entry Excel To User'!N7 | I39: ='Entry Excel To User'!O7
A40: 29 | B40: User - 9 | C40: ='Get User By Usercode'!A7 | D40: ='Get User By Usercode'!B7 | E40: ='Get User By Usercode'!C7 | F40: ='Get User By Usercode'!L7 | G40: ='Get User By Usercode'!M7 | H40: ='Get User By Usercode'!N7 | I40: ='Get User By Usercode'!O7
A41: 30 | B41: User - 10 | C41: =Login!A7 | D41: =Login!B7 | E41: =Login!C7 | F41: =Login!L7 | G41: =Login!M7 | H41: =Login!N7 | I41: =Login!O7
A42: 31 | B42: Borrowing - 1 | C42: ='Create Borrow Request'!A6 | D42: ='Create Borrow Request'!B6 | E42: ='Create Borrow Request'!C6 | F42: ='Create Borrow Request'!L6 | G42: ='Create Borrow Request'!M6 | H42: ='Create Borrow Request'!N6 | I42: ='Create Borrow Request'!O6
A43: 32 | B43: Borrowing - 2 | C43: ='Get Personal Borrowing'!A7 | D43: ='Get Personal Borrowing'!B7 | E43: ='Get Personal Borrowing'!C7 | F43: ='Get Personal Borrowing'!L7 | G43: ='Get Personal Borrowing'!M7 | H43: ='Get Personal Borrowing'!N7 | I43: ='Get Personal Borrowing'!O7
A44: 33 | B44: Borrowing - 3 | C44: ='Get Borrow List For Department'!A7 | D44: ='Get Borrow List For Department'!B7 | E44: ='Get Borrow List For Department'!C7 | F44: ='Get Borrow List For Department'!L7 | G44: ='Get Borrow List For Department'!M7 | H44: ='Get Borrow List For Department'!N7 | I44: ='Get Borrow List For Department'!O7
A45: 34 | B45: Borrowing - 4 | C45: ='Get Important Borrowing'!A7 | D45: ='Get Important Borrowing'!B7 | E45: ='Get Important Borrowing'!C7 | F45: ='Get Important Borrowing'!L7 | G45: ='Get Important Borrowing'!M7 | H45: ='Get Important Borrowing'!N7 | I45: ='Get Important Borrowing'!O7
...

Sheet Get All Room
A2: Function Code | C2: ='Function List'!E11 | F2: Function Name | L2: ='Function List'!D11
A3: Created By | C3: Nguyễn Hữu Duy | F3: Executed By | L3: Nguyễn Hữu Duy
A4: Lines of code | C4: 100 | F4: Lack of test cases | L4: 0
A5: Test requirement | C5: <Brief description about requirements which are tested in this function>
A6: Passed | C6: Failed | F6: Untested | L6: N/A/B | O6: Total Test Cases
A7: =COUNTIF(F23:HQ23,"P") | C7: =COUNTIF(F23:HQ23,"F") | F7: =SUM(O7,- A7,- C7) | L7: =COUNTIF(E22:HQ22,"N") | M7: =COUNTIF(E22:HQ22,"A") | N7: =COUNTIF(E22:HQ22,"B") | O7: =COUNTA(E9:HT9)
F9: UTCID01 | G9: UTCID02 | H9: UTCID03
A10: Condition | B10: Precondition
D11: Can connect with SQL Server | F11: O | G11: O
D12: Login with Authorize Account | F12: O | G12: O | H12: O
D13: No Entry In Database | G13: O
D14: Room Entry In Database | F14: O | H14: O
A15: Confirm | B15: Return
D16: Room List | F16: O
D17: Null | G17: O
B18: Exception
D19: InvalidOperationException | H19: O
B20: Exception
D21: "Database error" | H21: O
A22: Result | B22: Type(N : Normal, A : Abnormal, B : Boundary) | F22: N | G22: N | H22: A
B23: Passed/Failed | F23: P | G23: P | H23: P
B24: Executed Date | F24: 45700 | G24: 45700 | H24: 45700
B25: Defect ID

Sheet Get All Users
A2: Function Code | C2: User - 2 | F2: Function Name | L2: Get All Users
A3: Created By | C3: Nguyễn Hữu Duy | F3: Executed By | L3: Nguyễn Hữu Duy
A4: Lines of code | C4: 93 | F4: Lack of test cases | L4: 0
A5: Test requirement | C5: <Brief description about requirements which are tested in this function>
A6: Passed | C6: Failed | F6: Untested | L6: N/A/B | O6: Total Test Cases
A7: =COUNTIF(F23:HQ23,"P") | C7: =COUNTIF(F23:HQ23,"F") | F7: =SUM(O7,- A7,- C7) | L7: =COUNTIF(E22:HQ22,"N") | M7: =COUNTIF(E22:HQ22,"A") | N7: =COUNTIF(E22:HQ22,"B") | O7: =COUNTA(E9:HT9)
F9: UTCID01 | G9: UTCID02 | H9: UTCID03
A10: Condition | B10: Precondition
D11: Can connect with SQL Server | F11: O | G11: O
D12: Login with Authorize Account | F12: O | G12: O | H12: O
D13: No Entry In Database | G13: O
D14: Users Entry In Database | F14: O | H14: O
A15: Confirm | B15: Return
D16: User List | F16: O
D17: Null | G17: O
B18: Exception
D19: InvalidOperationException | H19: O
B20: Exception
D21: "Database error" | H21: O
A22: Result | B22: Type(N : Normal, A : Abnormal, B : Boundary) | F22: N | G22: N | H22: A
B23: Passed/Failed | F23: P | G23: P | H23: P
B24: Executed Date | F24: 45706 | G24: 45706 | H24: 45706
B25: Defect ID

Sheet Get Room Detail
A2: Function Code | C2: ='Function List'!E12 | F2: Function Name | L2: ='Function List'!D12
A3: Created By | C3: Nguyễn Hữu Duy | F3: Executed By | L3: Nguyễn Hữu Duy
A4: Lines of code | C4: 150 | F4: Lack of test cases | L4: =U5
A5: Test requirement | C5: Get Detail Successfully
A6: Passed | C6: Failed | F6: Untested | L6: N/A/B | O6: Total Test Cases
A7: =COUNTIF(F28:HQ28,"P") | C7: =COUNTIF(F28:HQ28,"F") | F7: =SUM(O7,- A7,- C7) | L7: =COUNTIF(E27:HQ27,"N") | M7: =COUNTIF(E27:HQ27,"A") | N7: =COUNTIF(E27:HQ27,"B") | O7: =COUNTA(E9:HT9)
F9: UTCID01 | G9: UTCID02 | H9: UTCID03 | I9: UTCID04
A10: Condition | B10: Precondition
D11: Can connect with SQL Server | F11: O | G11: O | H11: O | I11: O
D12: Login with Authorize Account | F12: O | G12: O | H12: O | I12: O
D13: Room Code Exist | F13: O | G13: O | H13: O
D14: Room Code Doesn't Exist | I14: O
B15: RoomCode
D16: "A101" | F16: O
D17: "" | G17: O
D18: "B202" | H18: O
D19: "Z999" | I19: O
A20: Confirm | B20: Return
D21: Room Detail | F21: O
D22: Null | G22: O | I22: O
B23: Exception
D24: InvalidOperationException | H24: O
B25: Log Message
D26: "Database error" | H26: O
A27: Result | B27: Type(N : Normal, A : Abnormal, B : Boundary) | F27: N | G27: N | H27: A | I27: N
B28: Passed/Failed | F28: P | G28: P | H28: P | I28: P
B29: Executed Date | F29: 45700 | G29: 45700 | H29: 45700 | I29: 45700
B30: Defect ID

Sheet Add Room
A2: Function Code | C2: ='Function List'!E13 | F2: Function Name | L2: ='Function List'!D13
A3: Created By | C3: Nguyễn Hữu Duy | F3: Executed By | L3: Nguyễn Hữu Duy
A4: Lines of code | C4: 160 | F4: Lack of test cases | L4: 0
A5: Test requirement
A6: Passed | C6: Failed | F6: Untested | L6: N/A/B | O6: Total Test Cases
A7: =COUNTIF(F38:HQ38,"P") | C7: =COUNTIF(F38:HQ38,"F") | F7: =SUM(O7,- A7,- C7) | L7: =COUNTIF(E37:HQ37,"N") | M7: =COUNTIF(E37:HQ37,"A") | N7: =COUNTIF(E37:HQ37,"B") | O7: =COUNTA(E9:HT9)
F9: UTCID01 | G9: UTCID02 | H9: UTCID03 | I9: UTCID04 | J9: UTCID05 | K9: UTCID06
A10: Condition | B10: Precondition
D11: Can connect with SQL Server | F11: O | G11: O | H11: O | I11: O | J11: O
D12: Login with Authorize Account | F12: O | G12: O | H12: O | I12: O | J12: O | K12: O
B13: BuildingId
D14: 1 | F14: O | H14: O | J14: O | K14: O
D15: 0 | I15: O
D16: null | G16: O
B17: RoomCode
D18: "A101" | F18: O | J18: O | K18: O
D19: "B200" | I19: O
D20: "" | G20: O | H20: O
B21: Description
D22: "Valid room description" | F22: O
D23: "Invalid room code" | H23: O
D24: "Invalid building ID" | I24: O
D25: "Sample room" | K25: O
D26: null | G26: O | J26: O
A27: Confirm | B27: Return
D28: T | F28: O
D29: F | G29: O | H29: O | I29: O | J29: O
B30: Exception
D31: InvalidOperationException | K31: O
B32: Log message
D33: "Expected AddNewRoom to return false for an empty RoomCode." | H33: O
D34: Expected AddNewRoom to return false for a BuildingId of 0. | I34: O
D35: "Expected AddNewRoom to return false when Description is null." | J35: O
D36: "Database insert error" | K36: O
A37: Result | B37: Type(N : Normal, A : Abnormal, B : Boundary) | F37: N | G37: A | H37: A | I37: A | J37: A | K37: A
B38: Passed/Failed | F38: P | G38: P | H38: P | I38: P | J38: P | K38: P
B39: Executed Date | F39: 45700 | G39: 45700 | H39: 45700 | I39: 45700 | J39: 45700 | K39: 45700
B40: Defect ID

Sheet Update Room
A2: Function Code | C2: Room - 4 | F2: Function Name | L2: Update Room
A3: Created By | C3: Nguyễn Hữu Duy | F3: Executed By | L3: Nguyễn Hữu Duy
A4: Lines of code | C4: 200 | F4: Lack of test cases | L4: 0
A5: Test requirement
A6: Passed | C6: Failed | F6: Untested | L6: N/A/B | O6: Total Test Cases
A7: =COUNTIF(F36:HQ36,"P") | C7: =COUNTIF(F37:HQ37,"F") | F7: =SUM(O7,- A7,- C7) | L7: =COUNTIF(E35:HQ35,"N") | M7: =COUNTIF(E35:HQ35,"A") | N7: =COUNTIF(E35:HQ35,"B") | O7: =COUNTA(E9:HT9)
F9: UTCID01 | G9: UTCID02 | H9: UTCID03 | I9: UTCID04 | J9: UTCID05
A10: Condition | B10: Precondition
D11: Can connect with SQL Server | F11: O | G11: O | H11: O | I11: O | J11: O
D12: Login with Authorize Account | F12: O | G12: O | H12: O | I12: O | J12: O
B13: RoomId
D14: Guid.NewGuid | F14: O | H14: O | I14: O | J14: O
D15: null | G15: O
B16: Status
D17: 1 | F17: O | I17: O | J17: O
D18: -1 | H18: O
D19: null | G19: O
B20: Description
D21: "Description1" | F21: O | H21: O | J21: O
D22: null | G22: O | I22: O
A23: Confirm | B23: Return
D24: T | F24: O
D25: F | G25: O | H25: O | I25: O | J25: O
B26: Exception
D27: InvalidOperationException
B28: Log message
D29: "Expected true for a successful update." | F29: O
D30: "Expected false when provided room is null." | G30: O
D31: "Expected false for invalid status." | H31: O
D32: "Expected false for invalid description." | I32: O
D33: "Database error" | J33: O
A35: Result | B35: Type(N : Normal, A : Abnormal, B : Boundary) | F35: N | G35: A | H35: A | I35: A | J35: A
B36: Passed/Failed | F36: P | G36: P | H36: P | I36: P | J36: P
B37: Executed Date | F37: 45700 | G37: 45700 | H37: 45700 | I37: 45700 | J37: 45700
B38: Defect ID

Sheet Entry Excel To Room
A2: Function Code | C2: Room - 4 | F2: Function Name | L2: Entry Excel to Room
A3: Created By | C3: Nguyễn Hữu Duy | F3: Executed By | L3: Nguyễn Hữu Duy
A4: Lines of code | C4: 100 | F4: Lack of test cases | L4: 0
A5: Test requirement
A6: Passed | C6: Failed | F6: Untested | L6: N/A/B | O6: Total Test Cases
A7: =COUNTIF(F28:HQ28,"P") | C7: =COUNTIF(F29:HQ29,"F") | F7: =SUM(O7,- A7,- C7) | L7: =COUNTIF(E27:HQ27,"N") | M7: =COUNTIF(E27:HQ27,"A") | N7: =COUNTIF(E27:HQ27,"B") | O7: =COUNTA(E9:HT9)
F9: UTCID01 | G9: UTCID02 | H9: UTCID03 | I9: UTCID04
A10: Condition | B10: Precondition
D11: Can connect with SQL Server | F11: O | G11: O | H11: O | I11: O
D12: Login with Authorize Account | F12: O | G12: O | H12: O | I12: O
B13: filePath
D14: "C:\Temp\rooms.xlsx" | F14: O | I14: O
D15: "C:\Temp\rooms.txt" | H15: O
D16: null | G16: O
A17: Confirm | B17: Return
D18: T | F18: O
D19: F | G19: O | H19: O | I19: O
B20: Exception
D21: IOException | I21: O
B22: Log message
D23: "Expected true when a valid file path is provided." | F23: O
D24: "Expected false when a null file path is provided." | G24: O
D25: "Expected false when an unsupported file format is provided." | H25: O
D26: "Failed to read file" | I26: O
A27: Result | B27: Type(N : Normal, A : Abnormal, B : Boundary) | F27: N | G27: A | H27: A | I27: A
B28: Passed/Failed | F28: P | G28: P | H28: P | I28: P
B29: Executed Date | F29: 45700 | G29: 45700 | H29: 45700 | I29: 45700
B30: Defect ID

Sheet Get All Roles
A2: Function Code | C2: Role - 1 | F2: Function Name | L2: Get All Role
A3: Created By | C3: Nguyễn Chí Hậu | F3: Executed By | L3: Nguyễn Chí Hậu
A4: Lines of code | C4: 100 | F4: Lack of test cases | L4: 0
A5: Test requirement
A6: Passed | C6: Failed | F6: Untested | L6: N/A/B | O6: Total Test Cases
A7: =COUNTIF(F23:HQ23,"P") | C7: =COUNTIF(F24:HQ24,"F") | F7: =SUM(O7,- A7,- C7) | L7: =COUNTIF(E22:HQ22,"N") | M7: =COUNTIF(E22:HQ22,"A") | N7: =COUNTIF(E22:HQ22,"B") | O7: =COUNTA(E9:HT9)
F9: UTCID01 | G9: UTCID02 | H9: UTCID03
A10: Condition | B10: Precondition
D11: Can connect with SQL Server | F11: O | G11: O
D12: Login with Authorize Account | F12: O | G12: O | H12: O
D13: Have Entry in Database | F13: O
D14: No Entry in Database | G14: O
A15: Confirm | B15: Return
D16: Role List | F16: O
D17: Null | G17: O
B18: Exception
D19: InvalidOperationException | H19: O
B20: Log message
D21: "Database query error" | H21: O
A22: Result | B22: Type(N : Normal, A : Abnormal, B : Boundary) | F22: N | G22: A | H22: A
B23: Passed/Failed | F23: P | G23: P | H23: P
B24: Executed Date | F24: 45695 | G24: 45695 | H24: 45695
B25: Defect ID

Sheet Get Role Detail
A2: Function Code | C2: Role - 2 | F2: Function Name | L2: Get Role Detail
A3: Created By | C3: Nguyễn Chí Hậu | F3: Executed By | L3: Nguyễn Chí Hậu
A4: Lines of code | C4: 100 | F4: Lack of test cases | L4: 0
A5: Test requirement
A6: Passed | C6: Failed | F6: Untested | L6: N/A/B | O6: Total Test Cases
A7: =COUNTIF(F27:HQ27,"P") | C7: =COUNTIF(F28:HQ28,"F") | F7: =SUM(O7,- A7,- C7) | L7: =COUNTIF(E26:HQ276,"N") | M7: =COUNTIF(E26:HQ26,"A") | N7: =COUNTIF(E26:HQ26,"B") | O7: =COUNTA(E9:HT9)
F9: UTCID01 | G9: UTCID02 | H9: UTCID03 | I9: UTCID04
A10: Condition | B10: Precondition
D11: Can connect with SQL Server | F11: O | H11: O | I11: O
D12: Login with Authorize Account | F12: O | G12: O | H12: O | I12: O
D13: Have Entry in Database | F13: O | I13: O
D14: No Entry in Database | H14: O
B15: roleId
D16: 1 | F16: O | G16: O
D17: 9999 | H17: O
D18: 0 | I18: O
A19: Confirm | B19: Return
D20: Role Detail by the RoleId | F20: O
D21: Null | H21: O | I21: O
B22: Exception
D23: InvalidOperationException | G23: O
B24: Log message
D25: "Database error" | G25: O
A26: Result | B26: Type(N : Normal, A : Abnormal, B : Boundary) | F26: N | G26: A | H26: N | I26: N
B27: Passed/Failed | F27: P | G27: P | H27: P | I27: P
B28: Executed Date | F28: 45695 | G28: 45695 | H28: 45695 | I28: 45695
B29: Defect ID

Sheet Add New Role
A2: Function Code | C2: Role - 3 | F2: Function Name | L2: Add New Role
A3: Created By | C3: Nguyễn Chí Hậu | F3: Executed By | L3: Nguyễn Chí Hậu
A4: Lines of code | C4: 100 | F4: Lack of test cases | L4: 0
A5: Test requirement
A6: Passed | C6: Failed | F6: Untested | L6: N/A/B | O6: Total Test Cases
A7: =COUNTIF(F51:HQ51,"P") | C7: =COUNTIF(F52:HQ52,"F") | F7: =SUM(O7,- A7,- C7) | L7: =COUNTIF(E50:HQ50,"N") | M7: =COUNTIF(E50:HQ50,"A") | N7: =COUNTIF(E50:HQ50,"B") | O7: =COUNTA(E9:HT9)
F9: UTCID01 | G9: UTCID02 | H9: UTCID03 | I9: UTCID04 | J9: UTCID05 | K9: UTCID06 | L9: UTCID07 | M9: UTCID08 | N9: UTCID09 | O9: UTCID10 | P9: UTCID11
A10: Condition | B10: Precondition
D11: Can connect with SQL Server | F11: O | G11: O | H11: O | I11: O | J11: O | L11: O | M11: O | N11: O
D12: Login with Authorize Account | F12: O | G12: O | H12: O | I12: O | J12: O | K12: O | L12: O | M12: O | N12: O
B13: RoleName
D14: "Admin" | F14: O | I14: O | O14: O | P14: O
D15: null | G15: O | H15: O
D16: "Support" | J16: O
D17: "DatabaseFail" | K17: O
D18: "Viewer" | L18: O
D19: 25 characters string | M19: O
D20: 26 characters string | N20: O
B21: RoleDescription
D22: "Administrator Role" | F22: O | M22: O | N22: O
D23: null | G23: O | I23: O
D24: "Test description" | H24: O
D25: "Support role" | J25: O
D26: "Test for exception scenario" | K26: O
D27: "Role with no explicit permissions" | L27: O
D28: 50 characters string | O28: O
D29: 51 characters string | P29: O
B30: Permissions
D31: { 101, 102 } | F31: O | M31: O | N31: O | O31: O | P31: O
D32: null | G32: O
D33: { 101 } | H33: O | I33: O
D34: { 301, 302 } | J34: O
D35: { 999 } | K35: O
D36: {} | L36: O
A37: Confirm | B37: Return
D38: T | F38: O | M38: O | O38: O
D39: F | G39: O | H39: O | I39: O | J39: O | L39: O | N39: O | P39: O
B40: Exception
D41: InvalidOperationException | K41: O
B42: Log message
...

Sheet Update Role
A2: Function Code | C2: Role - 4 | F2: Function Name | L2: Update Role
A3: Created By | C3: Nguyễn Chí Hậu | F3: Executed By | L3: Nguyễn Chí Hậu
A4: Lines of code | C4: 100 | F4: Lack of test cases | L4: 0
A5: Test requirement
A6: Passed | C6: Failed | F6: Untested | L6: N/A/B | O6: Total Test Cases
A7: =COUNTIF(F52:HQ52,"P") | C7: =COUNTIF(F53:HQ53,"F") | F7: =SUM(O7,- A7,- C7) | L7: =COUNTIF(E51:HQ51,"N") | M7: =COUNTIF(E51:HQ51,"A") | N7: =COUNTIF(E51:HQ51,"B") | O7: =COUNTA(E9:HT9)
F9: UTCID01 | G9: UTCID02 | H9: UTCID03 | I9: UTCID04 | J9: UTCID05 | K9: UTCID06 | L9: UTCID07 | M9: UTCID08 | N9: UTCID09 | O9: UTCID10
A10: Condition | B10: Precondition
D11: Can connect with SQL Server | F11: O | G11: O | H11: O | I11: O | J11: O | L11: O | M11: O | N11: O | O11: O
D12: Login with Authorize Account | F12: O | G12: O | H12: O | I12: O | J12: O | K12: O | L12: O | M12: O | N12: O | O12: O
B13: RoleId
D14: 1 | F14: O | L14: O | M14: O | N14: O | O14: O
D15: 2 | H15: O | J15: O
D16: 99999 | I16: O
D17: 99 | K17: O
D18: null | G18: O
B19: RoleName
D20: "Moderator" | F20: O | J20: O | N20: O | O20: O
D21: null | G21: O | H21: O
D22: "NonExistentRole" | I22: O
D23: "NewName" | K23: O
D24: 25 characters string | L24: O
D25: 26 characters string | M25: O
B26: RoleDescription
D27: "Updated Description" | F27: O | L27: O | M27: O
D28: null | G28: O | J28: O
D29: "No name provided" | H29: O
D30: "Attempt to update a role that doesn't exist", | I30: O
D31: "Desc" | K31: O
D32: 50 characters string | N32: O
D33: 51 characters string | O33: O
B34: Permissions
D35: { 101, 102 } | F35: O | K35: O | L35: O | M35: O | N35: O | O35: O
D36: null | G36: O
D37: { 101 } | H37: O | I37: O | J37: O
D38: { 103 }
A39: Confirm | B39: Return
D40: T | F40: O | L40: O | N40: O
D41: F | G41: O | H41: O | I41: O | J41: O | M41: O | O41: O
B42: Exception
...

Sheet Get Facilities
A2: Function Code | C2: Facility - 1 | F2: Function Name | L2: Get Facilities
A3: Created By | C3: Nguyễn Thanh Tuấn | F3: Executed By | L3: Nguyễn Thanh Tuấn
A4: Lines of code | C4: 102 | F4: Lack of test cases | L4: 0
A5: Test requirement
A6: Passed | C6: Failed | F6: Untested | L6: N/A/B | O6: Total Test Cases
A7: =COUNTIF(F26:HQ26,"P") | C7: =COUNTIF(F27:HQ27,"F") | F7: =SUM(O7,- A7,- C7) | L7: =COUNTIF(E25:HQ25,"N") | M7: =COUNTIF(E25:HQ25,"A") | N7: =COUNTIF(E25:HQ25,"B") | O7: =COUNTA(E9:HT9)
F9: UTCID01 | G9: UTCID02 | H9: UTCID03 | I9: UTCID04
A10: Condition | B10: Precondition
D11: Can connect with SQL Server | F11: O | G11: O | H11: O
D12: Login with Authorize Account | F12: O | G12: O | H12: O | I12: O
D13: Have Entry in Database | F13: O
D14: No Entry in Database | G14: O | H14: O | I14: O
B15: roleId
D16: 1 | F16: O | G16: O | I16: O
D17: 9999 | H17: O
A18: Confirm | B18: Return
D19: Facility List | F19: O
D20: Null | G20: O | H20: O
B21: Exception
D22: InvalidOperationException | I22: O
B23: Log message
D24: "Database query error" | I24: O
A25: Result | B25: Type(N : Normal, A : Abnormal, B : Boundary) | F25: N | G25: N | H25: N | I25: A
B26: Passed/Failed | F26: P | G26: P | H26: P | I26: P
B27: Executed Date | F27: 45700 | G27: 45700 | H27: 45700 | I27: 45700
B28: Defect ID

Sheet Get Room Facilities By Room Id
A2: Function Code | C2: RoomFacility - 1 | F2: Function Name | L2: Get Room Facilities By Room Id
A3: Created By | C3: Nguyễn Thanh Tuấn | F3: Executed By | L3: Nguyễn Thanh Tuấn
A4: Lines of code | C4: 102 | F4: Lack of test cases | L4: 0
A5: Test requirement
A6: Passed | C6: Failed | F6: Untested | L6: N/A/B | O6: Total Test Cases
A7: =COUNTIF(F26:HQ26,"P") | C7: =COUNTIF(F27:HQ27,"F") | F7: =SUM(O7,- A7,- C7) | L7: =COUNTIF(E25:HQ25,"N") | M7: =COUNTIF(E25:HQ25,"A") | N7: =COUNTIF(E25:HQ25,"B") | O7: =COUNTA(E9:HT9)
F9: UTCID01 | G9: UTCID02 | H9: UTCID03 | I9: UTCID04
A10: Condition | B10: Precondition
D11: Can connect with SQL Server | F11: O | G11: O | H11: O
D12: Login with Authorize Account | F12: O | G12: O | H12: O | I12: O
D13: Have Entry in Database | F13: O
D14: No Entry in Database | G14: O | H14: O | I14: O
B15: RoomId
D16: Guid | F16: O | G16: O | I16: O
D17: null | H17: O
A18: Confirm | B18: Return
D19: Room Facilities List | F19: O
D20: Null | G20: O | H20: O
B21: Exception
D22: InvalidOperationException | I22: O
B23: Log message
D24: "Simulated DB error" | I24: O
A25: Result | B25: Type(N : Normal, A : Abnormal, B : Boundary) | F25: N | G25: N | H25: N | I25: A
B26: Passed/Failed | F26: P | G26: P | H26: P | I26: P
B27: Executed Date | F27: 45702 | G27: 45702 | H27: 45702 | I27: 45702
B28: Defect ID

Sheet Get Personal Borrowing
A2: Function Code | C2: Borrowing - 2 | F2: Function Name | L2: Get Personal Borrowing
A3: Created By | C3: Nguyễn Hữu Duy | F3: Executed By | L3: Nguyễn Hữu Duy
A4: Lines of code | C4: 111 | F4: Lack of test cases | L4: 0
A5: Test requirement
A6: Passed | C6: Failed | F6: Untested | L6: N/A/B | O6: Total Test Cases
A7: =COUNTIF(F29:HQ29,"P") | C7: =COUNTIF(F30:HQ30,"F") | F7: =SUM(O7,- A7,- C7) | L7: =COUNTIF(E28:HQ28,"N") | M7: =COUNTIF(E28:HQ28,"A") | N7: =COUNTIF(E28:HQ28,"B") | O7: =COUNTA(E9:HT9)
F9: UTCID01 | G9: UTCID02 | H9: UTCID03 | I9: UTCID04 | J9: UTCID05
A10: Condition | B10: Precondition
D11: Can connect with SQL Server | F11: O | G11: O | H11: O | I11: O
D12: Login with Authorize Account | F12: O | G12: O | H12: O | I12: O | J12: O
D13: Have Entry in Database | F13: O | J13: O
D14: No Entry in Database | G14: O | H14: O | I14: O
D15: BorrowerId Exist | F15: O | G15: O | J15: O
D16: BorrowerId doesn't Exist | H16: O | I16: O
B17: BorrowerId
D18: Guid | F18: O | G18: O | J18: O
D19: "invalid-guid" | H19: O
D20: null | I20: O
A21: Confirm | B21: Return
D22: Personal Borrowing List | F22: O
D23: Null | G23: O | H23: O | I23: O
B24: Exception
D25: InvalidOperationException | J25: O
B26: Log message
D27: "Database connection failed" | J27: O
A28: Result | B28: Type(N : Normal, A : Abnormal, B : Boundary) | F28: N | G28: N | H28: N | I28: N | J28: A
B29: Passed/Failed | F29: P | G29: P | H29: P | I29: P | J29: P
B30: Executed Date | F30: 45708 | G30: 45708 | H30: 45708 | I30: 45708 | J30: 45708
B31: Defect ID

Sheet Get Borrow List For Department
A2: Function Code | C2: Borrowing - 3 | F2: Function Name | L2: Get Borrow List For Department
A3: Created By | C3: Nguyễn Hữu Duy | F3: Executed By | L3: Nguyễn Hữu Duy
A4: Lines of code | C4: 125 | F4: Lack of test cases | L4: 0
A5: Test requirement
A6: Passed | C6: Failed | F6: Untested | L6: N/A/B | O6: Total Test Cases
A7: =COUNTIF(F33:HQ33,"P") | C7: =COUNTIF(F34:HQ34,"F") | F7: =SUM(O7,- A7,- C7) | L7: =COUNTIF(E32:HQ32,"N") | M7: =COUNTIF(E32:HQ32,"A") | N7: =COUNTIF(E32:HQ32,"B") | O7: =COUNTA(E9:HT9)
F9: UTCID01 | G9: UTCID02 | H9: UTCID03 | I9: UTCID04 | J9: UTCID05
A10: Condition | B10: Precondition
D11: Can connect with SQL Server | F11: O | G11: O | H11: O | J11: O
D12: Login with Authorize Account | F12: O | G12: O | H12: O | I12: O | J12: O
D13: Have Entry in Database | F13: O | J13: O
D14: No Entry in Database | G14: O | H14: O | I14: O
D15: Department Exist | F15: O | G15: O | J15: O
D16: Department doesn't Exist | H16: O | I16: O
B17: Department
D18: 1 | F18: O | G18: O | I18: O | J18: O
D19: 9999 | H19: O
D20: null
B21: Type
D22: TRUE | F22: O | G22: O | H22: O
D23: FALSE | J23: O
A24: Confirm | B24: Return
D25: Borrow List for Department with type = True | F25: O
D26: Borrow List for Department with type = False | J26: O
D27: Null | G27: O | H27: O
B28: Exception
D29: InvalidOperationException | I29: O
B30: Log message
D31: "Database connection failed" | I31: O
A32: Result | B32: Type(N : Normal, A : Abnormal, B : Boundary) | F32: N | G32: N | H32: N | I32: A | J32: N
B33: Passed/Failed | F33: P | G33: P | H33: P | I33: P | J33: P
B34: Executed Date | F34: 45708 | G34: 45708 | H34: 45708 | I34: 45708 | J34: 45708
B35: Defect ID

Sheet Get Important Borrowing
A2: Function Code | C2: Borrowing - 4 | F2: Function Name | L2: Get Important Borrowing
A3: Created By | C3: Nguyễn Hữu Duy | F3: Executed By | L3: Nguyễn Hữu Duy
A4: Lines of code | C4: 73 | F4: Lack of test cases | L4: 0
A5: Test requirement
A6: Passed | C6: Failed | F6: Untested | L6: N/A/B | O6: Total Test Cases
A7: =COUNTIF(F23:HQ23,"P") | C7: =COUNTIF(F24:HQ24,"F") | F7: =SUM(O7,- A7,- C7) | L7: =COUNTIF(E22:HQ22,"N") | M7: =COUNTIF(E22:HQ22,"A") | N7: =COUNTIF(E22:HQ22,"B") | O7: =COUNTA(E9:HT9)
F9: UTCID01 | G9: UTCID02 | H9: UTCID03
A10: Condition | B10: Precondition
D11: Can connect with SQL Server | F11: O | G11: O
D12: Login with Authorize Account | F12: O | G12: O | H12: O
D13: Have Entry in Database | F13: O
D14: No Entry in Database | G14: O | H14: O
A15: Confirm | B15: Return
D16: Borrow List f | F16: O
D17: Null | G17: O
B18: Exception
D19: InvalidOperationException | H19: O
B20: Log message
D21: "Database connection failed" | H21: O
A22: Result | B22: Type(N : Normal, A : Abnormal, B : Boundary) | F22: N | G22: N | H22: A
B23: Passed/Failed | F23: P | G23: P | H23: P
B24: Executed Date | F24: 45708 | G24: 45708 | H24: 45708
B25: Defect ID

Sheet Get Borrowing Detail
A2: Function Code | C2: Borrowing - 5 | F2: Function Name | K2: Get Borrowing Detail
A3: Created By | C3: Nguyễn Hữu Duy | F3: Executed By | K3: Nguyễn Hữu Duy
A4: Lines of code | C4: 124 | F4: Lack of test cases | K4: 0
A5: Test requirement
A6: Passed | C6: Failed | F6: Untested | K6: N/A/B | N6: Total Test Cases
A7: =COUNTIF(F28:HP28,"P") | C7: =COUNTIF(F29:HP29,"F") | F7: =SUM(N7,- A7,- C7) | K7: =COUNTIF(E27:HP27,"N") | L7: =COUNTIF(E27:HP27,"A") | M7: =COUNTIF(E27:HP27,"B") | N7: =COUNTA(E9:HS9)
F9: UTCID01 | G9: UTCID02 | H9: UTCID03 | I9: UTCID04
A10: Condition | B10: Precondition
D11: Can connect with SQL Server | F11: O | G11: O | H11: O
D12: Login with Authorize Account | F12: O | G12: O | H12: O | I12: O
D13: Have Entry in Database | F13: O
D14: No Entry in Database | G14: O | H14: O | I14: O
D15: BorrowId Exist | F15: O | G15: O
D16: BorrowId doesn't Exist | H16: O | I16: O
B17: BorrowId
D18: Guid | F18: O | G18: O | H18: O | I18: O
D19: null
A20: Confirm | B20: Return
D21: Borrowing Detail | F21: O
D22: Null | G22: O | H22: O
B23: Exception
D24: InvalidOperationException | I24: O
B25: Log message
D26: "Database connection failed" | I26: O
A27: Result | B27: Type(N : Normal, A : Abnormal, B : Boundary) | F27: N | G27: N | H27: N | I27: A
B28: Passed/Failed | F28: P | G28: P | H28: P | I28: P
B29: Executed Date | F29: 45708 | G29: 45708 | H29: 45708 | I29: 45708
B30: Defect ID

Sheet Get HashSet Permissions
A2: Function Code | C2: Permissions - 1 | F2: Function Name | K2: Get HashSet Permissions
A3: Created By | C3: Nguyễn Chí Hậu | F3: Executed By | K3: Nguyễn Chí Hậu
A4: Lines of code | C4: 70 | F4: Lack of test cases | K4: 0
A5: Test requirement
A6: Passed | C6: Failed | F6: Untested | K6: N/A/B | N6: Total Test Cases
A7: =COUNTIF(F26:HP26,"P") | C7: =COUNTIF(F27:HP27,"F") | F7: =SUM(N7,- A7,- C7) | K7: =COUNTIF(E25:HP25,"N") | L7: =COUNTIF(E25:HP25,"A") | M7: =COUNTIF(E25:HP25,"B") | N7: =COUNTA(E9:HS9)
F9: UTCID01 | G9: UTCID02 | H9: UTCID03
A10: Condition | B10: Precondition
D11: Can connect with SQL Server | F11: O | G11: O
D12: Login with Authorize Account | F12: O | G12: O | H12: O
D13: UserId Exist | F13: O
D14: UserId doesn't Exist | G14: O | H14: O
B15: UserId
D16: Guid | F16: O | G16: O | H16: O
D17: null
A18: Confirm | B18: Return
D19: Permissions List | F19: O
D20: Null | G20: O
B21: Exception
D22: InvalidOperationException | H22: O
B23: Log message
D24: "Database connection failed" | H24: O
A25: Result | B25: Type(N : Normal, A : Abnormal, B : Boundary) | F25: N | G25: N | H25: A
B26: Passed/Failed | F26: P | G26: P | H26: P
B27: Executed Date | F27: 45709 | G27: 45709 | H27: 45709
B28: Defect ID

Sheet Get Permissions
A2: Function Code | C2: Permissions - 2 | F2: Function Name | K2: Get Permissions
A3: Created By | C3: Nguyễn Chí Hậu | F3: Executed By | K3: Nguyễn Chí Hậu
A4: Lines of code | C4: 95 | F4: Lack of test cases | K4: 0
A5: Test requirement
A6: Passed | C6: Failed | F6: Untested | K6: N/A/B | N6: Total Test Cases
A7: =COUNTIF(F27:HP27,"P") | C7: =COUNTIF(F28:HP28,"F") | F7: =SUM(N7,- A7,- C7) | K7: =COUNTIF(E26:HP26,"N") | L7: =COUNTIF(E26:HP26,"A") | M7: =COUNTIF(E26:HP26,"B") | N7: =COUNTA(E9:HS9)
F9: UTCID01 | G9: UTCID02 | H9: UTCID03 | I9: UTCID04
A10: Condition | B10: Precondition
D11: Can connect with SQL Server | F11: O | G11: O | H11: O
D12: Login with Authorize Account | F12: O | G12: O | H12: O | I12: O
D13: UserId Exist | F13: O | H13: O
D14: UserId doesn't Exist | G14: O | I14: O
D15: Have Permissions | F15: O
D16: Don't have Permissions | G16: O | H16: O | I16: O
B17: UserId
D18: Guid | F18: O | G18: O | H18: O
A19: Confirm | B19: Return
D20: Permissions List | F20: O
D21: Null | G21: O | H21: O
B22: Exception
D23: InvalidOperationException | I23: O
B24: Log message
D25: "Database connection failed" | I25: O
A26: Result | B26: Type(N : Normal, A : Abnormal, B : Boundary) | F26: N | G26: N | H26: N | I26: A
B27: Passed/Failed | F27: P | G27: P | H27: P | I27: P
B28: Executed Date | F28: 45709 | G28: 45709 | H28: 45709 | I28: 45709
B29: Defect ID

Sheet Get User with Permissions
A2: Function Code | C2: Permissions - 1 | F2: Function Name | K2: Get User with Permissions
A3: Created By | C3: Nguyễn Chí Hậu | F3: Executed By | K3: Nguyễn Chí Hậu
A4: Lines of code | C4: 45 | F4: Lack of test cases | K4: 0
A5: Test requirement
A6: Passed | C6: Failed | F6: Untested | K6: N/A/B | N6: Total Test Cases
A7: =COUNTIF(F29:HP29,"P") | C7: =COUNTIF(F30:HP30,"F") | F7: =SUM(N7,- A7,- C7) | K7: =COUNTIF(E28:HP28,"N") | L7: =COUNTIF(E28:HP28,"A") | M7: =COUNTIF(E28:HP28,"B") | N7: =COUNTA(E9:HS9)
F9: UTCID01 | G9: UTCID02 | H9: UTCID03
A10: Condition | B10: Precondition
D11: Can connect with SQL Server | F11: O | G11: O
D12: Login with Authorize Account | F12: O | G12: O | H12: O
D13: Users Exist | F13: O
D14: Users doesn't Exist | G14: O | H14: O
B15: requiredPermissions
D16: { "Read", "Write" } | F16: O | H16: O
D17: { "NonExistentPermission" } | G17: O
B18: requireAllPermissions
D19: TRUE | F19: O | H19: O
D20: FALSE | G20: O
A21: Confirm | B21: Return
D22: Users List | F22: O
D23: Null | G23: O
B24: Exception
D25: InvalidOperationException | H25: O
B26: Log message
D27: "Database connection failed" | H27: O
A28: Result | B28: Type(N : Normal, A : Abnormal, B : Boundary) | F28: N | G28: N | H28: A
B29: Passed/Failed | F29: P | G29: P | H29: P
B30: Executed Date | F30: 45709 | G30: 45709 | H30: 45709
B31: Defect ID

Sheet Get Facility By Id
A2: Function Code | C2: Facility - 2 | F2: Function Name | L2: Get Facility By ID
A3: Created By | C3: Nguyễn Thanh Tuấn | F3: Executed By | L3: Nguyễn Thanh Tuấn
A4: Lines of code | C4: 60 | F4: Lack of test cases | L4: 0
A5: Test requirement
A6: Passed | C6: Failed | F6: Untested | L6: N/A/B | O6: Total Test Cases
A7: =COUNTIF(F25:HQ25,"P") | C7: =COUNTIF(F26:HQ26,"F") | F7: =SUM(O7,- A7,- C7) | L7: =COUNTIF(E24:HQ24,"N") | M7: =COUNTIF(E24:HQ24,"A") | N7: =COUNTIF(E24:HQ24,"B") | O7: =COUNTA(E9:HT9)
F9: UTCID01 | G9: UTCID02 | H9: UTCID03
A10: Condition | B10: Precondition
D11: Can connect with SQL Server | F11: O | G11: O
D12: Login with Authorize Account | F12: O | G12: O | H12: O
D13: Have Entry in Database | F13: O | H13: O
D14: No Entry in Database | G14: O
B15: FacilityId
D16: Guid | F16: O | G16: O | H16: O
A17: Confirm | B17: Return
D18: Facility | F18: O
D19: Null | G19: O
B20: Exception
D21: InvalidOperationException | H21: O
B22: Log message
D23: "Simulated DB error" | H23: O
A24: Result | B24: Type(N : Normal, A : Abnormal, B : Boundary) | F24: N | G24: N | H24: A
B25: Passed/Failed | F25: P | G25: P | H25: P
B26: Executed Date | F26: 45700 | G26: 45700 | H26: 45700
B27: Defect ID

Sheet Get Room Facility Detail
A2: Function Code | C2: RoomFacility - 2 | F2: Function Name | L2: Get Facility By ID
A3: Created By | C3: Nguyễn Thanh Tuấn | F3: Executed By | L3: Nguyễn Thanh Tuấn
A4: Lines of code | C4: 71 | F4: Lack of test cases | L4: 0
A5: Test requirement
A6: Passed | C6: Failed | F6: Untested | L6: N/A/B | O6: Total Test Cases
A7: =COUNTIF(F25:HQ25,"P") | C7: =COUNTIF(F26:HQ26,"F") | F7: =SUM(O7,- A7,- C7) | L7: =COUNTIF(E24:HQ24,"N") | M7: =COUNTIF(E24:HQ24,"A") | N7: =COUNTIF(E24:HQ24,"B") | O7: =COUNTA(E9:HT9)
F9: UTCID01 | G9: UTCID02 | H9: UTCID03
A10: Condition | B10: Precondition
D11: Can connect with SQL Server | F11: O | G11: O
D12: Login with Authorize Account | F12: O | G12: O | H12: O
D13: Have Entry in Database | F13: O | H13: O
D14: No Entry in Database | G14: O
B15: roomFacilityId
D16: Guid | F16: O | G16: O | H16: O
A17: Confirm | B17: Return
D18: Room Facility | F18: O
D19: Null | G19: O
B20: Exception
D21: InvalidOperationException | H21: O
B22: Log message
D23: "Simulated DB error" | H23: O
A24: Result | B24: Type(N : Normal, A : Abnormal, B : Boundary) | F24: N | G24: N | H24: A
B25: Passed/Failed | F25: P | G25: P | H25: P
B26: Executed Date | F26: 45700 | G26: 45700 | H26: 45700
B27: Defect ID

Sheet Get User By Email
A2: Function Code | C2: User - 1 | F2: Function Name | L2: Get User By Email
A3: Created By | C3: Nguyễn Hữu Duy | F3: Executed By | L3: Nguyễn Hữu Duy
A4: Lines of code | C4: 79 | F4: Lack of test cases | L4: 0
A5: Test requirement
A6: Passed | C6: Failed | F6: Untested | L6: N/A/B | O6: Total Test Cases
A7: =COUNTIF(F26:HQ26,"P") | C7: =COUNTIF(F27:HQ27,"F") | F7: =SUM(O7,- A7,- C7) | L7: =COUNTIF(E25:HQ25,"N") | M7: =COUNTIF(E25:HQ25,"A") | N7: =COUNTIF(E25:HQ25,"B") | O7: =COUNTA(E9:HT9)
F9: UTCID01 | G9: UTCID02 | H9: UTCID03
A10: Condition | B10: Precondition
D11: Can connect with SQL Server | F11: O | G11: O
D12: Login with Authorize Account | F12: O | G12: O | H12: O
D13: Have Entry in Database | F13: O | H13: O
D14: No Entry in Database | G14: O
B15: Email
D16: test@example.com
D17: nonexistent@example.com | F17: O | G17: O | H17: O
A18: Confirm | B18: Return
D19: User Detail | F19: O
D20: Null | G20: O
B21: Exception
D22: InvalidOperationException | H22: O
B23: Log message
D24: "Simulated DB error" | H24: O
A25: Result | B25: Type(N : Normal, A : Abnormal, B : Boundary) | F25: N | G25: N | H25: A
B26: Passed/Failed | F26: P | G26: P | H26: P
B27: Executed Date | F27: 45706 | G27: 45706 | H27: 45706
B28: Defect ID

Sheet Get User By Usercode
A2: Function Code | C2: User - 7 | F2: Function Name | L2: Get User By Usercode
A3: Created By | C3: Nguyễn Hữu Duy | F3: Executed By | L3: Nguyễn Hữu Duy
A4: Lines of code | C4: 77 | F4: Lack of test cases | L4: 0
A5: Test requirement
A6: Passed | C6: Failed | F6: Untested | L6: N/A/B | O6: Total Test Cases
A7: =COUNTIF(F26:HQ26,"P") | C7: =COUNTIF(F27:HQ27,"F") | F7: =SUM(O7,- A7,- C7) | L7: =COUNTIF(E25:HQ25,"N") | M7: =COUNTIF(E25:HQ25,"A") | N7: =COUNTIF(E25:HQ25,"B") | O7: =COUNTA(E9:HT9)
F9: UTCID01 | G9: UTCID02 | H9: UTCID03
A10: Condition | B10: Precondition
D11: Can connect with SQL Server | F11: O | G11: O
D12: Login with Authorize Account | F12: O | G12: O | H12: O
D13: Have Entry in Database | F13: O | H13: O
D14: No Entry in Database | G14: O
B15: Usercode
D16: "USER001" | F16: O | H16: O
D17: "INVALID_USER" | G17: O
A18: Confirm | B18: Return
D19: User Detail | F19: O
D20: Null | G20: O
B21: Exception
D22: InvalidOperationException | H22: O
B23: Log message
D24: "Simulated DB error" | H24: O
A25: Result | B25: Type(N : Normal, A : Abnormal, B : Boundary) | F25: N | G25: N | H25: A
B26: Passed/Failed | F26: P | G26: P | H26: P
B27: Executed Date | F27: 45706 | G27: 45706 | H27: 45706
B28: Defect ID

Sheet Edit Password
A2: Function Code | C2: User - 4 | F2: Function Name | L2: Edit Password
A3: Created By | C3: Nguyễn Hữu Duy | F3: Executed By | L3: Nguyễn Hữu Duy
A4: Lines of code | C4: 235 | F4: Lack of test cases | L4: 0
A5: Test requirement
A6: Passed | C6: Failed | F6: Untested | L6: N/A/B | O6: Total Test Cases
A7: =COUNTIF(F46:HQ46,"P") | C7: =COUNTIF(F47:HQ47,"F") | F7: =SUM(O7,- A7,- C7) | L7: =COUNTIF(E45:HQ45,"N") | M7: =COUNTIF(E45:HQ45,"A") | N7: =COUNTIF(E45:HQ45,"B") | O7: =COUNTA(E9:HT9)
F9: UTCID01 | G9: UTCID02 | H9: UTCID03 | I9: UTCID04 | J9: UTCID05 | K9: UTCID06 | L9: UTCID07 | M9: UTCID08 | N9: UTCID09 | O9: UTCID10
A10: Condition | B10: Precondition
D11: Can connect with SQL Server | F11: O | G11: O | H11: O | I11: O | J11: O | K11: O | L11: O | M11: O | N11: O
D12: Login with Authorize Account | F12: O | G12: O | H12: O | I12: O | J12: O | K12: O | L12: O | M12: O | N12: O | O12: O
D13: Have Email in Database | F13: O | I13: O | J13: O | L13: O | M13: O | N13: O
D14: No Email in Database | G14: O | H14: O | K14: O | O14: O
B15: Email
D16: test@example.com | F16: O | H16: O | I16: O | J16: O | L16: O | M16: O | N16: O | O16: O
D17: null | G17: O | K17: O
B18: Password
D19: "newPassword" | F19: O | H19: O | I19: O | J19: O | K19: O | M19: O | N19: O | O19: O
D20: null | G20: O | L20: O
B21: OldPassword
D22: "oldPassword" | F22: O | H22: O | J22: O | K22: O | L22: O | N22: O | O22: O
D23: "wrongOldPassword" | I23: O
D24: null | G24: O | M24: O
B25: RePassword
D26: "newPassword" | F26: O | H26: O | I26: O | K26: O | L26: O | M26: O | O26: O
D27: "differentPassword" | J27: O
D28: null | G28: O | N28: O
A29: Confirm | B29: Return
D30: T | F30: O
D31: F | G31: O | H31: O | I31: O | J31: O | K31: O | L31: O | M31: O | N31: O
B32: Exception
D33: InvalidOperationException | O33: O
B34: Log message
D35: "Expected EditPassword to return true for a valid password change." | F35: O
D36: "Expected EditPassword to return false for a null user DTO." | G36: O
D37: "Expected EditPassword to return false for a non existence email." | H37: O
D38: "Expected EditPassword to return false for an incorrect old password." | I38: O
D39: "Expected EditPassword to return false when new password and re-password do not match." | J39: O
D40: "Expected EditPassword to return false for an empty email." | K40: O
D41: "Expected EditPassword to return false for an empty old password." | L41: O
D42: "Expected EditPassword to return false for an empty new password." | M42: O
...

Sheet Get User Profile
A2: Function Code | C2: User - 5 | F2: Function Name | L2: Get User Profile
A3: Created By | C3: Nguyễn Hữu Duy | F3: Executed By | L3: Nguyễn Hữu Duy
A4: Lines of code | C4: 72 | F4: Lack of test cases | L4: 0
A5: Test requirement
A6: Passed | C6: Failed | F6: Untested | L6: N/A/B | O6: Total Test Cases
A7: =COUNTIF(F25:HQ25,"P") | C7: =COUNTIF(F26:HQ26,"F") | F7: =SUM(O7,- A7,- C7) | L7: =COUNTIF(E24:HQ24,"N") | M7: =COUNTIF(E24:HQ24,"A") | N7: =COUNTIF(E24:HQ24,"B") | O7: =COUNTA(E9:HT9)
F9: UTCID01 | G9: UTCID02 | H9: UTCID03
A10: Condition | B10: Precondition
D11: Can connect with SQL Server | F11: O | G11: O
D12: Login with Authorize Account | F12: O | G12: O | H12: O
D13: Have Entry in Database | F13: O | H13: O
D14: No Entry in Database | G14: O
B15: Usercode
D16: Guid | F16: O | G16: O
A17: Confirm | B17: Return
D18: User Detail | F18: O
D19: Null | G19: O
B20: Exception
D21: InvalidOperationException | H21: O
B22: Log message
D23: "Simulated DB error" | H23: O
A24: Result | B24: Type(N : Normal, A : Abnormal, B : Boundary) | F24: N | G24: N | H24: A
B25: Passed/Failed | F25: P | G25: P | H25: P
B26: Executed Date | F26: 45706 | G26: 45706 | H26: 45706
B27: Defect ID

Sheet Change User Status
A2: Function Code | C2: User - 6 | F2: Function Name | L2: Change User Status
A3: Created By | C3: Nguyễn Hữu Duy | F3: Executed By | L3: Nguyễn Hữu Duy
A4: Lines of code | C4: 137 | F4: Lack of test cases | L4: 0
A5: Test requirement
A6: Passed | C6: Failed | F6: Untested | L6: N/A/B | O6: Total Test Cases
A7: =COUNTIF(F37:HQ37,"P") | C7: =COUNTIF(F38:HQ38,"F") | F7: =SUM(O7,- A7,- C7) | L7: =COUNTIF(E36:HQ36,"N") | M7: =COUNTIF(E36:HQ36,"A") | N7: =COUNTIF(E36:HQ36,"B") | O7: =COUNTA(E9:HT9)
F9: UTCID01 | G9: UTCID02 | H9: UTCID03 | I9: UTCID04 | J9: UTCID05 | K9: UTCID06
A10: Condition | B10: Precondition
D11: Can connect with SQL Server | F11: O | G11: O | H11: O | I11: O | J11: O
D12: Login with Authorize Account | F12: O | G12: O | H12: O | I12: O | J12: O | K12: O
D13: UserID Existed | F13: O | I13: O | J13: O
D14: UserID Doesn't Exist | G14: O | H14: O | K14: O
D15: Status Existed | F15: O | G15: O | J15: O
D16: Status Doesn't Exist | H16: O | I16: O | K16: O
B17: UserId
D18: Guid | F18: O | G18: O | I18: O | K18: O
D19: null | H19: O | J19: O
B20: Status
D21: 1 | F21: O | G21: O | J21: O | K21: O
D22: 9999 | I22: O
D23: null | H23: O
A24: Confirm | B24: Return
D25: T | F25: O
D26: F | G26: O | H26: O | I26: O | J26: O
B27: Exception
D28: InvalidOperationException | K28: O
B29: Log message
D30: "Expected ChangeUserStatus to return true for a valid status change." | F30: O
D31: "Expected ChangeUserStatus to return false for an invalid user ID." | G31: O
D32: "Expected ChangeUserStatus to return false for a null ChangeUserStatus DTO." | H32: O
D33: "Expected ChangeUserStatus to return false for a non-existent status." | I33: O
D34: "Expected ChangeUserStatus to return false for an empty UserId." | J34: O
D35: "Simulated DB error" | K35: O
A36: Result | B36: Type(N : Normal, A : Abnormal, B : Boundary) | F36: N | G36: A | H36: A | I36: A | J36: A | K36: A
B37: Passed/Failed | F37: P | G37: P | H37: P | I37: P | J37: P | K37: P
B38: Executed Date | F38: 45706 | G38: 45706 | H38: 45706 | I38: 45706 | J38: 45706 | K38: 45706
B39: Defect ID

Sheet Entry Excel To User
A2: Function Code | C2: User - 8 | F2: Function Name | L2: Entry Excel to User
A3: Created By | C3: Nguyễn Hữu Duy | F3: Executed By | L3: Nguyễn Hữu Duy
A4: Lines of code | C4: 137 | F4: Lack of test cases | L4: 0
A5: Test requirement
A6: Passed | C6: Failed | F6: Untested | L6: N/A/B | O6: Total Test Cases
A7: =COUNTIF(F32:HQ32,"P") | C7: =COUNTIF(F33:HQ33,"F") | F7: =SUM(O7,- A7,- C7) | L7: =COUNTIF(E31:HQ31,"N") | M7: =COUNTIF(E31:HQ31,"A") | N7: =COUNTIF(E31:HQ31,"B") | O7: =COUNTA(E9:HT9)
F9: UTCID01 | G9: UTCID02 | H9: UTCID03 | I9: UTCID04 | J9: UTCID05
A10: Condition | B10: Precondition
D11: Can connect with SQL Server | F11: O | G11: O | H11: O | I11: O
D12: Login with Authorize Account | F12: O | G12: O | H12: O | I12: O | J12: O
D13: Excel Existed | F13: O
D14: Excel Doesn't Exist | G14: O | H14: O | I14: O | J14: O
B15: filePath
D16: "validFilePath.xlsx" | F16: O | J16: O
D17: "invalidFilePath.xlsx" | G17: O
D18: "nonExistentFilePath.xlsx" | H18: O
D19: "nonExistentFilePath.exe" | I19: O
A20: Confirm | B20: Return
D21: T | F21: O
D22: F | G22: O | H22: O | I22: O | J22: O
B23: Exception
D24: InvalidOperationException
B25: Log message
D26: "Return true with valid file path" | F26: O
D27: "return false with invalid Excel Format" | G27: O
D28: "return false with non existent file path" | H28: O
D29: "return false not excel file" | I29: O
D30: "Processing error" | J30: O
A31: Result | B31: Type(N : Normal, A : Abnormal, B : Boundary) | F31: N | G31: A | H31: A | I31: A | J31: A
B32: Passed/Failed | F32: P | G32: P | H32: P | I32: P | J32: P
B33: Executed Date | F33: 45706 | G33: 45706 | H33: 45706 | I33: 45706 | J33: 45706
B34: Defect ID

Sheet Login
A2: Function Code | C2: User - 6 | F2: Function Name | L2: Login
A3: Created By | C3: Nguyễn Hữu Duy | F3: Executed By | L3: Nguyễn Hữu Duy
A4: Lines of code | C4: 130 | F4: Lack of test cases | L4: 0
A5: Test requirement
A6: Passed | C6: Failed | F6: Untested | L6: N/A/B | O6: Total Test Cases
A7: =COUNTIF(F36:HQ36,"P") | C7: =COUNTIF(F37:HQ37,"F") | F7: =SUM(O7,- A7,- C7) | L7: =COUNTIF(E35:HQ35,"N") | M7: =COUNTIF(E35:HQ35,"A") | N7: =COUNTIF(E35:HQ35,"B") | O7: =COUNTA(E9:HT9)
F9: UTCID01 | G9: UTCID02 | H9: UTCID03 | I9: UTCID04 | J9: UTCID05 | K9: UTCID06 | L9: UTCID07
A10: Condition | B10: Precondition
D11: Can connect with SQL Server | F11: O | G11: O | H11: O | J11: O | K11: O | L11: O
D12: Login with Authorize Account | F12: O | G12: O | H12: O | I12: O | J12: O | K12: O | L12: O
D13: Account Existed | F13: O | H13: O | I13: O | J13: O | K13: O | L13: O
D14: Account Does not Existed | G14: O
D15: Account Is Locked | H15: O
B16: Email
D17: user@example.com | F17: O | H17: O | I17: O | K17: O
D18: invalid@example.com | G18: O
D19: null | J19: O | L19: O
B20: Password
D21: "validPassword" | F21: O | H21: O | I21: O
D22: "wrongPassword" | G22: O
D23: null | K23: O | L23: O
A24: Confirm | B24: Return
D25: User Model | F25: O
B26: Exception
D27: InvalidOperationException | G27: O | H27: O | I27: O
D28: ArgumentNullException | J28: O | K28: O | L28: O
B29: Log message
D30: "Tài khoản của bạn đã bị khoá. Vui lòng liên hệ hỗ trợ." | H30: O
D31: "Đã xảy ra lỗi không mong muốn khi đăng nhập." | I31: O
D32: "Expected Login to return false for an empty Email." | J32: O
D33: "Expected Login to return false for an empty Password." | K33: O
D34: Expected Login to return false for Null Input." | L34: O
A35: Result | B35: Type(N : Normal, A : Abnormal, B : Boundary) | F35: N | G35: A | H35: A | I35: A | J35: A | K35: A | L35: A
B36: Passed/Failed | F36: P | G36: P | H36: P | I36: P | J36: P | K36: P | L36: P
B37: Executed Date | F37: 45706 | G37: 45706 | H37: 45706 | I37: 45706 | J37: 45706 | K37: 45706 | L37: 45706
B38: Defect ID

Sheet Delete Room Facility
A2: Function Code | C2: RoomFacility - 5 | F2: Function Name | L2: Delete Room Facility
A3: Created By | C3: Nguyễn Thanh Tuấn | F3: Executed By | L3: Nguyễn Thanh Tuấn
A4: Lines of code | C4: 75 | F4: Lack of test cases | L4: 0
A5: Test requirement
A6: Passed | C6: Failed | F6: Untested | L6: N/A/B | O6: Total Test Cases
A7: =COUNTIF(F27:HQ27,"P") | C7: =COUNTIF(F28:HQ28,"F") | F7: =SUM(O7,- A7,- C7) | L7: =COUNTIF(E26:HQ26,"N") | M7: =COUNTIF(E26:HQ26,"A") | N7: =COUNTIF(E26:HQ26,"B") | O7: =COUNTA(E9:HT9)
F9: UTCID01 | G9: UTCID02 | H9: UTCID03
A10: Condition | B10: Precondition
D11: Can connect with SQL Server | F11: O | G11: O
D12: Login with Authorize Account | F12: O | G12: O | H12: O
D13: Room Facility Existed | F13: O | H13: O
D14: Room Facility Does not Existed | G14: O
B15: roomFacilityId
D16: Guid | F16: O | G16: O | H16: O
A17: Confirm | B17: Return
D18: T | F18: O
D19: F | G19: O
B20: Exception
D21: InvalidOperationException | H21: O
B22: Log message
D23: Expected DeleteRoomFacility to return true for a valid ID.
D24: Expected DeleteRoomFacility to return false for a non-existent ID.
D25: "Simulated DB error" | H25: O
A26: Result | B26: Type(N : Normal, A : Abnormal, B : Boundary) | F26: N | G26: N | H26: A
B27: Passed/Failed | F27: P | G27: P | H27: P
B28: Executed Date | F28: 45702 | G28: 45702 | H28: 45702
B29: Defect ID

Sheet Add New Facility
A2: Function Code | C2: Facility - 3 | F2: Function Name | L2: Add New Facility
A3: Created By | C3: Nguyễn Thanh Tuấn | F3: Executed By | L3: Nguyễn Thanh Tuấn
A4: Lines of code | C4: 268 | F4: Lack of test cases | L4: 0
A5: Test requirement
A6: Passed | C6: Failed | F6: Untested | L6: N/A/B | O6: Total Test Cases
A7: =COUNTIF(F54:HQ54,"P") | C7: =COUNTIF(F55:HQ55,"F") | F7: =SUM(O7,- A7,- C7) | L7: =COUNTIF(E53:HQ53,"N") | M7: =COUNTIF(E53:HQ53,"A") | N7: =COUNTIF(E53:HQ53,"B") | O7: =COUNTA(E9:HT9)
F9: UTCID01 | G9: UTCID02 | H9: UTCID03 | I9: UTCID04 | J9: UTCID05 | K9: UTCID06 | L9: UTCID07 | M9: UTCID08 | N9: UTCID09 | O9: UTCID10 | P9: UTCID11 | Q9: UTCID12 | R9: UTCID13
A10: Condition | B10: Precondition
D11: Can connect with SQL Server | F11: O | G11: O | H11: O | I11: O | J11: O | L11: O | M11: O | N11: O | O11: O | P11: O | Q11: O
D12: Login with Authorize Account | F12: O | G12: O | H12: O | I12: O | J12: O | K12: O | L12: O | M12: O | N12: O | O12: O | P12: O | Q12: O | R12: O
D13: RoleId Existed | F13: O | H13: O | I13: O | J13: O | L13: O | M13: O | N13: O | O13: O | P13: O | Q13: O | R13: O
D14: RoleId Does not Existed | G14: O | K14: O
B15: FacilityName
D16: "New Facility" | F16: O | I16: O | J16: O | K16: O | N16: O | O16: O | P16: O | Q16: O | R16: O
D17: null | G17: O | H17: O
D18: 50 characters string | L18: O
D19: 51 characters string | M19: O
B20: TotalQuantity
