Workbook
Name ACTION: #REF!

Sheet Guideline
A1: Guideline to make and understand Unit Test Case
A3: 1. Overview
A4: - In the template, Unit test cases are based on functions. Each sheet presents test cases for one function.
A5: - Cover: General information of the project and Unit Test cases
A6: - FunctionList: The list of Classes and Functions in the document. + To control that the number of Unit TC meets customer's requirement or the norm, user should fill value for 'Normal number of Test cases/KLOC'.
A7: + Click on Function link to open the related Test cases of the function. Note: You should create new Function sheet before creating the link
A8: - Test Report: provive the overview results of Functions Unit test: Test coverage, Test successful coverage (Summary, for normal/abnormal/boundary cases)
A9: Note: Should check the formula of "Sub Total" if you add more functions
A11: 2. Content in Test function sheet
A12: 2.1 Combination of test cases.
A13: - To verify that number of Unit TC meets customer's requirement or not. User has to fill number LOC of tested function and fill value of 'Normal number test cases/KLOC' item in FunctionList sheet, which is required by customer or normal value. The number of lacked TC is shown in 'Lack of test cases' item.
A14: - If the number of Unit TC does not meet the requirement, creator should explain the reasons.
... A47: - Test requirement: Brief description about requirements which are tested in this function, it is not mandatory.

Sheet Cover
B2: UNIT TEST CASE
A4: Project Name | B4: InterDev | E4: Creator | F4: GitHub Copilot
A5: Project Code | B5: INTERDEV | E5: Reviewer/Approver | F5: QA Team
A6: Document Code | B6: INTERDEV_Unit_Test_EP270_EP284_v1.2 | E6: Issue Date | F6: 2026-04-06
E7: Version | F7: 1.2
A10: Record of change
A11: 2026-04-06 | B11: 1.2 | C11: Add task progress/discussion/submission endpoints | D11: A | E11: Generated evidence-driven unit test workbook for EP-270..EP-284 from executed Jest results. | F11: docs/test-evidence/tasks_ep270_284/jest-results.json

Sheet Function List
E2: UNIT TEST CASE LIST
A4: Project Name | E4: InterDev
A5: Project Code | E5: INTERDEV
A6: Normal number of Test cases/KLOC | E6: 300
A7: Test Environment Setup Description | E7: 1. Backend API: NestJS controller unit-test harness with mocked dependencies 2. Runtime: Node.js 22.x, Yarn 1.22.x 3. Test framework: Jest + ts-jest 4. Evidence source: tasks.controller.ep270-ep284.spec.ts with executed Jest JSON
A10: No | B10: Requirement Name | C10: Class Name | D10: Function Name | E10: Function Code(Optional) | F10: Sheet Name | G10: Description | H10: Pre-Condition
A11: 1 | B11: UC-36 View Current Progress | C11: TasksController | D11: Get Project Recent Activity | E11: EP-270 | F11: Get Project Recent Activity | G11: GET /tasks/project/:projectId/recent-activity | H11: Authenticated user exists | Project id is provided
A12: 2 | B12: UC-36 View Current Progress | C12: TasksController | D12: Get Task History | E12: EP-271 | F12: Get Task History | G12: GET /tasks/:id/history | H12: Authenticated user exists | Task id is provided
A13: 3 | B13: UC-37 Discussion | C13: TasksController | D13: Get Task Comments | E13: EP-272 | F13: Get Task Comments | G13: GET /tasks/:id/comments | H13: Authenticated user exists | Task id is provided
A14: 4 | B14: UC-59 Submit Done Item; UC-106 Review Done Item | C14: TasksController | D14: Get Task Submissions | E14: EP-274 | F14: Get Task Submissions | G14: GET /tasks/:id/submissions | H14: Authenticated user exists | Task id is provided
A15: 5 | B15: UC-37 Discussion | C15: TasksController | D15: Upload Attachment | E15: EP-280 | F15: Upload Attachment | G15: POST /tasks/upload-attachment | H15: Authenticated user exists | Multipart file is provided
A16: 6 | B16: UC-37 Discussion | C16: TasksController | D16: Add Comment | E16: EP-281 | F16: Add Comment | G16: POST /tasks/:id/comments | H16: Authenticated user exists | Task id is provided
A17: 7 | B17: UC-59 Submit Done Item | C17: TasksController | D17: Submit Work | E17: EP-283 | F17: Submit Work | G17: POST /tasks/:id/submissions | H17: Authenticated user exists | Task id is provided
A18: 8 | B18: UC-106 Review Done Item | C18: TasksController | D18: Review Submission | E18: EP-284 | F18: Review Submission | G18: PATCH /tasks/:id/submissions/:submissionId/review | H18: Reviewer user context is provided | Submission exists for task

Sheet Test Report
A2: UNIT TEST REPORT
A4: Project Name | B4: InterDev | D4: Creator | F4: GitHub Copilot
A5: Project Code | B5: INTERDEV | D5: Reviewer/Approver | F5: QA Team
A6: Document Code | B6: SEP492_Unit Test Report_v1.2 | D6: Issue Date | F6: 2026-04-06
A7: Notes | B7: Scope includes EP-270, EP-271, EP-272, EP-274, EP-280, EP-281, EP-283, EP-284 for UC-36, UC-37, UC-59, UC-106.
A11: No | B11: Function code | C11: Passed | D11: Failed | E11: Untested | F11: N | G11: A | H11: B | I11: Total Test Cases
A12: 1 | B12: EP-270 | C12: ='Get Project Recent Activity'!$A$7 | D12: ='Get Project Recent Activity'!$C$7 | E12: ='Get Project Recent Activity'!$F$7 | F12: ='Get Project Recent Activity'!$L$7 | G12: ='Get Project Recent Activity'!$M$7 | H12: ='Get Project Recent Activity'!$N$7 | I12: ='Get Project Recent Activity'!$O$7
A13: 2 | B13: EP-271 | C13: ='Get Task History'!$A$7 | D13: ='Get Task History'!$C$7 | E13: ='Get Task History'!$F$7 | F13: ='Get Task History'!$L$7 | G13: ='Get Task History'!$M$7 | H13: ='Get Task History'!$N$7 | I13: ='Get Task History'!$O$7
A14: 3 | B14: EP-272 | C14: ='Get Task Comments'!$A$7 | D14: ='Get Task Comments'!$C$7 | E14: ='Get Task Comments'!$F$7 | F14: ='Get Task Comments'!$L$7 | G14: ='Get Task Comments'!$M$7 | H14: ='Get Task Comments'!$N$7 | I14: ='Get Task Comments'!$O$7
A15: 4 | B15: EP-274 | C15: ='Get Task Submissions'!$A$7 | D15: ='Get Task Submissions'!$C$7 | E15: ='Get Task Submissions'!$F$7 | F15: ='Get Task Submissions'!$L$7 | G15: ='Get Task Submissions'!$M$7 | H15: ='Get Task Submissions'!$N$7 | I15: ='Get Task Submissions'!$O$7
A16: 5 | B16: EP-280 | C16: ='Upload Attachment'!$A$7 | D16: ='Upload Attachment'!$C$7 | E16: ='Upload Attachment'!$F$7 | F16: ='Upload Attachment'!$L$7 | G16: ='Upload Attachment'!$M$7 | H16: ='Upload Attachment'!$N$7 | I16: ='Upload Attachment'!$O$7
A17: 6 | B17: EP-281 | C17: ='Add Comment'!$A$7 | D17: ='Add Comment'!$C$7 | E17: ='Add Comment'!$F$7 | F17: ='Add Comment'!$L$7 | G17: ='Add Comment'!$M$7 | H17: ='Add Comment'!$N$7 | I17: ='Add Comment'!$O$7
A18: 7 | B18: EP-283 | C18: ='Submit Work'!$A$7 | D18: ='Submit Work'!$C$7 | E18: ='Submit Work'!$F$7 | F18: ='Submit Work'!$L$7 | G18: ='Submit Work'!$M$7 | H18: ='Submit Work'!$N$7 | I18: ='Submit Work'!$O$7
A19: 8 | B19: EP-284 | C19: ='Review Submission'!$A$7 | D19: ='Review Submission'!$C$7 | E19: ='Review Submission'!$F$7 | F19: ='Review Submission'!$L$7 | G19: ='Review Submission'!$M$7 | H19: ='Review Submission'!$N$7 | I19: ='Review Submission'!$O$7
B21: Sub total | C21: =SUM(C12:C19) | D21: =SUM(D12:D19) | E21: =SUM(E12:E19) | F21: =SUM(F12:F19) | G21: =SUM(G12:G19) | H21: =SUM(H12:H19) | I21: =SUM(I12:I19)
B23: Test coverage | D23: =IF(I21=0,0,(C21+D21)*100/I21) | E23: %
B24: Test successful coverage | D24: =IF(I21=0,0,C21*100/I21) | E24: %
B25: Normal case | D25: =IF(I21=0,0,F21*100/I21) | E25: %
B26: Abnormal case | D26: =IF(I21=0,0,G21*100/I21) | E26: %
B27: Boundary case | D27: =IF(I21=0,0,H21*100/I21) | E27: %

Sheet Get Project Recent Activity
A2: Function Code | C2: EP-270 | F2: Function Name | L2: Get Project Recent Activity
A3: Created By | C3: GitHub Copilot | F3: Executed By | L3: GitHub Copilot
A4: Lines of code | C4: 8 | F4: Lack of test cases | L4: 0
A5: Test requirement | C5: Verify getProjectRecentActivity: valid, edge, error, and auth cases for EP-270.
A6: Passed | C6: Failed | F6: Untested | L6: N/A/B | O6: Total Test Cases
A7: =COUNTIF(F34:I34,"P") | C7: =COUNTIF(F34:I34,"F") | F7: =COUNTIF(F34:I34,"U") | L7: =COUNTIF(F33:I33,"N") | M7: =COUNTIF(F33:I33,"A") | N7: =COUNTIF(F33:I33,"B") | O7: =COUNTA(F9:I9)
F9: UTC01 | G9: UTC02 | H9: UTC03 | I9: UTC04
A10: Condition | B10: Precondition
D11: user exists | F11: O | G11: O | H11: O
D12: Project "project-1" exists | F12: O
D13: Project "project-empty" exists with no activity | G13: O
D14: Project "project-missing" does not exist | H14: O
D15: TasksController is decorated with class-level guards | I15: O
B16: projectId
D17: project-1 | F17: O
D18: project-empty | G18: O
D19: project-missing | H19: O
B20: metadata
D21: GUARDS_METADATA on TasksController | I21: O
A22: Confirm | B22: Return
D23: Returns recent activity list for the project | F23: O
D24: Returns empty array when no activity is tracked | G24: O
D25: Guard metadata exists for authenticated access | I25: O
B26: Exception
D27: NotFoundException: Project not found | H27: O
B28: Log message
D29: EP-270 UTC01 Returns recent activity for a valid project id | F29: O
D30: EP-270 UTC02 Returns an empty list when no recent activity exists | G30: O
D31: EP-270 UTC03 propagates service errors for unknown project ids | H31: O
D32: EP-270 UTC04 is protected by JwtAuthGuard at controller level | I32: O
A33: Result | B33: Type(N : Normal, A : Abnormal, B : Boundary) | F33: N | G33: B | H33: A | I33: A
B34: Passed/Failed | F34: P | G34: P | H34: P | I34: P
B35: Executed Date | F35: 04-06 | G35: 04-06 | H35: 04-06 | I35: 04-06
B36: Defect ID

Sheet Get Task History
A2: Function Code | C2: EP-271 | F2: Function Name | L2: Get Task History
A3: Created By | C3: GitHub Copilot | F3: Executed By | L3: GitHub Copilot
A4: Lines of code | C4: 4 | F4: Lack of test cases | L4: 0
A5: Test requirement | C5: Verify getTaskHistory: valid, edge, error, and auth cases for EP-271.
A6: Passed | C6: Failed | F6: Untested | L6: N/A/B | O6: Total Test Cases
A7: =COUNTIF(F34:I34,"P") | C7: =COUNTIF(F34:I34,"F") | F7: =COUNTIF(F34:I34,"U") | L7: =COUNTIF(F33:I33,"N") | M7: =COUNTIF(F33:I33,"A") | N7: =COUNTIF(F33:I33,"B") | O7: =COUNTA(F9:I9)
F9: UTC01 | G9: UTC02 | H9: UTC03 | I9: UTC04
A10: Condition | B10: Precondition
D11: user exists | F11: O | G11: O | H11: O
D12: Task "task-1" exists | F12: O
D13: Task "task-clean" exists with no history | G13: O
D14: Task "task-missing" does not exist | H14: O
D15: TasksController is decorated with class-level guards | I15: O
B16: id
D17: task-1 | F17: O
D18: task-clean | G18: O
D19: task-missing | H19: O
B20: metadata
D21: GUARDS_METADATA on TasksController | I21: O
A22: Confirm | B22: Return
D23: Returns history entries for task | F23: O
D24: Returns empty history list | G24: O
D25: Guard metadata exists for authenticated access | I25: O
B26: Exception
D27: NotFoundException: Task not found | H27: O
B28: Log message
D29: EP-271 UTC01 Returns task history for a valid task id | F29: O
D30: EP-271 UTC02 Returns an empty list for tasks without history | G30: O
D31: EP-271 UTC03 propagates service errors for missing tasks | H31: O
D32: EP-271 UTC04 is protected by JwtAuthGuard at controller level | I32: O
A33: Result | B33: Type(N : Normal, A : Abnormal, B : Boundary) | F33: N | G33: B | H33: A | I33: A
B34: Passed/Failed | F34: P | G34: P | H34: P | I34: P
B35: Executed Date | F35: 04-06 | G35: 04-06 | H35: 04-06 | I35: 04-06
B36: Defect ID

Sheet Get Task Comments
A2: Function Code | C2: EP-272 | F2: Function Name | L2: Get Task Comments
A3: Created By | C3: GitHub Copilot | F3: Executed By | L3: GitHub Copilot
A4: Lines of code | C4: 4 | F4: Lack of test cases | L4: 0
A5: Test requirement | C5: Verify getTaskComments: valid, edge, error, and auth cases for EP-272.
A6: Passed | C6: Failed | F6: Untested | L6: N/A/B | O6: Total Test Cases
A7: =COUNTIF(F34:I34,"P") | C7: =COUNTIF(F34:I34,"F") | F7: =COUNTIF(F34:I34,"U") | L7: =COUNTIF(F33:I33,"N") | M7: =COUNTIF(F33:I33,"A") | N7: =COUNTIF(F33:I33,"B") | O7: =COUNTA(F9:I9)
F9: UTC01 | G9: UTC02 | H9: UTC03 | I9: UTC04
A10: Condition | B10: Precondition
D11: user exists | F11: O | G11: O | H11: O
D12: Task "task-1" exists | F12: O
D13: Task "task-silent" has no comments | G13: O
D14: Task "task-missing" does not exist | H14: O
D15: TasksController is decorated with class-level guards | I15: O
B16: taskId
D17: task-1 | F17: O
D18: task-silent | G18: O
D19: task-missing | H19: O
B20: metadata
D21: GUARDS_METADATA on TasksController | I21: O
A22: Confirm | B22: Return
D23: Returns comment list | F23: O
D24: Returns empty comment list | G24: O
D25: Guard metadata exists for authenticated access | I25: O
B26: Exception
D27: NotFoundException: Task not found | H27: O
B28: Log message
D29: EP-272 UTC01 Returns comments for a valid task id | F29: O
D30: EP-272 UTC02 Returns an empty list when discussion has no comments | G30: O
D31: EP-272 UTC03 propagates service errors for missing tasks | H31: O
D32: EP-272 UTC04 is protected by JwtAuthGuard at controller level | I32: O
A33: Result | B33: Type(N : Normal, A : Abnormal, B : Boundary) | F33: N | G33: B | H33: A | I33: A
B34: Passed/Failed | F34: P | G34: P | H34: P | I34: P
B35: Executed Date | F35: 04-06 | G35: 04-06 | H35: 04-06 | I35: 04-06
B36: Defect ID

Sheet Get Task Submissions
A2: Function Code | C2: EP-274 | F2: Function Name | L2: Get Task Submissions
A3: Created By | C3: GitHub Copilot | F3: Executed By | L3: GitHub Copilot
A4: Lines of code | C4: 4 | F4: Lack of test cases | L4: 0
A5: Test requirement | C5: Verify getTaskSubmissions: valid, edge, error, and auth cases for EP-274.
A6: Passed | C6: Failed | F6: Untested | L6: N/A/B | O6: Total Test Cases
A7: =COUNTIF(F34:I34,"P") | C7: =COUNTIF(F34:I34,"F") | F7: =COUNTIF(F34:I34,"U") | L7: =COUNTIF(F33:I33,"N") | M7: =COUNTIF(F33:I33,"A") | N7: =COUNTIF(F33:I33,"B") | O7: =COUNTA(F9:I9)
F9: UTC01 | G9: UTC02 | H9: UTC03 | I9: UTC04
A10: Condition | B10: Precondition
D11: user exists | F11: O | G11: O | H11: O
D12: Task "task-1" exists | F12: O
D13: Task "task-open" has no submissions | G13: O
D14: Task "task-missing" does not exist | H14: O
D15: TasksController is decorated with class-level guards | I15: O
B16: id
D17: task-1 | F17: O
D18: task-open | G18: O
D19: task-missing | H19: O
B20: metadata
D21: GUARDS_METADATA on TasksController | I21: O
A22: Confirm | B22: Return
D23: Returns submission list | F23: O
D24: Returns empty submissions list | G24: O
D25: Guard metadata exists for authenticated access | I25: O
B26: Exception
D27: NotFoundException: Task not found | H27: O
B28: Log message
D29: EP-274 UTC01 Returns submissions for a valid task id | F29: O
D30: EP-274 UTC02 Returns an empty list when no submissions exist | G30: O
D31: EP-274 UTC03 propagates service errors for missing tasks | H31: O
D32: EP-274 UTC04 is protected by JwtAuthGuard at controller level | I32: O
A33: Result | B33: Type(N : Normal, A : Abnormal, B : Boundary) | F33: N | G33: B | H33: A | I33: A
B34: Passed/Failed | F34: P | G34: P | H34: P | I34: P
B35: Executed Date | F35: 04-06 | G35: 04-06 | H35: 04-06 | I35: 04-06
B36: Defect ID

Sheet Upload Attachment
A2: Function Code | C2: EP-280 | F2: Function Name | L2: Upload Attachment
A3: Created By | C3: GitHub Copilot | F3: Executed By | L3: GitHub Copilot
A4: Lines of code | C4: 15 | F4: Lack of test cases | L4: 0
A5: Test requirement | C5: Verify uploadAttachment: valid, edge, error, and auth cases for EP-280.
A6: Passed | C6: Failed | F6: Untested | L6: N/A/B | O6: Total Test Cases
A7: =COUNTIF(F38:I38,"P") | C7: =COUNTIF(F38:I38,"F") | F7: =COUNTIF(F38:I38,"U") | L7: =COUNTIF(F37:I37,"N") | M7: =COUNTIF(F37:I37,"A") | N7: =COUNTIF(F37:I37,"B") | O7: =COUNTA(F9:I9)
F9: UTC01 | G9: UTC02 | H9: UTC03 | I9: UTC04
A10: Condition | B10: Precondition
D11: user exists | F11: O | G11: O | H11: O
D12: File exists | F12: O
D13: File exists with zero-byte buffer | G13: O
D14: No file is provided | H14: O
D15: TasksController is decorated with class-level guards | I15: O
B16: file.originalname
D17: evidence.png | F17: O
D18: empty.txt | G18: O
B19: file.mimetype
D20: image/png | F20: O
B21: file.size
D22: 0 | G22: O
B23: file
B24: metadata
D25: GUARDS_METADATA on TasksController | I25: O
A26: Confirm | B26: Return
D27: Returns uploaded file URL | F27: O
D28: Forwards file to service when file object exists | G28: O
D29: Guard metadata exists for authenticated access | I29: O
B30: Exception
D31: BadRequestException: File is required | H31: O
B32: Log message
D33: EP-280 UTC01 uploads a valid file via TasksService.uploadFile | F33: O
D34: EP-280 UTC02 still accepts a zero-byte file because controller valida... | G34: O
D35: EP-280 UTC03 rejects missing file with BadRequestException | H35: O
D36: EP-280 UTC04 is protected by JwtAuthGuard at controller level | I36: O
A37: Result | B37: Type(N : Normal, A : Abnormal, B : Boundary) | F37: N | G37: B | H37: A | I37: A
B38: Passed/Failed | F38: P | G38: P | H38: P | I38: P
B39: Executed Date | F39: 04-06 | G39: 04-06 | H39: 04-06 | I39: 04-06
B40: Defect ID

Sheet Add Comment
A2: Function Code | C2: EP-281 | F2: Function Name | L2: Add Comment
A3: Created By | C3: GitHub Copilot | F3: Executed By | L3: GitHub Copilot
A4: Lines of code | C4: 11 | F4: Lack of test cases | L4: 0
A5: Test requirement | C5: Verify addComment: valid, edge, error, and auth cases for EP-281.
A6: Passed | C6: Failed | F6: Untested | L6: N/A/B | O6: Total Test Cases
A7: =COUNTIF(F37:I37,"P") | C7: =COUNTIF(F37:I37,"F") | F7: =COUNTIF(F37:I37,"U") | L7: =COUNTIF(F36:I36,"N") | M7: =COUNTIF(F36:I36,"A") | N7: =COUNTIF(F36:I36,"B") | O7: =COUNTA(F9:I9)
F9: UTC01 | G9: UTC02 | H9: UTC03 | I9: UTC04
A10: Condition | B10: Precondition
D11: user exists | F11: O | G11: O
D12: Task "task-1" exists | F12: O | G12: O | H12: O
D13: Request user context is unavailable | H13: O
D14: TasksController is decorated with class-level guards | I14: O
B15: taskId
D16: task-1 | F16: O | G16: O | H16: O
B17: content
D18: Looks good | F18: O
G19: O
D20: System note | H20: O
B21: userId
D22: user-1 | F22: O | G22: O
D23: SYSTEM | H23: O
B24: metadata
D25: GUARDS_METADATA on TasksController | I25: O
A26: Confirm | B26: Return
D27: Returns persisted task comment | F27: O
D28: Forwards whitespace content to service | G28: O
D29: Returns persisted comment with SYSTEM actor | H29: O
D30: Guard metadata exists for authenticated access | I30: O
B31: Log message
D32: EP-281 UTC01 adds comment with authenticated actor id | F32: O
D33: EP-281 UTC02 forwards whitespace comment content to service for downs... | G33: O
D34: EP-281 UTC03 falls back to SYSTEM actor when request user is unavailable | H34: O
D35: EP-281 UTC04 is protected by JwtAuthGuard at controller level | I35: O
A36: Result | B36: Type(N : Normal, A : Abnormal, B : Boundary) | F36: N | G36: B | H36: A | I36: A
B37: Passed/Failed | F37: P | G37: P | H37: P | I37: P
B38: Executed Date | F38: 04-06 | G38: 04-06 | H38: 04-06 | I38: 04-06
B39: Defect ID

Sheet Submit Work
A2: Function Code | C2: EP-283 | F2: Function Name | L2: Submit Work
A3: Created By | C3: GitHub Copilot | F3: Executed By | L3: GitHub Copilot
A4: Lines of code | C4: 10 | F4: Lack of test cases | L4: 0
A5: Test requirement | C5: Verify submitWork: valid, edge, error, and auth cases for EP-283.
A6: Passed | C6: Failed | F6: Untested | L6: N/A/B | O6: Total Test Cases
A7: =COUNTIF(F38:I38,"P") | C7: =COUNTIF(F38:I38,"F") | F7: =COUNTIF(F38:I38,"U") | L7: =COUNTIF(F37:I37,"N") | M7: =COUNTIF(F37:I37,"A") | N7: =COUNTIF(F37:I37,"B") | O7: =COUNTA(F9:I9)
F9: UTC01 | G9: UTC02 | H9: UTC03 | I9: UTC04
A10: Condition | B10: Precondition
D11: user exists | F11: O | G11: O
D12: Task "task-1" exists | F12: O | G12: O | H12: O
D13: Request user context is unavailable | H13: O
D14: TasksController is decorated with class-level guards | I14: O
B15: id
D16: task-1 | F16: O | G16: O | H16: O
B17: content
D18: Completed implementation | F18: O
D19: Done without files | G19: O
D20: Fallback submission | H20: O
B21: userId
D22: freelancer-1 | F22: O
D23: SYSTEM | H23: O
B24: attachments
B25: metadata
D26: GUARDS_METADATA on TasksController | I26: O
A27: Confirm | B27: Return
D28: Returns created task submission | F28: O
D29: Returns created submission with empty attachments | G29: O
D30: Returns created submission with SYSTEM actor | H30: O
D31: Guard metadata exists for authenticated access | I31: O
B32: Log message
D33: EP-283 UTC01 submits work with authenticated user id | F33: O
D34: EP-283 UTC02 forwards empty attachments list for boundary | G34: O
D35: EP-283 UTC03 falls back to SYSTEM actor when request user is unavailable | H35: O
D36: EP-283 UTC04 is protected by JwtAuthGuard at controller level | I36: O
A37: Result | B37: Type(N : Normal, A : Abnormal, B : Boundary) | F37: N | G37: B | H37: A | I37: A
B38: Passed/Failed | F38: P | G38: P | H38: P | I38: P
B39: Executed Date | F39: 04-06 | G39: 04-06 | H39: 04-06 | I39: 04-06
B40: Defect ID

Sheet Review Submission
A2: Function Code | C2: EP-284 | F2: Function Name | L2: Review Submission
A3: Created By | C3: GitHub Copilot | F3: Executed By | L3: GitHub Copilot
A4: Lines of code | C4: 30 | F4: Lack of test cases | L4: 0
A5: Test requirement | C5: Verify reviewSubmission: valid, edge, error, and auth cases for EP-284.
A6: Passed | C6: Failed | F6: Untested | L6: N/A/B | O6: Total Test Cases
A7: =COUNTIF(F41:I41,"P") | C7: =COUNTIF(F41:I41,"F") | F7: =COUNTIF(F41:I41,"U") | L7: =COUNTIF(F40:I40,"N") | M7: =COUNTIF(F40:I40,"A") | N7: =COUNTIF(F40:I40,"B") | O7: =COUNTA(F9:I9)
F9: UTC01 | G9: UTC02 | H9: UTC03 | I9: UTC04
A10: Condition | B10: Precondition
D11: reviewer has CLIENT | F11: O
D12: Task "task-1" and submission "submission-1" exist | F12: O | G12: O
D13: reviewer has value "broker" | G13: O
D14: No authenticated reviewer is present | H14: O
D15: reviewer has FREELANCER | I15: O
B16: id
D17: task-1 | F17: O | G17: O | H17: O | I17: O
B18: submissionId
D19: submission-1 | F19: O | G19: O | H19: O | I19: O
B20: status
D21: APPROVED | F21: O | H21: O | I21: O
D22: REQUEST_CHANGES | G22: O
B23: reviewerId
D24: client-1 | F24: O
B25: reviewerRole
D26: broker | G26: O
D27: FREELANCER | I27: O
B28: user
A29: Confirm | B29: Return
D30: Returns review result from service | F30: O
D31: Returns review result for normalized broker | G31: O
B32: Exception
D33: ForbiddenException: Authentication required | H33: O
D34: ForbiddenException: | I34: O
B35: Log message
D36: EP-284 UTC01 allows CLIENT reviewer and forwards review to service | F36: O
D37: EP-284 UTC02 accepts lowercase broker after normalization | G37: O
D38: EP-284 UTC03 rejects unauthenticated review requests | H38: O
D39: EP-284 UTC04 rejects FREELANCER reviewer | I39: O
A40: Result | B40: Type(N : Normal, A : Abnormal, B : Boundary) | F40: N | G40: B | H40: A | I40: A
B41: Passed/Failed | F41: P | G41: P | H41: P | I41: P
B42: Executed Date | F42: 04-06 | G42: 04-06 | H42: 04-06 | I42: 04-06
...
